Workbook

Sheet Methodology Guide
A1: CHRIS CROFT 12-STEP PROJECT METHOD
A2: Integrated operating checklist from Twelve Steps.pdf and PM-Simplified.md
A4: Story-in-Brief
A5: The workbook now connects the control-tower metrics to Chris Croft’s practical 12-step project method: define scope, build the task plan, add contingency, control schedule/resources/risks, monitor Gantt and cost, then re-plan and review. For this portfolio, the strongest alignment is EVM cost monitoring and RAID control; the main watch area is resource leveling because overtime events are already visible in the audit sheet.
A10: Step | B10: Croft Step | C10: Controller Interpretation | D10: Workbook Evidence | E10: Primary KPI | F10: Current Integration Note
A11: 1 | B11: Define the project | C11: Confirm objectives, success criteria, scope, and cost/time/quality priority. | D11: Projects table + dashboard narrative | E11: BAC, Status, Manager | F11: Needs explicit success criteria per project.
A12: 2 | B12: List the tasks | C12: Build a complete WBS with no omissions and no overlaps. | D12: WBS_Performance table | E12: WBS_ID, PlannedCost | F12: Implemented via 14 WBS elements.
A13: 3 | B13: Plan the running order | C13: Sequence activities and identify dependencies before committing dates. | D13: Schedule & Gantt | E13: Start/End dates | F13: Add predecessor logic for full CPM.
A14: 4 | B14: Add contingency | C14: Reserve budget/time for uncertainty and known risk exposure. | D14: RAID + simulator | E14: Active RAID count | F14: Add quantified risk reserve if needed.
A15: 5 | B15: Consider crashing | C15: Evaluate extra cost to shorten critical-path activities. | D15: Interactive Simulator | E15: Crash days, penalty, benefit | F15: Implemented as editable what-if.
A16: 6 | B16: Make a Gantt chart | C16: Show who does what when, including critical activities. | D16: Schedule & Gantt | E16: Duration, timeline marks | F16: Month-level view included.
A17: 7 | B17: Calculate resource requirements | C17: Compare planned capacity against actual hours and bottlenecks. | D17: CFO + Risk Audit | E17: Hours, overtime events | F17: Overtime audit flags 8 events.
A18: 8 | B18: Assess risks and action plans | C18: Maintain RAID log with probability, impact, mitigation, owner, status. | D18: Contract & RAID Risk Audit | E18: Active RAID, owner | F18: 3 active RAID items visible.
A19: 9 | B19: Monitor progress using Gantt | C19: Track physical progress and schedule movement. | D19: EVM Data + Gantt | E19: Progress % | F19: Physical progress drives EV.
A20: 10 | B20: Monitor costs | C20: Compare AC, EV, BAC and calculate CPI/EAC. | D20: Control Tower + EVM Data | E20: AC, EV, CPI, EAC | F20: Portfolio CPI is 0.91.
A21: 11 | B21: Readjust the plan | C21: Use cost/schedule signals to trigger corrective action and reforecasting. | D21: Simulator + dashboard | E21: Simulated CPI/EAC | F21: Use when CPI < 1 or overtime persists.
A22: 12 | B22: Review | C22: Capture lessons learned after delivery and feed estimates back into future projects. | D22: Controller Playbook | E22: Review cadence | F22: Add post-project lessons log if needed.
A25: Portfolio Alignment Snapshot
A26: Control Area | B26: Current Workbook Signal | C26: Interpretation | D26: Action Trigger
A27: Cost control | B27: ='Control Tower Dashboard'!G5 -> 0.91029936 | C27: CPI below 1.00 shows cost inefficiency. | D27: Investigate WBS CPI < 0.90.
A28: Progress | B28: ='Control Tower Dashboard'!I5 -> 0.6693662 | C28: EV/BAC shows portfolio physical progress. | D28: Review if progress stalls while AC rises.
A29: Resource pressure | B29: ='Control Tower Dashboard'!L6 -> 8 | C29: Weekly overtime events indicate resource overload. | D29: Level resources or re-sequence work.
A30: Risk exposure | B30: ='Control Tower Dashboard'!L5 -> 3 | C30: Active RAID items need mitigation ownership. | D30: Escalate high-impact active items.
A31: Corrective action | B31: ='Interactive Simulator'!B19 -> 0.96670792 | C31: Simulated CPI after savings/crash choices. | D31: Run scenario before committing changes.
A34: Project CFO / Executive Agent Overlay
A35: SKILL.md adds an executive-CFO lens on top of the project-control method: profitability first, margin variance thresholds, cash-flow sensitivity, and concise board-level recommendations. In practice, this means the workbook should not stop at CPI/EAC diagnostics — it should translate each cost or schedule signal into margin-at-completion and cash-risk actions for leadership.
A40: CFO Directive | B40: Rule from SKILL.md | C40: Workbook Implementation | D40: Primary Location
A41: Profitability First | B41: Evaluate every cost/schedule movement by its impact on final profit margin. | C41: Use EAC, BAC/contract value, and simulated CPI to frame margin-at-completion risk. | D41: Control Tower Dashboard + Interactive Simulator
A42: Variance Thresholds | B42: Flag any project where projected Margin at Completion is >2 percentage points below baseline. | C42: Add/maintain margin-at-completion once revenue/contract value is available. | D42: 3S Model Blueprint + 3S Readiness Audit
A43: Cash Flow Sensitivity | B43: Compare billing milestones with timesheet/material outlays to avoid negative project cash balances. | C43: Current workbook has cost timing but not billing milestones; this is a data gap. | D43: CFO & Cost Share Audit + Source Data
A44: Strategic Focus | B44: Use concise, bulleted recommendations for board/investor summaries. | C44: Executive narrative should state action required, owner, and financial consequence. | D44: Control Tower Dashboard narrative
A47: Live CFO Trigger Snapshot
A48: Trigger | B48: Live Signal | C48: Threshold / Rule | D48: Current Status | E48: Recommended Executive Action
A49: Cost efficiency | B49: ='Control Tower Dashboard'!G5 -> 0.91029936 | C49: CPI < 1.00 indicates cost pressure. | D49: =IF(B49<1,"⚠ Margin pressure","✓ Stable") -> ⚠ Margin pressure | E49: Action Required: review low-CPI WBS and protect margin.
A50: Worst project CPI | B50: ='Control Tower Dashboard'!L10 -> 0.80727603 | C50: Project CPI below 0.95 signals margin deterioration risk. | D50: =IF(B50<0.95,"⚠ Reforecast required","✓ Within tolerance") -> ⚠ Reforecast required | E50: Action Required: reforecast EAC and recovery plan.
A51: Cash-out mix | B51: ='Control Tower Dashboard'!L8 -> 0.79466788 | C51: Labor/material cost concentration drives funding risk. | D51: =IF(B51>0.75,"⚠ Labor-heavy outflow","✓ Balanced mix") -> ⚠ Labor-heavy outflow | E51: Action Required: compare outlays to billing milestones.
A52: Overtime pressure | B52: ='Control Tower Dashboard'!L6 -> 8 | C52: Any overtime event >45h/week is capacity/cost risk. | D52: =IF(B52>0,"⚠ Capacity risk","✓ No overtime flag") -> ⚠ Capacity risk | E52: Action Required: level resources or approve recovery cost.
A53: Large procurement | B53: ='Control Tower Dashboard'!L7 -> 5 | C53: High early materials can create cash-flow troughs. | D53: =IF(B53>0,"⚠ Procurement cash risk","✓ No large-purchase flag") -> ⚠ Procurement cash risk | E53: Action Required: align procurement with milestone billing.

Sheet Controller Playbook
A1: PROJECT CONTROLLER PLAYBOOK
A2: Role, cadence, KPI definitions, and decision rules from PM-Simplified.md
A4: Operating Thesis
A5: The controller translates project activity into decision-grade financial insight: EVM indices, EAC/ETC forecasting, resource burn, risk exposure, and scenario analysis. In the workbook, the controller should use the dashboard as the executive view, EVM Data as the calculation ledger, Risk Audit for exceptions, and the Simulator for corrective-action tradeoffs.
A10: Cadence | B10: Controller Activity | C10: Workbook Location | D10: Decision / Output | E10: Escalation Rule
A11: Weekly | B11: Review overtime and capacity pressure | C11: Contract & RAID Risk Audit | D11: Resource leveling recommendation | E11: Any resource >45h/week.
A12: Weekly | B12: Update physical progress evidence | C12: EVM Data / Source Data | D12: EV refresh and progress trend | E12: Progress unchanged while cost increases.
A13: Monthly | B13: Close AC and material costs | C13: CFO & Cost Share Audit | D13: Cost-share and burn-rate update | E13: Actual cost variance >5%.
A14: Monthly | B14: Reforecast EAC/ETC | C14: EVM Data | D14: Revised forecast and commentary | E14: CPI <0.95 or EAC > BAC.
A15: Stage gate | B15: Present cost/schedule/risk pack | C15: Control Tower Dashboard | D15: Go / hold / re-plan recommendation | E15: Red project status or high RAID.
A16: Closeout | B16: Capture lessons learned | C16: Methodology Guide | D16: Estimate calibration notes | E16: Mandatory for completed projects.
A19: KPI Definitions and Workbook Formula Logic
A20: KPI | B20: Definition | C20: Workbook Formula Pattern | D20: Management Meaning
A21: AC | B21: Actual cost incurred. | C21: Labor Cost + Material Cost | D21: What has been spent.
A22: EV | B22: Earned value from physical progress. | C22: BAC * Latest Progress | D22: Value of work earned.
A23: CPI | B23: Cost Performance Index. | C23: EV / AC | D23: <1.00 means over-spend vs earned work.
A24: EAC Typical | B24: Forecast final cost using cost efficiency. | C24: BAC / CPI | D24: Expected final cost if current efficiency continues.
A25: Progress | B25: Portfolio physical completion. | C25: EV / BAC | D25: How much baseline value has been earned.
A26: Cost Share | B26: Labor/material mix. | C26: Category Cost / AC | D26: Where cost is being consumed.
A30: Role Split
A31: Role | B31: Primary Responsibility | C31: Workbook Usage
A32: Project Manager | B32: Own scope, delivery, stakeholder decisions, and corrective action. | C32: Reads dashboard signals and approves interventions.
A33: Project Support / PMO | B33: Maintain process, meeting records, data collection, and reporting cadence. | C33: Keeps source data complete and timely.
A34: Project Controller | B34: Analyze cost, schedule, EVM, forecasts, risks, and scenarios. | C34: Maintains EVM model and explains financial impact.
A37: Project CFO Agent Operating Rules
A38: The controller playbook now includes the Project CFO / Executive Agent rules from SKILL.md. These rules convert project-control analytics into leadership decisions: protect margin, flag >2pp margin deterioration once baseline margin exists, prevent negative project cash balances, and write board-ready action statements.
A42: Rule | B42: Controller Question | C42: Required Workbook Evidence | D42: Decision Output | E42: Escalation Trigger
A43: Profitability First | B43: What is the effect on margin at completion? | C43: EAC, contract value/revenue, cost variance | D43: Margin recovery recommendation | E43: Any EAC increase or CPI below 1.00.
A44: >2pp Margin Variance | B44: Is projected margin >2 percentage points below baseline? | C44: Baseline margin and projected MAC | D44: Executive red flag / recovery plan | E44: MAC variance < -2pp.
A45: Cash Flow Sensitivity | B45: Do billing milestones cover timesheet/material outlays? | C45: Billing schedule, labor/material cash timing | D45: Funding-risk warning | E45: Negative project cash balance forecast.
A46: Strategic Focus | B46: What action should leadership take now? | C46: Owner, financial impact, mitigation | D46: Board-ready bullet recommendation | E46: Any red/amber KPI.
A49: Board Brief Action Template
A50: Board Brief Component | B50: Required Wording | C50: Workbook Source | D50: Example for Current Portfolio
A51: Headline | B51: Action Required: [decision] due to [financial driver]. | C51: Dashboard KPI + Risk Audit | D51: Action Required: protect margin because portfolio CPI is below 1.00.
A52: Financial Impact | B52: Quantify AC, EV, EAC, CPI, cash exposure, or margin variance. | C52: Control Tower Dashboard / EVM Data | D52: AC $5.22M vs EV $4.75M; CPI 0.91.
A53: Owner | B53: Name the accountable project manager/controller. | C53: Project_Summary / RAID owner | D53: Owner depends on project/WBS flagged.
A54: Recommendation | B54: State approve / hold / renegotiate / re-sequence / recover. | C54: Simulator + Controller Playbook | D54: Run recovery scenario before approving additional spend.
A55: Next Review | B55: Set date or cadence for reforecast/checkpoint. | C55: Controller cadence | D55: Review weekly until CPI returns toward 1.00.

Sheet Cover
A1: Project Control Tower Refresh
A2: Executive EVM dashboard rebuilt from attached CSV source files
A4: Contents | B4: Description | D4: RAG Legend
A5: Control Tower Dashboard | B5: Executive portfolio KPIs, project/WBS breakdowns, and charts | D5: Red | E5: Action / escalation required | F5: CPI < 0.90, high risk, missing/gap
A6: Gantt Charts | B6: Portfolio Gantt-of-Gantts and per-project WBS Gantt charts | D6: Amber | E6: Watch / manage closely | F6: CPI 0.90–0.99, partial, active/planned
A7: Methodology Guide | B7: Chris Croft 12-step method plus Project CFO profitability overlay | D7: Green | E7: On track / complete | F7: CPI ≥ 1.00, approved, present, closed
A8: Controller Playbook | B8: Controller cadence, KPI definitions, CFO operating rules, and board brief template | D8: Grey | E8: Not started / neutral | F8: Planned or not applicable
A9: Data Model Map | B9: ERD relationships, integrity rules, and modern PM readiness audit
A10: 3S Readiness Audit | B10: 3-statement readiness and gap assessment | D10: Data Bars
A11: 3S Model Blueprint | B11: Recommended IS/BS/CF build architecture and source mapping | D11: Blue bars | E11: Relative magnitude within comparable numeric columns | F11: Costs, EV, progress, hours, procurement, simulator outputs
A12: EVM Data | B12: Live calculation model using structured source tables | D12: Purpose | E12: Scan highs/lows quickly without replacing RAG status colors | F12: Bars are only applied to numeric comparison ranges
A13: Schedule & Gantt | B13: Project schedule and month-level Gantt view
A14: CFO & Cost Share Audit | B14: Cost-share and resource burn-rate audit | D14: Visual Style Update
A15: Contract & RAID Risk Audit | B15: Overtime, procurement, and RAID exception audit | D15: Tufte cleanup | E15: Muted colors, reduced gridlines, no decorative frames | F15: Dashboard + Gantt charts
A16: Interactive Simulator | B16: Editable what-if corrective action and crash simulator | D16: Color meaning | E16: Grey = plan/baseline, black = actual, blue = earned/progress | F16: Red/amber reserved for RAG risk flags
A17: Source Data | B17: Imported CSV source tables

Sheet Gantt Charts
A1: PORTFOLIO & PROJECT GANTT CHARTS | T1: Project | U1: Start Offset | V1: Duration Days | W1: Start | X1: End | Y1: Status
A2: Portfolio-level Gantt-of-Gantts plus per-project WBS Gantts. WBS dates are planning estimates allocated within each project window by WBS planned-cost weight because source WBS start/end dates are not available. | T2: PRJ-001 Composite Maritime Vessel Construction | U2: 46023 | V2: 181 | W2: 46023 | X2: 46203 | Y2: Completed
T3: PRJ-002 Patrol Vessel Carbon Mold Design | U3: 46235 | V3: 153 | W3: 46235 | X3: 46387 | Y3: Planned
T4: PRJ-003 Subsea Cable Installation Frame | U4: 46143 | V4: 184 | W4: 46143 | X4: 46326 | Y4: Active
T5: PRJ-004 Autonomous Workboat Hull Weldments | U5: 46082 | V5: 184 | W5: 46082 | X5: 46265 | Y5: Active
T6: PRJ-005 Defense Logistics Pontoon Build | U6: 46054 | V6: 181 | W6: 46054 | X6: 46234 | Y6: Active
T7: PRJ-006 Lightweight Composite Cargo Hatch | U7: 46113 | V7: 61 | W7: 46113 | X7: 46173 | Y7: Completed
T10: Task | U10: Start Offset | V10: Duration Days | W10: Start | X10: End | Y10: Status
T11: 1 Project Management & Engineering | U11: 46023 | V11: 36 | W11: 46023 | X11: 46058 | Y11: 🔴 Overrun
T12: 2 Hull Fabrication & Assembly | U12: 46059 | V12: 72 | W12: 46059 | X12: 46130 | Y12: 🟡 Complete/Watch
T13: 3 Outfitting & Integration | U13: 46131 | V13: 48 | W13: 46131 | X13: 46178 | Y13: 🔴 Overrun
T14: 4 Sea Trials & Handover | U14: 46179 | V14: 25 | W14: 46179 | X14: 46203 | Y14: 🔴 Overrun
T17: Task | U17: Start Offset | V17: Duration Days | W17: Start | X17: End | Y17: Status
T18: 1 Design & CFD Analysis | U18: 46235 | V18: 57 | W18: 46235 | X18: 46291 | Y18: ⚪ Planned
T19: 2 Material Procurement | U19: 46292 | V19: 96 | W19: 46292 | X19: 46387 | Y19: ⚪ Planned
T22: Task | U22: Start Offset | V22: Duration Days | W22: Start | X22: End | Y22: Status
T23: 1 Structural Frame Engineering | U23: 46143 | V23: 61 | W23: 46143 | X23: 46203 | Y23: 🟢 On Track
T24: 2 Steel Fabrication | U24: 46204 | V24: 123 | W24: 46204 | X24: 46326 | Y24: 🔴 Overrun
T27: Task | U27: Start Offset | V27: Duration Days | W27: Start | X27: End | Y27: Status
T28: 1 Engineering Drawings & Class Approval | U28: 46082 | V28: 46 | W28: 46082 | X28: 46127 | Y28: 🟢 Completed
T29: 2 Hull Welding & Assembly | U29: 46128 | V29: 138 | W29: 46128 | X29: 46265 | Y29: 🔴 Overrun
T32: Task | U32: Start Offset | V32: Duration Days | W32: Start | X32: End | Y32: Status
T33: 1 Project Control & PM | U33: 46054 | V33: 36 | W33: 46054 | X33: 46089 | Y33: 🟢 Completed
T34: 2 Pontoon Assembly & Painting | U34: 46090 | V34: 145 | W34: 46090 | X34: 46234 | Y34: 🟡 Watch
T37: Task | U37: Start Offset | V37: Duration Days | W37: Start | X37: End | Y37: Status
T38: 1 Hatch Engineering & FEA | U38: 46113 | V38: 20 | W38: 46113 | X38: 46132 | Y38: 🟢 Completed
T39: 2 Molding & Testing | U39: 46133 | V39: 41 | W39: 46133 | X39: 46173 | Y39: 🟡 Complete/Watch
T42: RAG / Today Legend
T43: Green | U43: Complete / on track
T44: Amber | U44: Active / watch / warning
T45: Red | U45: Overrun / escalation
T46: Grey | U46: Planned / not started
T47: Blue dotted line | U47: Present date: 01-Aug-2026
A78: Gantt Assumption & Source Notes
A79: Portfolio chart uses actual project dates from Schedule & Gantt. Individual project Gantts use WBS elements from EVM Data and allocate each WBS task sequentially across the project date range by planned-cost weight because WBS-level start/end dates are not present in the source data.
A84: Visual Style Applied
A85: Tufte-style cleanup applied: muted functional colors, reduced chart ink, no decorative frames, minimized gridlines, and hidden Gantt legends where the dummy start series adds no meaning.

Sheet Control Tower Dashboard
A1: ⚓ PROJECT CONTROL TOWER DASHBOARD
A2: Relational EVM & Analytical Controller Dashboard | PRINCE2 Compliance | Refreshed from 8 CSV sources
A4: BUDGET (BAC) | C4: ACTUAL COST (AC) | E4: EARNED VALUE (EV) | G4: CPI | I4: PROGRESS | K4: Metric | L4: Value | M4: Signal | N4: Owner
A5: =SUM(Project_Summary[BAC]) -> 7100000 | C5: =SUM(Project_Summary[AC]) -> 5220810 | E5: =SUM(Project_Summary[EV]) -> 4752500 | G5: =E5/C5 -> 0.91029936 | I5: =E5/A5 -> 0.6693662 | K5: Active RAID | L5: =COUNTIF('Contract & RAID Risk Audit'!H27:H29,"Active") -> 3 | M5: Open risk exposure | N5: Risk Audit
K6: Overtime Events | L6: =COUNTA('EVM Data'!T18:T25) -> 8 | M6: Capacity anomaly | N6: Risk Audit
A7: Executive Portfolio Summary | K7: Large Purchases | L7: =COUNTA('Contract & RAID Risk Audit'!D19:D23) -> 5 | M7: Procurement control | N7: Risk Audit
A8: ="The portfolio contains "&COUNTA(Project_Summary[Project ID])&" projects with a total BAC of "&TEXT(A5,"$#,##0")&", actual cost of "&TEXT(C5,"$#,##0")&", and earned value of "&TEXT(E5,"$#,##0")&". Current CPI is "&TEXT(G5,"0.00")&", meaning the portfolio is earning about "&TEXT(G5,"$0.00")&" for every $1.00 spent. The largest executive pressure is cost control: PRJ-001 is over budget, while three active projects remain below CPI 1.00." -> The portfolio contains 6 projects with a total BAC of $7,100,000, actual cost of $5,220,810, and earned value of $4,752,500. Current CPI is 0.91, meaning the portfolio is earning about $0.91 for every $1.00 spent. The largest executive pressure is cost control: PRJ-001 is over budget, while three active projects remain below CPI 1.00. | K8: Labor Share | L8: =SUM('EVM Data'!I6:I19)/SUM('EVM Data'!K6:K19) -> 0.79466788 | M8: Cost mix | N8: CFO
K9: Material Share | L9: =SUM('EVM Data'!J6:J19)/SUM('EVM Data'!K6:K19) -> 0.20533212 | M9: Cost mix | N9: CFO
K10: Worst Project CPI | L10: =MIN('EVM Data'!G25:G30) -> 0.80727603 | M10: Cost pressure | N10: Executive
A12: Portfolio Project Breakdown
A13: Project ID | B13: Project Name | C13: Manager | D13: BAC | E13: AC | F13: EV | G13: CPI | H13: Progress | I13: Status
A14: {=Project_Summary[[Project ID]:[Status]]} -> PRJ-001 | B14: Composite Maritime Vessel Construction | C14: Morten Hansen | D14: 1500000 | E14: 1848810 | F14: 1492500 | G14: 0.80727603 | H14: 0.995 | I14: 1858100.5 | J14: 🔴 Over Budget
A15: PRJ-002 | B15: PRJ-002: Patrol Vessel Carbon Mold Design | C15: Morten Hansen | D15: 800000 | E15: 0 | F15: 0 | G15: 1 | H15: 0 | J15: ⚪ Planned
A16: PRJ-003 | B16: PRJ-003: Subsea Cable Installation Frame | C16: Erik Johansen | D16: 1200000 | E16: 382500 | F16: 360000 | G16: 0.94117647 | H16: 0.3 | I16: 1275000 | J16: 🔴 Overrun Warn
A17: PRJ-004 | B17: PRJ-004: Autonomous Workboat Hull Weldments | C17: Astrid Nilsen | D17: 2000000 | E17: 1476000 | F17: 1400000 | G17: 0.94850949 | H17: 0.7 | I17: 2108571.4 | J17: 🔴 Overrun Warn
A18: PRJ-005 | B18: PRJ-005: Defense Logistics Pontoon Build | C18: Frank Ellingsen | D18: 1000000 | E18: 927000 | F18: 900000 | G18: 0.97087379 | H18: 0.9 | I18: 1030000 | J18: 🟡 Within Margins
A19: PRJ-006 | B19: PRJ-006: Lightweight Composite Cargo Hatch | C19: Morten Hansen | D19: 600000 | E19: 586500 | F19: 600000 | G19: 1.0230179 | H19: 1 | I19: 586500 | J19: 🟢 Completed
A22: WBS Element Performance Details
A23: WBS Code | B23: Element Name | C23: BAC | D23: AC | E23: EV | F23: CPI | G23: Progress | H23: EAC Typical | I23: Status
A24: {=_xlfn.CHOOSECOLS(WBS_Performance[],3,4,7,11,12,13,8,14,15)} -> 1 | B24: Project Management & Engineering | C24: 300000 | D24: 419230 | E24: 292500 | F24: 0.6977077 | G24: 0.975 | H24: 429979.49 | I24: 🔴 Overrun
A25: 2 | B25: Hull Fabrication & Assembly | C25: 600000 | D25: 620450 | E25: 600000 | F25: 0.96704005 | G25: 1 | H25: 620450 | I25: 🟡 Complete/Watch
A26: 3 | B26: Outfitting & Integration | C26: 400000 | D26: 540445 | E26: 400000 | F26: 0.74013082 | G26: 1 | H26: 540445 | I26: 🔴 Overrun
A27: 4 | B27: Sea Trials & Handover | C27: 200000 | D27: 268685 | E27: 200000 | F27: 0.74436608 | G27: 1 | H27: 268685 | I27: 🔴 Overrun
A28: 1 | B28: Design & CFD Analysis | C28: 300000 | D28: 0 | E28: 0 | F28: 1 | G28: 0 | I28: ⚪ Planned
A29: 2 | B29: Material Procurement | C29: 500000 | D29: 0 | E29: 0 | F29: 1 | G29: 0 | I29: ⚪ Planned
A30: 1 | B30: Structural Frame Engineering | C30: 400000 | D30: 332500 | E30: 360000 | F30: 1.0827068 | G30: 0.9 | H30: 369444.44 | I30: 🟢 On Track
A31: 2 | B31: Steel Fabrication | C31: 800000 | D31: 50000 | E31: 0 | F31: 0 | G31: 0 | I31: 🔴 Overrun
A32: 1 | B32: Engineering Drawings & Class Approval | C32: 500000 | D32: 456000 | E32: 500000 | F32: 1.0964912 | G32: 1 | H32: 456000 | I32: 🟢 Completed
A33: 2 | B33: Hull Welding & Assembly | C33: 1500000 | D33: 1020000 | E33: 900000 | F33: 0.88235294 | G33: 0.6 | H33: 1700000 | I33: 🔴 Overrun
A34: 1 | B34: Project Control & PM | C34: 200000 | D34: 187000 | E34: 200000 | F34: 1.0695187 | G34: 1 | H34: 187000 | I34: 🟢 Completed
A35: 2 | B35: Pontoon Assembly & Painting | C35: 800000 | D35: 740000 | E35: 700000 | F35: 0.94594595 | G35: 0.875 | H35: 845714.29 | I35: 🟡 Watch
A36: 1 | B36: Hatch Engineering & FEA | C36: 200000 | D36: 180500 | E36: 200000 | F36: 1.1080332 | G36: 1 | H36: 180500 | I36: 🟢 Completed
A37: 2 | B37: Molding & Testing | C37: 400000 | D37: 406000 | E37: 400000 | F37: 0.98522167 | G37: 1 | H37: 406000 | I37: 🟡 Complete/Watch

Sheet Data Model Map
A1: PROJECT CONTROLLING DATA MODEL MAP
A2: ERD-driven source-table relationships and integrity rules from datamodel_erd.md
A4: Relational Model Summary
A5: The workbook follows the ERD pattern: Projects contain WBS elements; WBS elements receive resource assignments, timesheets, material costs, and physical-progress records; resources log hours; RAID items track risks/issues/dependencies. EVM is calculated by joining these tables at WBS level and rolling up to project and portfolio level. The modern-PM audit below extends this model with required gaps for PV/SPI, stage-gates, portfolio governance, stakeholder reporting, cash-flow/WIP, quality, and lessons learned.
A9: Entity / Table | B9: Primary Key | C9: Key Foreign Keys | D9: Purpose | E9: Workbook Location
A10: Projects | B10: ProjectID | C10: — | D10: Project master, manager, BAC, dates, status | E10: Source Data / Project_Summary
A11: WBS_ELEMENTS | B11: WBS_ID | C11: ProjectID | D11: Work package budget and planned hours | E11: Source Data / WBS_Performance
A12: Resources | B12: ResourceID | C12: — | D12: People/roles/rates | E12: Source Data / CFO Audit
A13: Resource_Assignments | B13: AssignmentID | C13: WBS_ID, ResourceID | D13: Planned resource allocation | E13: Source Data
A14: Timesheets | B14: TimesheetID | C14: WBS_ID, ResourceID | D14: Actual labor hours | E14: Source Data / WBS_Source_Summary
A15: Material_Costs | B15: PurchaseID | C15: WBS_ID | D15: Actual material/procurement cost | E15: Source Data / Risk Audit
A16: Physical_Progress | B16: ProgressID | C16: WBS_ID | D16: Physical completion records driving EV | E16: Source Data / EVM Data
A17: RAID_Log | B17: RiskID | C17: — | D17: Risks, assumptions, issues, dependencies | E17: Source Data / Risk Audit
A21: Integrity Rules
A22: Rule | B22: Relationship / Logic | C22: Workbook Check
A23: Projects to WBS | B23: 1:N; each WBS element belongs to one project. | C23: WBS ProjectID must exist in Projects.
A24: Resources to timesheets | B24: 1:N; each timesheet row has a valid resource. | C24: Timesheet ResourceID must exist in Resources.
A25: WBS to timesheets/materials/progress | B25: 1:N; actuals and EV attach to WBS. | C25: WBS_ID must exist in WBS table.
A26: Labor cost | B26: Actual Labor Cost = HoursWorked * HourlyRate. | C26: WBS_Source_Summary LaborCost reconciles to timesheets.
A27: Material cost | B27: Actual material cost is summed by WBS. | C27: Large purchases > $50k are flagged.
A28: Earned value | B28: EV = PlannedCost * PercentComplete. | C28: WBS_Performance EV column.
A29: Project rollup | B29: Project AC/EV/CPI sums from WBS rows. | C29: Project_Summary table.
A32: Workbook Data Flow
A33: Layer | B33: Tables / Sheets | C33: Output
A34: Raw source | B34: Source Data tables | C34: CSV import layer
A35: WBS calculation | B35: EVM Data!WBS_Performance | C35: AC, EV, CPI, EAC by WBS
A36: Project rollup | B36: EVM Data!Project_Summary | C36: BAC, AC, EV, CPI by project
A37: Executive reporting | B37: Control Tower Dashboard | C37: Portfolio KPIs and charts
A38: Exception control | B38: CFO / Risk Audit sheets | C38: Overtime, procurement, RAID, cost share
A39: Decision support | B39: Interactive Simulator | C39: Corrective-action scenario impact
A42: Modern PM / Controlling Readiness Audit
A43: Audit based on glossary.md, modern_pm.md, and PM-Simplified.md: the workbook has a strong EVM cost spine (BAC, AC, EV, CPI, EAC), source-table ERD, RAID log, and executive dashboard. The main modern-PM gaps are PV/SPI/schedule variance, stage-gate metadata, stakeholder-specific reporting slices, revenue/cash-flow/WIP fields, resource capacity baselines, quality KPIs, and quantified risk exposure. These gaps matter because modern project controlling combines EVM, hybrid/stage-gate governance, portfolio dashboards, margin/cash-flow views, and BI-ready data definitions.
A48: Modern PM Requirement | B48: Readiness | C48: Evidence in Current Workbook | D48: Data Model / Workbook Action
A49: EVM core: BAC / AC / EV / CPI | B49: Present | C49: Dashboard and EVM Data include BAC, AC, EV, CPI and EAC. | D49: Retain as core fact layer; add formal PV/SPI.
A50: PV / SV / SPI schedule EVM | B50: Gap | C50: Glossary and modern_pm emphasize PV, SV = EV-PV, SPI = EV/PV. Workbook lacks PV baseline by date. | D50: Add planned value curve by WBS/date and SPI in EVM Data.
A51: Objective physical progress | B51: Partial | C51: Physical progress table exists and drives EV, but measurement method/acceptance criteria are not stored. | D51: Add progress basis, milestone acceptance, and reported evidence fields.
A52: EAC / ETC / VAC / TCPI | B52: Partial | C52: EAC exists; ETC/VAC/TCPI are not explicit portfolio metrics. | D52: Add ETC=EAC-AC, VAC=BAC-EAC, TCPI=(BAC-EV)/(BAC-AC).
A53: Hybrid / agile / stage-gate governance | B53: Gap | C53: Guidance recommends agile within stage-gate for complex projects; workbook has no phase/gate entities. | D53: Add Stage, Gate, Decision, Gate Status, Approval Date fields.
A54: Portfolio management / PPM | B54: Partial | C54: Portfolio dashboard compares projects, but prioritization/resource-capacity scoring is missing. | D54: Add strategic priority, capacity demand, and portfolio rank.
A55: Stakeholder reporting hierarchy | B55: Partial | C55: Executive dashboard exists; role-specific views for PL/PMO/CFO/team are not formalized. | D55: Add stakeholder-to-KPI matrix and report cadence fields.
...

Sheet 3S Readiness Audit
A1: 3-STATEMENT MODEL READINESS AUDIT
A2: Audit of current project-control workbook against integrated IS / BS / CF model requirements
A4: Executive Assessment
A5: The current workbook is strong as an EVM/project-control model, but it is not yet a complete 3-statement financial model. It contains cost, earned value, resource, procurement, RAID, and scenario data that can feed parts of an Income Statement and operating forecast; however, it lacks full revenue recognition, Balance Sheet accounts, working-capital schedules, debt/equity schedules, tax/NOL logic, and Cash Flow Statement tie-outs. The readiness status is therefore 'PARTIAL — project-cost model ready, corporate 3-statement model not ready'.
A10: Readiness Metric | B10: Live Value | C10: Status
A11: Portfolio BAC | B11: ='Control Tower Dashboard'!A5 -> 7100000 | C11: Available as project budget, not revenue.
A12: Actual Cost | B12: ='Control Tower Dashboard'!C5 -> 5220810 | C12: Available as operating/project cost base.
A13: Earned Value | B13: ='Control Tower Dashboard'!E5 -> 4752500 | C13: Available as EVM production value, not GAAP revenue.
A14: Portfolio CPI | B14: ='Control Tower Dashboard'!G5 -> 0.91029936 | C14: Useful for forecast/EAC stress testing.
A15: Progress | B15: ='Control Tower Dashboard'!I5 -> 0.6693662 | C15: Useful for revenue/progress recognition proxy only if policy confirmed.
A18: Statement Area | B18: Required Component | C18: Readiness | D18: Workbook Evidence | E18: Next Action
A19: Income Statement | B19: Revenue / Net Sales | C19: Missing | D19: No customer revenue, contract value, or revenue-recognition policy is in the workbook. | E19: Add contract revenue schedule by project and period.
A20: Income Statement | B20: COGS / Direct Costs | C20: Partial | D20: Labor and material costs exist by WBS and project. | E20: Map WBS actual/projected cost into cost of revenue.
A21: Income Statement | B21: Gross Profit / Margins | C21: Missing | D21: No revenue line means gross profit and margins cannot be calculated. | E21: Add revenue and cost-of-revenue classification.
A22: Income Statement | B22: Operating Expenses | C22: Missing | D22: No SG&A, R&D, overhead, D&A, SBC, or other OpEx categories. | E22: Add OpEx assumptions by period.
A23: Income Statement | B23: EBIT / EBITDA / Taxes / Net Income | C23: Missing | D23: No D&A, interest, tax, or income statement closeout. | E23: Add D&A, debt/interest, tax/NOL schedules.
A24: Balance Sheet | B24: Cash | C24: Missing | D24: Simulator shows cost impact but no formal cash balance. | E24: Add opening cash and CF-linked ending cash.
A25: Balance Sheet | B25: Working Capital | C25: Missing | D25: No AR, inventory, AP, DSO, DIO, DPO schedules. | E25: Add WC schedule linked to revenue/COGS.
A26: Balance Sheet | B26: PP&E / D&A | C26: Missing | D26: No fixed asset roll-forward or depreciation schedule. | E26: Add CapEx and depreciation schedule.
A27: Balance Sheet | B27: Debt / Equity | C27: Missing | D27: No debt balance, interest rate, repayment, equity, retained earnings. | E27: Add debt and equity schedules.
A28: Cash Flow Statement | B28: CFO | C28: Missing | D28: No net income, non-cash addbacks, or WC movement. | E28: Build CFO from IS + WC + D&A.
A29: Cash Flow Statement | B29: CFI | C29: Missing | D29: No CapEx or investing activities. | E29: Add CapEx assumptions and PP&E linkage.
... A33: Checks | B33: Formula Integrity | C33: Partial | D33: EVM formulas exist and no visible errors were previously verified. | E33: Add statement-specific checks once IS/BS/CF are created.
A36: Master 3-Statement Readiness Status
A37: Check | B37: Formula / Logic | C37: Result
A38: Formal IS/BS/CF tabs present | B38: Income Statement, Balance Sheet, Cash Flow Statement tabs exist | C38: FALSE
A39: Project-control source data present | B39: BAC, AC and EV are populated | C39: =AND('Control Tower Dashboard'!A5>0,'Control Tower Dashboard'!C5>0,'Control Tower Dashboard'!E5>0) -> TRUE
A40: Overall readiness | B40: Combines formal statement tabs and source-data availability | C40: =IF(C38=TRUE,"READY FOR FULL 3S CHECKS",IF(C39=TRUE,"PARTIAL — EVM/cost data available; IS/BS/CF missing","NOT READY")) -> PARTIAL — EVM/cost data available; IS/BS/CF missing

Sheet 3S Model Blueprint
A1: 3-STATEMENT MODEL BLUEPRINT
A2: Recommended build path to convert the EVM workbook into an integrated Income Statement / Balance Sheet / Cash Flow model
A4: Recommended Tab Architecture
A6: Proposed Sheet | B6: Purpose | C6: Primary Inputs | D6: Key Outputs | E6: Build Priority
A7: Assumptions | B7: Scenario toggle, fiscal periods, revenue policy, tax rate, working-capital days, CapEx %, debt terms | C7: User inputs / management assumptions | D7: Drivers for IS/BS/CF | E7: 1
A8: Income Statement | B8: Revenue, COGS, OpEx, D&A, EBIT, interest, tax, net income | C8: Revenue schedule + WBS costs + assumptions | D8: Net Income, EBITDA, margins | E8: 2
A9: Working Capital | B9: AR, inventory, AP, DSO/DIO/DPO and ΔNWC | C9: Revenue, COGS, WC day assumptions | D9: ΔWC for CFO, BS current accounts | E9: 3
A10: PP&E / D&A | B10: Gross PP&E, CapEx, accumulated depreciation, net PP&E | C10: CapEx %, depreciation life | D10: D&A, PP&E net | E10: 4
A11: Debt Schedule | B11: Debt roll-forward, interest expense, repayments | C11: Opening debt, rates, repayments | D11: Interest expense, ending debt | E11: 5
A12: Balance Sheet | B12: Assets, liabilities, equity, retained earnings | C12: IS + WC + D&A + debt + CF | D12: Balanced BS, cash, equity | E12: 6
A13: Cash Flow Statement | B13: CFO, CFI, CFF, ending cash | C13: IS + BS changes + schedules | D13: Ending cash and FCF | E13: 7
A14: 3S Checks | B14: BS balance, cash tie-out, NI link, RE roll-forward, formula integrity | C14: All model tabs | D14: Master check status | E14: 8
A18: Current Workbook Data Mapping
A20: Existing Workbook Source | B20: Can Feed 3S Line Item | C20: Limitation / Assumption Needed | D20: Suggested Formula Logic
A21: Project_Summary[BAC] | B21: Backlog / contract budget / project budget | C21: Not equivalent to GAAP revenue unless revenue policy is confirmed. | D21: Revenue schedule should reference contract value and % complete rules.
A22: WBS_Performance[Labor Cost] | B22: Direct labor / cost of revenue | C22: Need classification between COGS vs SG&A/engineering overhead. | D22: Cost of Revenue = classified labor + materials.
A23: WBS_Performance[Material Cost] | B23: Material COGS / inventory consumption | C23: Need inventory vs direct-expense policy. | D23: COGS = material usage or purchases depending policy.
A24: WBS_Performance[EV] | B24: Progress / production value proxy | C24: EV is not automatically revenue. | D24: Revenue = contract value × recognized progress if policy allows.
A25: WBS_Performance[EAC Typical] | B25: Forecast project cost | C25: Useful for cost forecast but not full financial statement. | D25: Forecast COGS = EAC by project/WBS.
A26: Weekly_Overtime | B26: Labor risk / productivity pressure | C26: Does not directly post to financial statements. | D26: Use as margin risk driver or contingency flag.
A27: RAID | B27: Risk reserve / disclosure input | C27: Requires quantified probability × impact to affect model. | D27: Contingency = SUM(probability × impact).
A31: Core 3S Checks to Add After Build
A33: Check | B33: Formula Pattern | C33: Expected Result
A34: Balance Sheet Balance | B34: Total Assets - Total Liabilities - Total Equity | C34: 0
A35: Cash Tie-Out | B35: CF Ending Cash - BS Cash | C35: 0
A36: Net Income Link | B36: IS Net Income - CF Starting Net Income | C36: 0
A37: Retained Earnings | B37: Prior RE + Net Income - Dividends - Ending RE | C37: 0
A38: Debt Tie-Out | B38: Debt Schedule Ending Debt - BS Total Debt | C38: 0
A39: Formula Errors | B39: COUNT of #REF!, #DIV/0!, #VALUE!, #NAME? across model ranges | C39: 0
A42: Formula Color Convention
A43: Convention | B43: Color | C43: Meaning | D43: Applied To
A44: Blue font | B44: #0000FF | C44: Hardcoded input | D44: Assumptions and historical data
A45: Black font | B45: #000000 | C45: Calculation formula | D45: Operating calculations
A46: Purple font | B46: #800080 | C46: Same-sheet link | D46: Line-item references
A47: Green font | B47: #008000 | C47: Cross-sheet link | D47: Statement and schedule links

Sheet Schedule & Gantt
A1: 📅 PORTFOLIO GANTT & SCHEDULE
A2: Project start/end dates from projects.csv with month-level timeline
A5: Project ID | B5: Project / Task | C5: Start Date | D5: End Date | E5: Duration (Days) | F5: Status | G5: Manager | H5: Critical? | I5: 46023 | J5: 46054 | K5: 46082 | L5: 46113 | M5: 46143 | N5: 46174
A6: PRJ-001 | B6: Composite Maritime Vessel Construction | C6: 46023 | D6: 46203 | E6: =D6-C6+1 -> 181 | F6: Completed | G6: Morten Hansen | H6: Yes | I6: =IF(AND(DATE(2026,1,1)<=$D6,EOMONTH(DATE(2026,1,1),0)>=$C6),"■","") -> ■ | J6: =IF(AND(DATE(2026,2,1)<=$D6,EOMONTH(DATE(2026,2,1),0)>=$C6),"■","") -> ■ | K6: =IF(AND(DATE(2026,3,1)<=$D6,EOMONTH(DATE(2026,3,1),0)>=$C6),"■","") -> ■ | L6: =IF(AND(DATE(2026,4,1)<=$D6,EOMONTH(DATE(2026,4,1),0)>=$C6),"■","") -> ■ | M6: =IF(AND(DATE(2026,5,1)<=$D6,EOMONTH(DATE(2026,5,1),0)>=$C6),"■","") -> ■ | N6: =IF(AND(DATE(2026,6,1)<=$D6,EOMONTH(DATE(2026,6,1),0)>=$C6),"■","") -> ■
A7: PRJ-002 | B7: Patrol Vessel Carbon Mold Design | C7: 46235 | D7: 46387 | E7: =D7-C7+1 -> 153 | F7: Planned | G7: Morten Hansen | H7: No | I7: =IF(AND(DATE(2026,1,1)<=$D7,EOMONTH(DATE(2026,1,1),0)>=$C7),"■","") | J7: =IF(AND(DATE(2026,2,1)<=$D7,EOMONTH(DATE(2026,2,1),0)>=$C7),"■","") | K7: =IF(AND(DATE(2026,3,1)<=$D7,EOMONTH(DATE(2026,3,1),0)>=$C7),"■","") | L7: =IF(AND(DATE(2026,4,1)<=$D7,EOMONTH(DATE(2026,4,1),0)>=$C7),"■","") | M7: =IF(AND(DATE(2026,5,1)<=$D7,EOMONTH(DATE(2026,5,1),0)>=$C7),"■","") | N7: =IF(AND(DATE(2026,6,1)<=$D7,EOMONTH(DATE(2026,6,1),0)>=$C7),"■","")
A8: PRJ-003 | B8: Subsea Cable Installation Frame | C8: 46143 | D8: 46326 | E8: =D8-C8+1 -> 184 | F8: Active | G8: Erik Johansen | H8: No | I8: =IF(AND(DATE(2026,1,1)<=$D8,EOMONTH(DATE(2026,1,1),0)>=$C8),"■","") | J8: =IF(AND(DATE(2026,2,1)<=$D8,EOMONTH(DATE(2026,2,1),0)>=$C8),"■","") | K8: =IF(AND(DATE(2026,3,1)<=$D8,EOMONTH(DATE(2026,3,1),0)>=$C8),"■","") | L8: =IF(AND(DATE(2026,4,1)<=$D8,EOMONTH(DATE(2026,4,1),0)>=$C8),"■","") | M8: =IF(AND(DATE(2026,5,1)<=$D8,EOMONTH(DATE(2026,5,1),0)>=$C8),"■","") -> ■ | N8: =IF(AND(DATE(2026,6,1)<=$D8,EOMONTH(DATE(2026,6,1),0)>=$C8),"■","") -> ■
A9: PRJ-004 | B9: Autonomous Workboat Hull Weldments | C9: 46082 | D9: 46265 | E9: =D9-C9+1 -> 184 | F9: Active | G9: Astrid Nilsen | H9: Yes | I9: =IF(AND(DATE(2026,1,1)<=$D9,EOMONTH(DATE(2026,1,1),0)>=$C9),"■","") | J9: =IF(AND(DATE(2026,2,1)<=$D9,EOMONTH(DATE(2026,2,1),0)>=$C9),"■","") | K9: =IF(AND(DATE(2026,3,1)<=$D9,EOMONTH(DATE(2026,3,1),0)>=$C9),"■","") -> ■ | L9: =IF(AND(DATE(2026,4,1)<=$D9,EOMONTH(DATE(2026,4,1),0)>=$C9),"■","") -> ■ | M9: =IF(AND(DATE(2026,5,1)<=$D9,EOMONTH(DATE(2026,5,1),0)>=$C9),"■","") -> ■ | N9: =IF(AND(DATE(2026,6,1)<=$D9,EOMONTH(DATE(2026,6,1),0)>=$C9),"■","") -> ■
A10: PRJ-005 | B10: Defense Logistics Pontoon Build | C10: 46054 | D10: 46234 | E10: =D10-C10+1 -> 181 | F10: Active | G10: Frank Ellingsen | H10: Yes | I10: =IF(AND(DATE(2026,1,1)<=$D10,EOMONTH(DATE(2026,1,1),0)>=$C10),"■","") | J10: =IF(AND(DATE(2026,2,1)<=$D10,EOMONTH(DATE(2026,2,1),0)>=$C10),"■","") -> ■ | K10: =IF(AND(DATE(2026,3,1)<=$D10,EOMONTH(DATE(2026,3,1),0)>=$C10),"■","") -> ■ | L10: =IF(AND(DATE(2026,4,1)<=$D10,EOMONTH(DATE(2026,4,1),0)>=$C10),"■","") -> ■ | M10: =IF(AND(DATE(2026,5,1)<=$D10,EOMONTH(DATE(2026,5,1),0)>=$C10),"■","") -> ■ | N10: =IF(AND(DATE(2026,6,1)<=$D10,EOMONTH(DATE(2026,6,1),0)>=$C10),"■","") -> ■
A11: PRJ-006 | B11: Lightweight Composite Cargo Hatch | C11: 46113 | D11: 46173 | E11: =D11-C11+1 -> 61 | F11: Completed | G11: Morten Hansen | H11: No | I11: =IF(AND(DATE(2026,1,1)<=$D11,EOMONTH(DATE(2026,1,1),0)>=$C11),"■","") | J11: =IF(AND(DATE(2026,2,1)<=$D11,EOMONTH(DATE(2026,2,1),0)>=$C11),"■","") | K11: =IF(AND(DATE(2026,3,1)<=$D11,EOMONTH(DATE(2026,3,1),0)>=$C11),"■","") | L11: =IF(AND(DATE(2026,4,1)<=$D11,EOMONTH(DATE(2026,4,1),0)>=$C11),"■","") -> ■ | M11: =IF(AND(DATE(2026,5,1)<=$D11,EOMONTH(DATE(2026,5,1),0)>=$C11),"■","") -> ■ | N11: =IF(AND(DATE(2026,6,1)<=$D11,EOMONTH(DATE(2026,6,1),0)>=$C11),"■","")

Sheet CFO & Cost Share Audit
A1: 💼 CFO PROFITABILITY & COST SHARE AUDIT
A2: Resource and material allocations, burn rates, and cost-share indicators
A5: Cost-Share Breakdown
A6: Category | B6: Actual Cost (USD) | C6: Share %
A7: Labor Costs | B7: =SUM('EVM Data'!I6:I19) -> 4148810 | C7: =B7/$B$9 -> 0.79466788
A8: Material & Procurement Costs | B8: =SUM('EVM Data'!J6:J19) -> 1072000 | C8: =B8/$B$9 -> 0.20533212
A9: TOTAL ACTUAL COST | B9: =SUM(B7:B8) -> 5220810 | C9: =1 -> 1
A12: Resource Burn Rates
A13: Resource Name | B13: Role | C13: Hourly Rate (USD) | D13: Hours Logged | E13: Total Cost Logged (USD)
A14: Astrid Nilsen | B14: Structural Welder | C14: 700 | D14: =SUMIFS(Timesheets[HoursWorked],Timesheets[ResourceID],"RES-004") -> 4290.1143 | E14: =C14*D14 -> 3003080
A15: Erik Johansen | B15: Senior Design Engineer | C15: 950 | D15: =SUMIFS(Timesheets[HoursWorked],Timesheets[ResourceID],"RES-003") -> 1228.5053 | E15: =C15*D15 -> 1167080
A16: Lars Olsen | B16: Marine Electrician | C16: 750 | D16: =SUMIFS(Timesheets[HoursWorked],Timesheets[ResourceID],"RES-005") -> 498.8 | E16: =C16*D16 -> 374100
A17: Morten Hansen | B17: Project Manager | C17: 1000 | D17: =SUMIFS(Timesheets[HoursWorked],Timesheets[ResourceID],"RES-002") -> 743.5 | E17: =C17*D17 -> 743500
A18: Frank Ellingsen | B18: Project Controller | C18: 850 | D18: =SUMIFS(Timesheets[HoursWorked],Timesheets[ResourceID],"RES-001") -> 382.3 | E18: =C18*D18 -> 324955

Sheet Contract & RAID Risk Audit
A1: 🚨 CONTRACT, RISK & ANOMALY AUDIT
A2: Weekly overtime limits, high-value invoices, and active RAID registry
A5: Overtime Audits (>45 Hours/Week)
A6: {=Weekly_Overtime[]} -> WBS-013 | B6: 1 | C6: 180500 | D6: 0
A7: WBS-014 | B7: 1 | C7: 336000 | D7: 70000
A8: 2026-11 | B8: Erik Johansen | C8: Senior Design Engineer | D8: 480
A9: 2025-46 | B9: Astrid Nilsen | C9: Structural Welder | D9: 461.5
A10: 2026-19 | B10: Erik Johansen | C10: Senior Design Engineer | D10: 389.5
A11: 2026-08 | B11: Frank Ellingsen | C11: Project Controller | D11: 133.3
A12: 2025-42 | B12: Morten Hansen | C12: Project Manager | D12: 200
A13: 2026-13 | B13: Astrid Nilsen | C13: Structural Welder | D13: 46.3
A17: Large Procurement Audits (>$50,000)
A18: Purchase Date | B18: Invoice Number | C18: Description | D18: Cost (USD)
A19: 46106 | B19: MAT-4001 | C19: Consumables & Steel Plates | D19: 250000
A20: 46082 | B20: MAT-5001 | C20: Paint & Marine Alloy Plates | D20: 180000
A21: 46058 | B21: INV-001 | C21: Structural Composite Carbon Sheets | D21: 150000
A22: 46144 | B22: INV-007 | C22: Twin Electric Inboard Engines | D22: 130000
A23: 45962 | B23: MAT-6001 | C23: Composite Cutting Fiber | D23: 70000
A25: Active RAID Log Register
A26: RAID ID | B26: Category | C26: Description | D26: Impact | E26: Probability | F26: Mitigation Strategy | G26: Owner | H26: Status
A27: R-001 | B27: Risk | C27: Delay in composite carbon sheet deliveries from overseas supplier | D27: High | E27: Medium | F27: Pre-order early or source alternative local supplier | G27: Morten Hansen | H27: Active
A28: I-001 | B28: Issue | C28: Astrid Nilsen welder overtime limit breached due to recovery fabrication schedule | D28: Medium | E28: High | F28: Allocate junior welder to assist with low-priority tasks | G28: Morten Hansen | H28: Active
A29: D-001 | B29: Dependency | C29: Sea trials (WBS 4.0) depend on DNV safety and compliance certification approval | D29: High | E29: High | F29: Submit compliance paperwork 2 weeks in advance of handover date | G29: Frank Ellingsen | H29: Active

Sheet Interactive Simulator
A1: 🎛️ WHAT-IF CORRECTIVE ACTION & CRASH SIMULATOR
A2: Edit yellow input cells to simulate corrective actions, rate savings, and schedule crashing
A5: Simulator Inputs (Editable)
A6: Simulated Labor Rate Savings (%) | B6: 0.05
A7: Simulated Material Price Savings (%) | B7: 0.1
A8: Contract Delay Penalty (USD/Day) | B8: 10000
A9: Crash Schedule? (0=No, 5=Crash 5 Days, 10=Crash 10 Days) | B9: 5
A12: Simulation Results (Calculated)
A14: Current Baseline BAC (USD) | B14: =SUM('EVM Data'!D25:D30) -> 7100000
A15: Current Actual Cost AC (USD) | B15: =SUM('EVM Data'!E25:E30) -> 5220810
A16: Current Earned Value EV (USD) | B16: =SUM('EVM Data'!F25:F30) -> 4752500
A18: Simulated Actual Cost (AC) USD | B18: =B15-(SUM('EVM Data'!I6:I19)*$B$6)-(SUM('EVM Data'!J6:J19)*$B$7)+B24 -> 4916169.5
A19: Simulated CPI | B19: =B16/B18 -> 0.96670792
A20: Simulated Estimate At Completion (EAC) USD | B20: =B14/B19 -> 7344514.1
A22: Simulated Schedule Delay (Days) | B22: =MAX(0,10-B9) -> 5
A23: Simulated Liquidated Damages Penalty (USD) | B23: =B22*B8 -> 50000
A24: Direct Schedule Crashing Cost (USD) | B24: =B9*2000 -> 10000
A25: Net Crashing Trade-off Benefit (USD) | B25: =B23-B24 -> 40000

Sheet EVM Data
A1: EVM CALCULATION MODEL
A2: Live formulas calculate AC, EV, CPI, EAC and statuses from Source Data tables
A5: WBS_ID | B5: ProjectID | C5: WBS Code | D5: Element Name | E5: Project Name | F5: Manager | G5: BAC | H5: Latest Progress | I5: Labor Cost | J5: Material Cost | K5: AC | L5: EV | M5: CPI | N5: EAC Typical | O5: Status | Q5: WBS_ID | R5: LatestProgress | S5: LaborCost | T5: MaterialCost | U5: WBS_ID | V5: LatestProgress | W5: LaborCost | X5: MaterialCost
A6: WBS-001 | B6: PRJ-001 | C6: 1 | D6: Project Management & Engineering | E6: Composite Maritime Vessel Construction | F6: Morten Hansen | G6: 300000 | H6: =INDEX(WBS_Source_Summary[LatestProgress],MATCH(WBS_Performance[[#This Row],[WBS_ID]],WBS_Source_Summary[WBS_ID],0)) -> 0.975 | I6: =INDEX(WBS_Source_Summary[LaborCost],MATCH(WBS_Performance[[#This Row],[WBS_ID]],WBS_Source_Summary[WBS_ID],0)) -> 419230 | J6: =INDEX(WBS_Source_Summary[MaterialCost],MATCH(WBS_Performance[[#This Row],[WBS_ID]],WBS_Source_Summary[WBS_ID],0)) -> 0 | K6: =WBS_Performance[[#This Row],[Labor Cost]]+WBS_Performance[[#This Row],[Material Cost]] -> 419230 | L6: =WBS_Performance[[#This Row],[BAC]]*WBS_Performance[[#This Row],[Latest Progress]] -> 292500 | M6: =IF(WBS_Performance[[#This Row],[AC]]=0,IF(WBS_Performance[[#This Row],[EV]]=0,1,""),WBS_Performance[[#This Row],[EV]]/WBS_Performance[[#This Row],[AC]]) -> 0.6977077 | N6: =IF(AND(WBS_Performance[[#This Row],[EV]]>0,WBS_Performance[[#This Row],[CPI]]>0),WBS_Performance[[#This Row],[BAC]]/WBS_Performance[[#This Row],[CPI]],"") -> 429979.49 | O6: =IF(AND(WBS_Performance[[#This Row],[AC]]=0,WBS_Performance[[#This Row],[EV]]=0),"⚪ Planned",IF(WBS_Performance[[#This Row],[Latest Progress]]>=0.999,IF(WBS_Performance[[#This Row],[CPI]]>=1,"🟢 Completed",IF(WBS_Performance[[#This Row],[CPI]]<0.95,"🔴 Overrun","🟡 Complete/Watch")),IF(WBS_Performance[[#This Row],[CPI]]<0.9,"🔴 Overrun",IF(WBS_Performance[[#This Row],[CPI]]<1,"🟡 Watch","🟢 On Track")))) -> 🔴 Overrun | Q6: WBS-001 | R6: 0.975 | S6: 419230 | T6: 0 | U6: WBS-001 | V6: 0.975 | W6: 419230 | X6: 0
A7: WBS-002 | B7: PRJ-001 | C7: 2 | D7: Hull Fabrication & Assembly | E7: Composite Maritime Vessel Construction | F7: Morten Hansen | G7: 600000 | H7: =INDEX(WBS_Source_Summary[LatestProgress],MATCH(WBS_Performance[[#This Row],[WBS_ID]],WBS_Source_Summary[WBS_ID],0)) -> 1 | I7: =INDEX(WBS_Source_Summary[LaborCost],MATCH(WBS_Performance[[#This Row],[WBS_ID]],WBS_Source_Summary[WBS_ID],0)) -> 374950 | J7: =INDEX(WBS_Source_Summary[MaterialCost],MATCH(WBS_Performance[[#This Row],[WBS_ID]],WBS_Source_Summary[WBS_ID],0)) -> 245500 | K7: =WBS_Performance[[#This Row],[Labor Cost]]+WBS_Performance[[#This Row],[Material Cost]] -> 620450 | L7: =WBS_Performance[[#This Row],[BAC]]*WBS_Performance[[#This Row],[Latest Progress]] -> 600000 | M7: =IF(WBS_Performance[[#This Row],[AC]]=0,IF(WBS_Performance[[#This Row],[EV]]=0,1,""),WBS_Performance[[#This Row],[EV]]/WBS_Performance[[#This Row],[AC]]) -> 0.96704005 | N7: =IF(AND(WBS_Performance[[#This Row],[EV]]>0,WBS_Performance[[#This Row],[CPI]]>0),WBS_Performance[[#This Row],[BAC]]/WBS_Performance[[#This Row],[CPI]],"") -> 620450 | O7: =IF(AND(WBS_Performance[[#This Row],[AC]]=0,WBS_Performance[[#This Row],[EV]]=0),"⚪ Planned",IF(WBS_Performance[[#This Row],[Latest Progress]]>=0.999,IF(WBS_Performance[[#This Row],[CPI]]>=1,"🟢 Completed",IF(WBS_Performance[[#This Row],[CPI]]<0.95,"🔴 Overrun","🟡 Complete/Watch")),IF(WBS_Performance[[#This Row],[CPI]]<0.9,"🔴 Overrun",IF(WBS_Performance[[#This Row],[CPI]]<1,"🟡 Watch","🟢 On Track")))) -> 🟡 Complete/Watch | Q7: WBS-002 | R7: 1 | S7: 374950 | T7: 245500 | U7: WBS-002 | V7: 1 | W7: 374950 | X7: 245500
A8: WBS-003 | B8: PRJ-001 | C8: 3 | D8: Outfitting & Integration | E8: Composite Maritime Vessel Construction | F8: Morten Hansen | G8: 400000 | H8: =INDEX(WBS_Source_Summary[LatestProgress],MATCH(WBS_Performance[[#This Row],[WBS_ID]],WBS_Source_Summary[WBS_ID],0)) -> 1 | I8: =INDEX(WBS_Source_Summary[LaborCost],MATCH(WBS_Performance[[#This Row],[WBS_ID]],WBS_Source_Summary[WBS_ID],0)) -> 297445 | J8: =INDEX(WBS_Source_Summary[MaterialCost],MATCH(WBS_Performance[[#This Row],[WBS_ID]],WBS_Source_Summary[WBS_ID],0)) -> 243000 | K8: =WBS_Performance[[#This Row],[Labor Cost]]+WBS_Performance[[#This Row],[Material Cost]] -> 540445 | L8: =WBS_Performance[[#This Row],[BAC]]*WBS_Performance[[#This Row],[Latest Progress]] -> 400000 | M8: =IF(WBS_Performance[[#This Row],[AC]]=0,IF(WBS_Performance[[#This Row],[EV]]=0,1,""),WBS_Performance[[#This Row],[EV]]/WBS_Performance[[#This Row],[AC]]) -> 0.74013082 | N8: =IF(AND(WBS_Performance[[#This Row],[EV]]>0,WBS_Performance[[#This Row],[CPI]]>0),WBS_Performance[[#This Row],[BAC]]/WBS_Performance[[#This Row],[CPI]],"") -> 540445 | O8: =IF(AND(WBS_Performance[[#This Row],[AC]]=0,WBS_Performance[[#This Row],[EV]]=0),"⚪ Planned",IF(WBS_Performance[[#This Row],[Latest Progress]]>=0.999,IF(WBS_Performance[[#This Row],[CPI]]>=1,"🟢 Completed",IF(WBS_Performance[[#This Row],[CPI]]<0.95,"🔴 Overrun","🟡 Complete/Watch")),IF(WBS_Performance[[#This Row],[CPI]]<0.9,"🔴 Overrun",IF(WBS_Performance[[#This Row],[CPI]]<1,"🟡 Watch","🟢 On Track")))) -> 🔴 Overrun | Q8: WBS-003 | R8: 1 | S8: 297445 | T8: 243000 | U8: WBS-003 | V8: 1 | W8: 297445 | X8: 243000
A9: WBS-004 | B9: PRJ-001 | C9: 4 | D9: Sea Trials & Handover | E9: Composite Maritime Vessel Construction | F9: Morten Hansen | G9: 200000 | H9: =INDEX(WBS_Source_Summary[LatestProgress],MATCH(WBS_Performance[[#This Row],[WBS_ID]],WBS_Source_Summary[WBS_ID],0)) -> 1 | I9: =INDEX(WBS_Source_Summary[LaborCost],MATCH(WBS_Performance[[#This Row],[WBS_ID]],WBS_Source_Summary[WBS_ID],0)) -> 235185 | J9: =INDEX(WBS_Source_Summary[MaterialCost],MATCH(WBS_Performance[[#This Row],[WBS_ID]],WBS_Source_Summary[WBS_ID],0)) -> 33500 | K9: =WBS_Performance[[#This Row],[Labor Cost]]+WBS_Performance[[#This Row],[Material Cost]] -> 268685 | L9: =WBS_Performance[[#This Row],[BAC]]*WBS_Performance[[#This Row],[Latest Progress]] -> 200000 | M9: =IF(WBS_Performance[[#This Row],[AC]]=0,IF(WBS_Performance[[#This Row],[EV]]=0,1,""),WBS_Performance[[#This Row],[EV]]/WBS_Performance[[#This Row],[AC]]) -> 0.74436608 | N9: =IF(AND(WBS_Performance[[#This Row],[EV]]>0,WBS_Performance[[#This Row],[CPI]]>0),WBS_Performance[[#This Row],[BAC]]/WBS_Performance[[#This Row],[CPI]],"") -> 268685 | O9: =IF(AND(WBS_Performance[[#This Row],[AC]]=0,WBS_Performance[[#This Row],[EV]]=0),"⚪ Planned",IF(WBS_Performance[[#This Row],[Latest Progress]]>=0.999,IF(WBS_Performance[[#This Row],[CPI]]>=1,"🟢 Completed",IF(WBS_Performance[[#This Row],[CPI]]<0.95,"🔴 Overrun","🟡 Complete/Watch")),IF(WBS_Performance[[#This Row],[CPI]]<0.9,"🔴 Overrun",IF(WBS_Performance[[#This Row],[CPI]]<1,"🟡 Watch","🟢 On Track")))) -> 🔴 Overrun | Q9: WBS-004 | R9: 1 | S9: 235185 | T9: 33500 | U9: WBS-004 | V9: 1 | W9: 235185 | X9: 33500
A10: WBS-005 | B10: PRJ-002 | C10: 1 | D10: Design & CFD Analysis | E10: PRJ-002: Patrol Vessel Carbon Mold Design | F10: Morten Hansen | G10: 300000 | H10: =INDEX(WBS_Source_Summary[LatestProgress],MATCH(WBS_Performance[[#This Row],[WBS_ID]],WBS_Source_Summary[WBS_ID],0)) -> 0 | I10: =INDEX(WBS_Source_Summary[LaborCost],MATCH(WBS_Performance[[#This Row],[WBS_ID]],WBS_Source_Summary[WBS_ID],0)) -> 0 | J10: =INDEX(WBS_Source_Summary[MaterialCost],MATCH(WBS_Performance[[#This Row],[WBS_ID]],WBS_Source_Summary[WBS_ID],0)) -> 0 | K10: =WBS_Performance[[#This Row],[Labor Cost]]+WBS_Performance[[#This Row],[Material Cost]] -> 0 | L10: =WBS_Performance[[#This Row],[BAC]]*WBS_Performance[[#This Row],[Latest Progress]] -> 0 | M10: =IF(WBS_Performance[[#This Row],[AC]]=0,IF(WBS_Performance[[#This Row],[EV]]=0,1,""),WBS_Performance[[#This Row],[EV]]/WBS_Performance[[#This Row],[AC]]) -> 1 | N10: =IF(AND(WBS_Performance[[#This Row],[EV]]>0,WBS_Performance[[#This Row],[CPI]]>0),WBS_Performance[[#This Row],[BAC]]/WBS_Performance[[#This Row],[CPI]],"") | O10: =IF(AND(WBS_Performance[[#This Row],[AC]]=0,WBS_Performance[[#This Row],[EV]]=0),"⚪ Planned",IF(WBS_Performance[[#This Row],[Latest Progress]]>=0.999,IF(WBS_Performance[[#This Row],[CPI]]>=1,"🟢 Completed",IF(WBS_Performance[[#This Row],[CPI]]<0.95,"🔴 Overrun","🟡 Complete/Watch")),IF(WBS_Performance[[#This Row],[CPI]]<0.9,"🔴 Overrun",IF(WBS_Performance[[#This Row],[CPI]]<1,"🟡 Watch","🟢 On Track")))) -> ⚪ Planned | Q10: WBS-005 | R10: 0 | S10: 0 | T10: 0 | U10: WBS-005 | V10: 0 | W10: 0 | X10: 0
A11: WBS-006 | B11: PRJ-002 | C11: 2 | D11: Material Procurement | E11: PRJ-002: Patrol Vessel Carbon Mold Design | F11: Morten Hansen | G11: 500000 | H11: =INDEX(WBS_Source_Summary[LatestProgress],MATCH(WBS_Performance[[#This Row],[WBS_ID]],WBS_Source_Summary[WBS_ID],0)) -> 0 | I11: =INDEX(WBS_Source_Summary[LaborCost],MATCH(WBS_Performance[[#This Row],[WBS_ID]],WBS_Source_Summary[WBS_ID],0)) -> 0 | J11: =INDEX(WBS_Source_Summary[MaterialCost],MATCH(WBS_Performance[[#This Row],[WBS_ID]],WBS_Source_Summary[WBS_ID],0)) -> 0 | K11: =WBS_Performance[[#This Row],[Labor Cost]]+WBS_Performance[[#This Row],[Material Cost]] -> 0 | L11: =WBS_Performance[[#This Row],[BAC]]*WBS_Performance[[#This Row],[Latest Progress]] -> 0 | M11: =IF(WBS_Performance[[#This Row],[AC]]=0,IF(WBS_Performance[[#This Row],[EV]]=0,1,""),WBS_Performance[[#This Row],[EV]]/WBS_Performance[[#This Row],[AC]]) -> 1 | N11: =IF(AND(WBS_Performance[[#This Row],[EV]]>0,WBS_Performance[[#This Row],[CPI]]>0),WBS_Performance[[#This Row],[BAC]]/WBS_Performance[[#This Row],[CPI]],"") | O11: =IF(AND(WBS_Performance[[#This Row],[AC]]=0,WBS_Performance[[#This Row],[EV]]=0),"⚪ Planned",IF(WBS_Performance[[#This Row],[Latest Progress]]>=0.999,IF(WBS_Performance[[#This Row],[CPI]]>=1,"🟢 Completed",IF(WBS_Performance[[#This Row],[CPI]]<0.95,"🔴 Overrun","🟡 Complete/Watch")),IF(WBS_Performance[[#This Row],[CPI]]<0.9,"🔴 Overrun",IF(WBS_Performance[[#This Row],[CPI]]<1,"🟡 Watch","🟢 On Track")))) -> ⚪ Planned | Q11: WBS-006 | R11: 0 | S11: 0 | T11: 0 | U11: WBS-006 | V11: 0 | W11: 0 | X11: 0
A12: WBS-007 | B12: PRJ-003 | C12: 1 | D12: Structural Frame Engineering | E12: PRJ-003: Subsea Cable Installation Frame | F12: Erik Johansen | G12: 400000 | H12: =INDEX(WBS_Source_Summary[LatestProgress],MATCH(WBS_Performance[[#This Row],[WBS_ID]],WBS_Source_Summary[WBS_ID],0)) -> 0.9 | I12: =INDEX(WBS_Source_Summary[LaborCost],MATCH(WBS_Performance[[#This Row],[WBS_ID]],WBS_Source_Summary[WBS_ID],0)) -> 332500 | J12: =INDEX(WBS_Source_Summary[MaterialCost],MATCH(WBS_Performance[[#This Row],[WBS_ID]],WBS_Source_Summary[WBS_ID],0)) -> 0 | K12: =WBS_Performance[[#This Row],[Labor Cost]]+WBS_Performance[[#This Row],[Material Cost]] -> 332500 | L12: =WBS_Performance[[#This Row],[BAC]]*WBS_Performance[[#This Row],[Latest Progress]] -> 360000 | M12: =IF(WBS_Performance[[#This Row],[AC]]=0,IF(WBS_Performance[[#This Row],[EV]]=0,1,""),WBS_Performance[[#This Row],[EV]]/WBS_Performance[[#This Row],[AC]]) -> 1.0827068 | N12: =IF(AND(WBS_Performance[[#This Row],[EV]]>0,WBS_Performance[[#This Row],[CPI]]>0),WBS_Performance[[#This Row],[BAC]]/WBS_Performance[[#This Row],[CPI]],"") -> 369444.44 | O12: =IF(AND(WBS_Performance[[#This Row],[AC]]=0,WBS_Performance[[#This Row],[EV]]=0),"⚪ Planned",IF(WBS_Performance[[#This Row],[Latest Progress]]>=0.999,IF(WBS_Performance[[#This Row],[CPI]]>=1,"🟢 Completed",IF(WBS_Performance[[#This Row],[CPI]]<0.95,"🔴 Overrun","🟡 Complete/Watch")),IF(WBS_Performance[[#This Row],[CPI]]<0.9,"🔴 Overrun",IF(WBS_Performance[[#This Row],[CPI]]<1,"🟡 Watch","🟢 On Track")))) -> 🟢 On Track | Q12: WBS-007 | R12: 0.9 | S12: 332500 | T12: 0 | U12: WBS-007 | V12: 0.9 | W12: 332500 | X12: 0
A13: WBS-008 | B13: PRJ-003 | C13: 2 | D13: Steel Fabrication | E13: PRJ-003: Subsea Cable Installation Frame | F13: Erik Johansen | G13: 800000 | H13: =INDEX(WBS_Source_Summary[LatestProgress],MATCH(WBS_Performance[[#This Row],[WBS_ID]],WBS_Source_Summary[WBS_ID],0)) -> 0 | I13: =INDEX(WBS_Source_Summary[LaborCost],MATCH(WBS_Performance[[#This Row],[WBS_ID]],WBS_Source_Summary[WBS_ID],0)) -> 0 | J13: =INDEX(WBS_Source_Summary[MaterialCost],MATCH(WBS_Performance[[#This Row],[WBS_ID]],WBS_Source_Summary[WBS_ID],0)) -> 50000 | K13: =WBS_Performance[[#This Row],[Labor Cost]]+WBS_Performance[[#This Row],[Material Cost]] -> 50000 | L13: =WBS_Performance[[#This Row],[BAC]]*WBS_Performance[[#This Row],[Latest Progress]] -> 0 | M13: =IF(WBS_Performance[[#This Row],[AC]]=0,IF(WBS_Performance[[#This Row],[EV]]=0,1,""),WBS_Performance[[#This Row],[EV]]/WBS_Performance[[#This Row],[AC]]) -> 0 | N13: =IF(AND(WBS_Performance[[#This Row],[EV]]>0,WBS_Performance[[#This Row],[CPI]]>0),WBS_Performance[[#This Row],[BAC]]/WBS_Performance[[#This Row],[CPI]],"") | O13: =IF(AND(WBS_Performance[[#This Row],[AC]]=0,WBS_Performance[[#This Row],[EV]]=0),"⚪ Planned",IF(WBS_Performance[[#This Row],[Latest Progress]]>=0.999,IF(WBS_Performance[[#This Row],[CPI]]>=1,"🟢 Completed",IF(WBS_Performance[[#This Row],[CPI]]<0.95,"🔴 Overrun","🟡 Complete/Watch")),IF(WBS_Performance[[#This Row],[CPI]]<0.9,"🔴 Overrun",IF(WBS_Performance[[#This Row],[CPI]]<1,"🟡 Watch","🟢 On Track")))) -> 🔴 Overrun | Q13: WBS-008 | R13: 0 | S13: 0 | T13: 50000 | U13: WBS-008 | V13: 0 | W13: 0 | X13: 50000
