Workbook
Name Actual_Cost_Values: tbl_Fact_Actual_Costs[Actual_Cost]
Name Actual_Hours_Values: tbl_Fact_Actual_Costs[Hours_Worked]
Name Baseline_PV_Values: tbl_Fact_Baseline_PV[Planned_Value]
Name Control_BAC: Dim_Project!$E$2
Name Control_CPI_SPI_Green: Setup!$B$13
Name Control_CPI_SPI_Red: Setup!$B$12
Name Control_Progress_Amber: Setup!$B$14
Name Control_Progress_Green: Setup!$B$15
Name Control_Project_End: Dim_Project!$D$2
Name Control_Project_ID: Dim_Project!$A$2
Name Control_Project_Name: Dim_Project!$B$2
Name Control_Project_Start: Dim_Project!$C$2
Name Control_Sector: Dim_Project!$F$2
Name Control_Status_Date: Setup!$B$9
Name Input_Actual_Costs: tbl_Fact_Actual_Costs[]
Name Input_Baseline_PV: tbl_Fact_Baseline_PV[]
Name Input_Calendar: tbl_Dim_Calendar[]
Name Input_Physical_Progress: tbl_Fact_Physical_Progress[]
Name Input_Project: tbl_Dim_Project[]
Name Input_Resources: tbl_Dim_Resource[]
Name Input_WBS: tbl_Dim_WBS[]
Name Progress_Pct_Values: tbl_Fact_Physical_Progress[Physical_Progress_Pct]
Name Slicer_Category: #N/A
Name Slicer_Measure: #N/A
Name Slicer_Month_Name: #N/A
Name Slicer_Owner: #N/A
Name Slicer_Owner1: #N/A
Name Slicer_Owner2: #N/A
Name Slicer_RAG: #N/A
Name Slicer_RAG1: #N/A
Name Slicer_RAG2: #N/A
Name Slicer_RAG3: #N/A
Name Slicer_Resource_ID: #N/A
Name Slicer_Role: #N/A
Name Slicer_Status: #N/A
Name Slicer_Status1: #N/A
Name Slicer_Status2: #N/A
Name Slicer_Status3: #N/A
Name Slicer_Status4: #N/A
Name Slicer_Type: #N/A
Name Slicer_Type1: #N/A
Name Slicer_Type2: #N/A
Name Slicer_Type3: #N/A
Name Slicer_WBS_ID: #N/A
Name Slicer_WBS_ID1: #N/A
Name Slicer_WBS_ID2: #N/A
Name Slicer_WBS_ID3: #N/A
Name Slicer_WBS_ID4: #N/A
Name Slicer_Week: #N/A
Name Slicer_Week_Number: #N/A
Name WBS_Activities: tbl_Dim_WBS[Activity_Name]
Name WBS_Budgets: tbl_Dim_WBS[Total_Budget]
Name WBS_IDs: tbl_Dim_WBS[WBS_ID]
Name WBS_Types: tbl_Dim_WBS[Type]

Sheet Cover
A1: Office Fit-Out Project Control Workbook
A2: PM-EVM compliant workbook map: setup controls, task plan, Gantt, EVM S-curve, dashboard, source dimensions, and fact tables.
A4: Sheet | B4: Purpose | D4: Tab Color Legend
A5: Setup | B5: Project-level controls: project metadata, status date, reporting period, and RAG thresholds. | D5: Color | E5: Category | F5: Sheets
A6: Task Plan | B6: Integrated WBS/task control table linking baseline dates, BAC, progress, AC, EV, variances, forecasts, and RAG status. | E6: Navigation / Reference | F6: Cover, Glossary
A7: EVM | B7: Weekly EVM reporting table with cumulative PV, AC, EV, SV, CV, SPI, CPI, EAC, ETC, and VAC. | E7: Method / Governance | F7: Method Roadmap, PID, PM-EVM Compliance, Review
A8: EVM Charts | B8: Baseline Gantt schedule and EVM S-curve generated from the same WBS, budget, progress, and actual-cost data. | E8: Controls / Planning | F8: Setup, Task Plan, Task Capture, Resource Grid
A9: EVM Dashboard | B9: Management view with KPI tiles, WBS performance breakdown, trends, and RAG coloring. | E9: Management Outputs | F9: EVM Dashboard, EVM, EVM Charts
A10: PM-EVM Compliance | B10: Checklist mapping the workbook to the attached PM-EVM guideline. | E10: Dimension Data | F10: Dim_Project, Dim_WBS, Dim_Resource, Dim_Calendar
A11: Dim_* / Fact_* | B11: Star-schema source data used by the live formulas and charts. | E11: Fact Data | F11: Fact_Baseline_PV, Fact_Actual_Costs, Fact_Physical_Progress
A12: Glossary | B12: Definitions for the EVM, WBS, Gantt, schedule, cost, RAG, and data-model terms used in the workbook.
A13: Method Roadmap | B13: 12-step project management method mapped to workbook sheets and current project controls. | D13: Input / Control / Output Classification
A14: PID | B14: Project Initiation Document template with business case, scope, controls, risk and financial sections. | D14: Class | E14: Meaning | F14: Sheets
A15: Task Capture | B15: Task-list brainstorming sheet based on the attached list-the-tasks method, linked to current WBS. | D15: Input | E15: Source data or user-entered templates that feed calculations. | F15: Dim_Project, Dim_WBS, Dim_Resource, Dim_Calendar, Fact_Baseline_PV, Fact_Actual_Costs, Fact_Physical_Progress, PID, Task Capture, Review
A16: Resource Grid | B16: Weekly hours/cost resource allocation grid adapted from the attached Gantt template. | D16: Control | E16: Assumptions, governance, validation, methods, and planning logic that manage how inputs are interpreted. | F16: Setup, Method Roadmap, PM-EVM Compliance, Task Plan, Resource Grid
A17: Review | B17: GOOD / BAD / BETTER review template and action log. | D17: Output | E17: Management-facing reports, charts, dashboards, and reference views produced from inputs and controls. | F17: Cover, Glossary, EVM Dashboard, EVM, EVM Charts
A18: Garden Gantt Model | B18: Attached garden-office Gantt template implemented with current project weekly hours and cost data.
A19: PERT Diagram | B19: Visio-style PERT network diagram reflecting the current WBS, schedule, progress and RAG status. | D19: Sheet | E19: Class | F19: Reason
A20: Red Actions | B20: Recommended recovery actions for all current red RAG WBS items and control risks. | D20: Cover | E20: Output | F20: Workbook navigation and summary.
A21: Pivot Summary | B21: High-level PivotTables and descriptive statistics for project cost, schedule, EVM, and RAG performance. | D21: Glossary | E21: Output
D22: Review | E22: Input
D23: Setup | E23: Control
D24: PID | E24: Input
D25: Method Roadmap | E25: Control
D26: PM-EVM Compliance | E26: Control
D27: Task Plan | E27: Control
D28: Task Capture | E28: Input
D29: EVM Dashboard | E29: Output
D30: Resource Grid | E30: Control
D31: Dim_Project | E31: Input
D32: Dim_WBS | E32: Input
D33: Dim_Resource | E33: Input
... D39: EVM Charts | E39: Output

Sheet Slicer Controls
A1: Workbook Slicer Controls
A2: Use this panel to filter the source Excel Tables directly. Slicers are grouped by reporting outputs, source inputs, and governance/control tables.
A4: MANAGEMENT OUTPUTS
A30: SOURCE INPUTS
A56: GOVERNANCE / CONTROL
A105: Slicer name | B105: Source area | C105: Field | D105: Caption
A106: slc_Dashboard_Status | B106: Dashboard | C106: Status | D106: Dashboard: Status
A107: slc_Dashboard_Type | B107: Dashboard | C107: Type | D107: Dashboard: Type
A108: slc_TaskPlan_Status | B108: Task Plan | C108: Status | D108: Task Plan: Status
A109: slc_TaskPlan_Type | B109: Task Plan | C109: Type | D109: Task Plan: Type
A110: slc_TaskPlan_WBSID | B110: Task Plan | C110: WBS ID | D110: Task Plan: WBS ID
A111: slc_EVM_Status | B111: EVM | C111: Status | D111: EVM: Status
A112: slc_EVM_Week | B112: EVM | C112: Week | D112: EVM: Week
A113: slc_PERT_RAG | B113: PERT | C113: RAG | D113: PERT: RAG
A114: slc_Resource_Measure | B114: Resource Grid | C114: Measure | D114: Resource Grid: Measure
A115: slc_Resource_RAG | B115: Resource Grid | C115: RAG | D115: Resource Grid: RAG
A116: slc_Calendar_Month | B116: Calendar | C116: Month | D116: Calendar: Month
... A133: slc_Method_Owner | B133: Method Roadmap | C133: Owner | D133: Method Roadmap: Owner

Sheet Glossary
A1: Project Control Glossary
A2: Definitions for the EVM, WBS, Gantt, schedule, cost, and RAG terms used across this workbook.
A4: Category | B4: Term | C4: Abbrev. | D4: Definition | E4: Workbook reference
A5: Project setup | B5: Project Start | D5: Approved start date for the project control baseline. | E5: Setup!B7 / Dim_Project!C2
A6: Project setup | B6: Project End | D6: Approved planned end date for the project. | E6: Setup!B8 / Dim_Project!D2
A7: Project setup | B7: Status Date | D7: Cut-off date for reported progress, actual costs, and EVM metrics. | E7: Setup!B9 / EVM Dashboard!B4
A8: Scope / WBS | B8: Work Breakdown Structure | C8: WBS | D8: Hierarchical breakdown of project scope into controllable work packages or activities. | E8: Dim_WBS / Task Plan
A9: Scope / WBS | B9: WBS ID | D9: Unique identifier used to connect WBS activities to baseline PV, actual costs, and progress facts. | E9: Dim_WBS!A:A
A10: Scope / WBS | B10: Activity / Task | D10: A controllable unit of project work with budget, schedule, progress, and cost tracking. | E10: Task Plan!C:C
A11: Schedule | B11: Baseline Start | D11: Planned start date for a WBS activity from the approved baseline. | E11: Task Plan!E:E
A12: Schedule | B12: Baseline Finish | D12: Planned finish date for a WBS activity from the approved baseline. | E12: Task Plan!F:F
A13: Schedule | B13: Duration Days | D13: Calendar-day span between baseline start and finish dates. | E13: Task Plan!G:G
A14: Schedule | B14: Gantt Chart | D14: Timeline chart showing planned activity timing and duration by WBS activity. | E14: EVM Charts!Gantt Schedule
A15: Cost / EVM | B15: Budget at Completion | C15: BAC | D15: Approved total budget for the project or WBS activity. | E15: Setup!B11 / Task Plan!H:H
A16: Cost / EVM | B16: Planned Value | C16: PV | D16: Budgeted value of work planned to be complete by a given date. | E16: Task Plan!I:I / EVM!C:C
A17: Cost / EVM | B17: Actual Cost | C17: AC | D17: Actual cost incurred by a given date. | E17: Task Plan!J:J / EVM!D:D
A18: Cost / EVM | B18: Physical Progress | C18: Progress % | D18: Latest reported percent complete for each WBS activity as of the status date. | E18: Task Plan!K:K
A19: Cost / EVM | B19: Earned Value | C19: EV | D19: Budgeted value of the work actually completed; calculated as BAC × progress. | E19: Task Plan!L:L / EVM!E:E
A20: Variance | B20: Schedule Variance | C20: SV | D20: EV minus PV; negative means less work completed than planned. | E20: Task Plan!M:M / EVM!F:F
A21: Variance | B21: Cost Variance | C21: CV | D21: EV minus AC; negative means cost overrun for completed work. | E21: Task Plan!N:N / EVM!G:G
A22: Performance index | B22: Schedule Performance Index | C22: SPI | D22: EV divided by PV; below 1.0 indicates unfavorable schedule efficiency. | E22: Task Plan!O:O / EVM!H:H
A23: Performance index | B23: Cost Performance Index | C23: CPI | D23: EV divided by AC; below 1.0 indicates unfavorable cost efficiency. | E23: Task Plan!P:P / EVM!I:I
A24: Forecast | B24: Estimate at Completion | C24: EAC | D24: Forecast final project or WBS cost, typically BAC divided by CPI. | E24: Task Plan!Q:Q / EVM!K:K
A25: Forecast | B25: Estimate to Complete | C25: ETC | D25: Forecast remaining cost to complete the work; EAC minus AC. | E25: Task Plan!R:R / EVM!L:L
A26: Forecast | B26: Variance at Completion | C26: VAC | D26: Expected budget variance at completion; BAC minus EAC. | E26: Task Plan!S:S / EVM!M:M
A27: Chart | B27: EVM S-Curve | D27: Line chart comparing cumulative PV, EV, and AC over time. | E27: EVM Charts!EVM S-Curve
A28: RAG | B28: Green | D28: Good condition: on/above plan, favorable variance, or acceptable performance threshold. | E28: Setup!A18:D18
A29: RAG | B29: Amber | D29: Watch condition: close to threshold or mid-progress; monitor closely. | E29: Setup!A19:D19
A30: RAG | B30: Red | D30: Action condition: negative variance, low progress, CPI/SPI below threshold, or overrun. | E30: Setup!A20:D20
A31: Reporting | B31: Dashboard | D31: Management summary view showing KPIs, WBS performance, trend data, and RAG status. | E31: EVM Dashboard!A1:P47
A32: Reporting | B32: Tie-out | D32: Validation that dashboard KPIs match the detailed EVM reporting table at the status date. | E32: EVM!H19:M25
A33: Data model | B33: Dimension Table | C33: Dim | D33: Reference table describing projects, WBS, resources, or calendar dates. | E33: Dim_Project / Dim_WBS / Dim_Resource / Dim_Calendar
A34: Data model | B34: Fact Table | C34: Fact | D34: Transaction or event table containing planned values, actual costs, or progress observations. | E34: Fact_Baseline_PV / Fact_Actual_Costs / Fact_Physical_Progress
A36: Workbook classification | B36: Input | D36: Source data or user-entered content that feeds project calculations and reports. | E36: Cover!D13:H39
A37: Workbook classification | B37: Control | D37: Assumptions, thresholds, validation, governance, and planning logic used to interpret inputs. | E37: Cover!D13:H39
A38: Workbook classification | B38: Output | D38: Reports, charts, dashboards, and references produced from the input data and control logic. | E38: Cover!D13:H39

Sheet Review
A1: Project Review & Lessons
A2: Review template from attachment: GOOD / BAD / BETTER plus action log for plan adjustments and lessons learned.
A4: Project Description | B4: =Control_Project_Name -> Generic Master Project
A5: Project Period | B5: =TEXT(Control_Project_Start,"yyyy-mm-dd")&" to "&TEXT(Control_Project_End,"yyyy-mm-dd") -> 2026-01-01 to 2026-12-31
A6: Status Date | B6: =Control_Status_Date -> 46203
A7: Review Owner | B7: Frank Ellingsen
A8: Review Date | B8: =TODAY() -> 46238
A10: GOOD — what went well that others should repeat?
A15: BAD — what mistakes were made or unexpected issues occurred?
A20: BETTER / ACTION LOG | B20: Owner | C20: Due date | D20: Decision required? | E20: RAG | F20: Linked workbook evidence
A21: 1 | B21: 2026-01-01 | C21: Action description | D21: Owner | E21: Medium | F21: Open
A22: Review cost efficiency and current EAC forecast | B22: Project Controls | D22: Yes | E22: Red | F22: EVM Dashboard!G10 / Task Plan!Q17
A23: Confirm mitigation for red WBS activities in Gantt | B23: Project Manager | D23: Yes | E23: Red | F23: EVM Charts!Gantt Schedule
A24: Check future material/subcontractor dependencies | B24: Planner | D24: No | E24: Amber | F24: Task Plan / Resource Grid
A25: Capture lessons from completed WBS items | B25: Project Team | D25: No | E25: Amber | F25: Task Capture / Review
A30: Review source | B30: 13.1.2 Review Template.pdf

Sheet PID
A1: Project Initiation Document (PID)
A2: PID template from the attached method, prefilled with current workbook metadata where available. Fill yellow cells during project definition.
A4: Project header
A5: Project Name | B5: =Control_Project_Name -> Generic Master Project
A6: Project Number | B6: =Control_Project_ID -> PRJ001
A7: Project Risk Level | B7: H/M/L
A8: Prepared by | B8: Frank Ellingsen
A9: Date | B9: =TODAY() -> 46238
A10: Persons consulted
A11: Key Driver | B11: Cost / Quality / Time
A13: 1. Business Case
A14: Why this project; why now; options considered; what if we do not do it; benefits; payback period.
A18: 2.1 In Scope / Included
A19: Work and deliverables included in the project.
A23: 2.2 Out of Scope / Excluded
A24: Work explicitly excluded from the project.
A28: 2.3 Dependencies
A29: How the project impacts or is impacted by other projects or programmes.
A33: 2.4 Constraints
A34: Deadlines, budget limits, resource limitations or other delivery constraints.
A38: 2.5 Assumptions
A39: Assumptions currently being used for planning.
... A49: How progress will be reported, frequency, method and responsibility.
A53: Frequency / timing | B53: How control is reported | C53: Responsibility | D53: Next report date | E53: Status
A54: Project Controls Lead | B54: Role Description | C54: Name | D54: Contact | E54: Approved
A55: Stage end | B55: PID / Review pack | C55: Project Manager | E55: Planned
A56: Monthly | B56: Board summary | C56: Project Manager | E56: Planned
A58: 5. Risk Control
A59: Project risks and containment measures.
A63: Project Risk | B63: Containment Measures | C63: Owner | D63: Due Date | E63: RAG
A64: Risk ID | B64: Risk Description | C64: Probability | D64: Impact | E64: Mitigation Strategy
A65: Cost overrun | B65: Monitor CPI/CV/EAC and review WBS cost drivers. | C65: Project Controls | E65: Red
A66: Resource availability | B66: Use weekly Resource Grid to identify conflicts. | C66: Resource Manager | E66: Amber
A67: Scope creep | B67: Confirm in/out of scope and change-control route in PID. | C67: Project Manager | E67: Amber
A68: Quality issue | B68: Define acceptance criteria and quality checks by task. | C68: Project Manager | E68: Amber
A69: Supplier delay | B69: Track procurement/material activities and delivery milestones. | C69: Project Manager | E69: Amber
A72: 6. Financial Implications
A73: Quarterly/annual financial profile adapted from the PID template; Year 1 is linked to the current baseline planned value.
A74: Financial Implications | B74: Q1 | C74: Q2 | D74: Q3 | E74: Q4 | F74: Total
A75: Cost Category | B75: 0 | C75: 0 | D75: 0 | E75: Comments | F75: Status
...

Sheet Method Roadmap
A1: 12-Step Project Management Method Roadmap
A2: Course method embedded into the workbook: define, list, sequence, estimate, check, Gantt, resource, risk, monitor progress/cost, adjust, and review.
A4: Step | B4: Method step | C4: Purpose | D4: Workbook implementation | E4: Primary sheet / range | F4: Owner | G4: Status | H4: Source
A5: 1 | B5: Define the project | C5: Create the project definition and controls. | D5: PID template added with live project metadata. | E5: PID!A1:H50 | F5: Project Manager | G5: Active | H5: 1.2 12 Step Process / 2.1.2 PID template
A6: 2 | B6: List the tasks | C6: Capture all tasks without initially worrying about order, cost, or time. | D6: Task Capture sheet added; WBS imported from current Dim_WBS and grouped by type. | E6: Task Capture!A4:J18 | F6: Project Team | G6: Active | H6: 3.1.5 List the Tasks / 4.1 List of Tasks
A7: 3 | B7: Establish task order | C7: Convert brainstormed tasks into planned sequencing. | D7: Task Plan and Gantt use WBS order and baseline dates. | E7: Task Plan!A4:T17 | F7: Planner | G7: Active | H7: 1.2 12 Step Process
A8: 4 | B8: Estimate time | C8: Estimate duration by task. | D8: Baseline start, finish, and duration calculated per WBS. | E8: Task Plan!E5:G17 | F8: Planner | G8: Active | H8: 1.2 12 Step Process
A9: 5 | B9: Margin check & reality check | C9: Check whether dates, budget, and resource assumptions are feasible. | D9: Status tie-out, EVM checks, and RAG indicators added. | E9: EVM!H19:M25 | F9: Project Controls | G9: Active | H9: 1.2 12 Step Process
A10: 6 | B10: Gantt Chart | C10: Show planned timing and status. | D10: Gantt chart with RAG bars and status-date marker exists. | E10: EVM Charts!Gantt Schedule | F10: Project Controls | G10: Active | H10: 8.1.2 Gantt templates
A11: 7 | B11: Resource allocation | C11: Map tasks to people/resources and weekly loading. | D11: Resource Grid added with weekly hours and costs by WBS. | E11: Resource Grid!A4:Z35 | F11: Resource Manager | G11: Active | H11: 8.1.2 Gantt template from garden office
A12: 8 | B12: Predicting & reducing risk | C12: Identify project risks and containment measures. | D12: PID risk-control register added. | E12: PID!A63:E70 | F12: Project Manager | G12: Template ready | H12: 2.1.2 PID template
A13: 9 | B13: Monitoring progress | C13: Track completion against plan. | D13: Progress is linked from Fact_Physical_Progress to Task Plan and dashboard. | E13: Task Plan!K5:K17 | F13: Project Controls | G13: Active | H13: 1.2 12 Step Process
A14: 10 | B14: Monitoring cost | C14: Track actual cost and forecast. | D14: EVM reporting monitors AC, CV, CPI, EAC, ETC, VAC. | E14: EVM!A4:N16 | F14: Project Controls | G14: Active | H14: 1.2 12 Step Process
A15: 11 | B15: Adjusting the plan | C15: Use EVM and RAG exceptions to trigger decisions. | D15: Decision/action log added to Review. | E15: Review!A20:F28 | F15: Project Board | G15: Template ready | H15: 1.2 12 Step Process
A16: 12 | B16: Review & lessons | C16: Capture good, bad, better after delivery. | D16: Review sheet added with GOOD / BAD / BETTER structure. | E16: Review!A4:F17 | F16: Project Team | G16: Template ready | H16: 13.1.2 Review Template

Sheet PM-EVM Compliance
A1: PM-EVM Compliance Checklist
A2: Workbook compliance map against the attached PM-EVM guideline: WBS, Gantt, EVM, dashboard, live formulas, and exception-focused reporting.
A4: Guideline requirement | B4: Workbook implementation | C4: Location | D4: Status | E4: Evidence
A5: Setup controls: project metadata, status date, reporting period, rates/thresholds | B5: Added setup control sheet with live project metadata and thresholds | C5: Setup!A4:D20 | D5: Compliant | E5: PM-EVM.md lines 117-126
A6: Task Plan as integrated WBS/task control view | B6: Added live task table combining WBS, dates, BAC, PV, AC, progress, EV, variances, forecasts and RAG | C6: Task Plan!A4:T17 | D6: Compliant | E6: PM-EVM.md lines 120-125
A7: Gantt display tied to WBS baseline dates | B7: Existing EVM Charts Gantt uses WBS activities, baseline start/finish and duration | C7: EVM Charts!Gantt Schedule | D7: Compliant | E7: PM-EVM.md lines 122-125
A8: EVM by reporting period with PV, EV, AC, SV, CV, SPI, CPI, BAC, EAC, ETC, VAC | B8: Added EVM reporting table with weekly live formulas | C8: EVM!A4:N16 | D8: Compliant | E8: PM-EVM.md lines 123-124
A9: S-curve shows cumulative PV, EV, and AC over time | B9: Existing EVM S-curve chart is sourced from weekly cumulative helper table | C9: EVM Charts!EVM S-Curve | D9: Compliant | E9: PM-EVM.md lines 50-54
A10: Dashboard summarizes management KPIs and top WBS exceptions | B10: Existing dashboard has KPI tiles, WBS table, RAG, variance/status fields | C10: EVM Dashboard!A1:P47 | D10: Compliant | E10: PM-EVM.md lines 781-785
A11: Exception-focused reporting with RAG / traffic-light indicators | B11: RAG rules applied across performance indices, progress, variances, and status cells | C11: EVM Dashboard, Task Plan, EVM | D11: Compliant | E11: PM-EVM.md lines 781-785
A12: Consistent WBS codes, budgets, dates, and actuals across views | B12: Task Plan, EVM, Gantt and dashboard all reference Dim_WBS and fact tables | C12: Dim_WBS / Fact_* | D12: Compliant | E12: PM-EVM.md lines 270-274
A13: Validate formulas and totals | B13: Added formula validation and status-date tie-out to dashboard KPIs | C13: EVM!H19:M25 | D13: Compliant | E13: PM-EVM.md lines 783-785

Sheet Setup
A1: Setup Controls
A2: Single place to review project metadata, status date, reporting period, and RAG thresholds used by the control workbook.
A4: Control | B4: Value
A5: Project ID | B5: PRJ001
A6: Project Name | B6: Generic Master Project
A7: Project Start | B7: 46023
A8: Project End | B8: 46387
A9: Status Date | B9: 46203
A10: Reporting Period | B10: Weekly
A11: Budget at Completion (BAC) | B11: 267150
A12: CPI/SPI Red Threshold | B12: 0.95
A13: CPI/SPI Green Threshold | B13: 1
A14: Progress Amber Threshold | B14: 0.5
A15: Progress Green Threshold | B15: 0.8
A17: RAG | B17: Metric | C17: Rule | D17: Interpretation
A18: Green | B18: CPI/SPI | C18: >= 1.00 | D18: On or above plan
A19: Amber | B19: CPI/SPI | C19: 0.95 to < 1.00 | D19: Near threshold / watch
A20: Red | B20: CPI/SPI | C20: < 0.95 | D20: Action required

Sheet Task Plan
A1: Task Plan
A2: Integrated WBS control table: one live task-level view for scope, schedule, budget, progress, actuals, forecasts, and RAG status.
A4: WBS ID | B4: WBS Code | C4: Task / Activity | D4: Type | E4: Baseline Start | F4: Baseline Finish | G4: Duration Days | H4: BAC (NOK) | I4: PV @ Status | J4: AC @ Status | K4: Progress % | L4: EV @ Status | M4: SV | N4: CV | O4: SPI | P4: CPI | Q4: EAC | R4: ETC | S4: VAC | T4: Status
A5: WBS-01 | B5: 1 | C5: Project Management | D5: Labor | E5: 46153 | F5: 46229 | G5: 77 | H5: 16500 | I5: 12000 | J5: 9280 | K5: 0.5 | L5: 8250 | M5: -3750 | N5: -1030 | O5: 0.6875 | P5: 0.88900862 | Q5: 18560 | R5: 9280 | S5: -2060 | T5: Red
A6: WBS-02 | B6: 2 | C6: Site Survey & Mobilization | D6: Labor | E6: 46146 | F6: 46152 | G6: 7 | H6: 8500 | I6: 8500 | J6: 8700 | K6: 1 | L6: 8500 | M6: 0 | N6: -200 | O6: 1 | P6: 0.97701149 | Q6: 8700 | R6: 0 | S6: -200 | T6: Red
A7: WBS-03 | B7: 3 | C7: Design & Engineering | D7: Labor | E7: 46146 | F7: 46166 | G7: 21 | H7: 19200 | I7: 19200 | J7: 18195.04 | K7: 1 | L7: 19200 | M7: 0 | N7: 1004.96 | O7: 1 | P7: 1.0552326 | Q7: 18195.04 | R7: 0 | S7: 1004.96 | T7: Green
A8: WBS-04 | B8: 4 | C8: Procurement - Materials | D8: Material | E8: 46153 | F8: 46180 | G8: 28 | H8: 42000 | I8: 42000 | J8: 41300 | K8: 1 | L8: 42000 | M8: 0 | N8: 700 | O8: 1 | P8: 1.0169492 | Q8: 41300 | R8: 0 | S8: 700 | T8: Green
A9: WBS-05 | B9: 5 | C9: Demolition & Prep | D9: Labor | E9: 46153 | F9: 46173 | G9: 21 | H9: 13200 | I9: 13200 | J9: 13408.16 | K9: 1 | L9: 13200 | M9: 0 | N9: -208.16 | O9: 1 | P9: 0.98447513 | Q9: 13408.16 | R9: 0 | S9: -208.16 | T9: Red
A10: WBS-06 | B10: 6 | C10: Electrical Rough-In | D10: Labor | E10: 46167 | F10: 46187 | G10: 21 | H10: 26000 | I10: 26000 | J10: 26206.24 | K10: 0.7 | L10: 18200 | M10: -7800 | N10: -8006.24 | O10: 0.7 | P10: 0.69449108 | Q10: 37437.486 | R10: 11231.246 | S10: -11437.486 | T10: Red
A11: WBS-07 | B11: 7 | C11: HVAC Installation | D11: Subcontractor | E11: 46174 | F11: 46201 | G11: 28 | H11: 36000 | I11: 36000 | J11: 17476.8 | K11: 0.4 | L11: 14400 | M11: -21600 | N11: -3076.8 | O11: 0.4 | P11: 0.82394946 | Q11: 43692 | R11: 26215.2 | S11: -7692 | T11: Red
A12: WBS-08 | B12: 8 | C12: Partitions & Drywall | D12: Subcontractor | E12: 46181 | F12: 46208 | G12: 28 | H12: 28000 | I12: 28000 | J12: 7099.2 | K12: 0.248857 | L12: 6967.996 | M12: -21032.004 | N12: -131.204 | O12: 0.248857 | P12: 0.98151848 | Q12: 28527.226 | R12: 21428.026 | S12: -527.22648 | T12: Red
A13: WBS-09 | B13: 9 | C13: Flooring | D13: Material | E13: 46195 | F13: 46215 | G13: 21 | H13: 35750 | I13: 23833.34 | J13: 0 | K13: 0 | L13: 0 | M13: -23833.34 | N13: 0 | O13: 0 | P13: 1 | Q13: 35750 | R13: 35750 | S13: 0 | T13: Red
A14: WBS-10 | B14: 10 | C14: Fixtures & Furniture | D14: Material | E14: 46202 | F14: 46222 | G14: 21 | H14: 30000 | I14: 10000 | J14: 0 | K14: 0 | L14: 0 | M14: -10000 | N14: 0 | O14: 0 | P14: 1 | Q14: 30000 | R14: 30000 | S14: 0 | T14: Red
A15: WBS-11 | B15: 11 | C15: Testing / Commissioning | D15: Labor | E15: 46216 | F15: 46229 | G15: 14 | H15: 8400 | I15: 0 | J15: 0 | K15: 0 | L15: 0 | M15: 0 | N15: 0 | O15: 1 | P15: 1 | Q15: 8400 | R15: 8400 | S15: 0 | T15: Green
A16: WBS-12 | B16: 12 | C16: Handover & Closeout | D16: Labor | E16: 46223 | F16: 46229 | G16: 7 | H16: 3600 | I16: 0 | J16: 0 | K16: 0 | L16: 0 | M16: 0 | N16: 0 | O16: 1 | P16: 1 | Q16: 3600 | R16: 3600 | S16: 0 | T16: Green
A17: Total / Project Portfolio | H17: 267150 | I17: 218733.34 | J17: 141665.44 | K17: 0.48930562 | L17: 130718 | M17: -88015.344 | N17: -10947.444 | O17: 0.5976135 | P17: 0.92272326 | Q17: 289523.43 | R17: 147857.99 | S17: -22373.428 | T17: Red

Sheet Task Capture
A1: Task Capture / List the Tasks
A2: Method: first list all tasks without worrying about order, cost, or time; then group into phases and convert into the controlled Task Plan.
A4: Phase / Area | B4: Task | C4: WBS ID | D4: Type | E4: Included? | F4: Event / Milestone? | G4: Owner | H4: Notes | I4: Source / next action | J4: Mapped to Task Plan
A5: 1 | B5: Project Management | C5: WBS-01 | D5: Labor | E5: Yes | F5: No | G5: Project Team | H5: Imported from current Dim_WBS source data | I5: Feeds Task Plan / EVM | J5: Mapped
A6: 2 | B6: Site Survey & Mobilization | C6: WBS-02 | D6: Labor | E6: Yes | F6: No | G6: Project Team | H6: Imported from current Dim_WBS source data | I6: Feeds Task Plan / EVM | J6: Mapped
A7: 3 | B7: Design & Engineering | C7: WBS-03 | D7: Labor | E7: Yes | F7: No | G7: Project Team | H7: Imported from current Dim_WBS source data | I7: Feeds Task Plan / EVM | J7: Mapped
A8: 4 | B8: Procurement - Materials | C8: WBS-04 | D8: Material | E8: Yes | F8: No | G8: Project Team | H8: Imported from current Dim_WBS source data | I8: Feeds Task Plan / EVM | J8: Mapped
A9: 5 | B9: Demolition & Prep | C9: WBS-05 | D9: Labor | E9: Yes | F9: No | G9: Project Team | H9: Imported from current Dim_WBS source data | I9: Feeds Task Plan / EVM | J9: Mapped
A10: 6 | B10: Electrical Rough-In | C10: WBS-06 | D10: Labor | E10: Yes | F10: No | G10: Project Team | H10: Imported from current Dim_WBS source data | I10: Feeds Task Plan / EVM | J10: Mapped
A11: 7 | B11: HVAC Installation | C11: WBS-07 | D11: Subcontractor | E11: Yes | F11: No | G11: Project Team | H11: Imported from current Dim_WBS source data | I11: Feeds Task Plan / EVM | J11: Mapped
A12: 8 | B12: Partitions & Drywall | C12: WBS-08 | D12: Subcontractor | E12: Yes | F12: No | G12: Project Team | H12: Imported from current Dim_WBS source data | I12: Feeds Task Plan / EVM | J12: Mapped
A13: 9 | B13: Flooring | C13: WBS-09 | D13: Material | E13: Yes | F13: No | G13: Project Team | H13: Imported from current Dim_WBS source data | I13: Feeds Task Plan / EVM | J13: Mapped
A14: 10 | B14: Fixtures & Furniture | C14: WBS-10 | D14: Material | E14: Yes | F14: No | G14: Project Team | H14: Imported from current Dim_WBS source data | I14: Feeds Task Plan / EVM | J14: Mapped
A15: 11 | B15: Testing / Commissioning | C15: WBS-11 | D15: Labor | E15: Yes | F15: No | G15: Project Team | H15: Imported from current Dim_WBS source data | I15: Feeds Task Plan / EVM | J15: Mapped
A16: 12 | B16: Handover & Closeout | C16: WBS-12 | D16: Labor | E16: Yes | F16: No | G16: Project Team | H16: Imported from current Dim_WBS source data | I16: Feeds Task Plan / EVM | J16: Mapped
A17: Brainstorm / new | I17: Add new tasks here before sequencing
A18: Brainstorm / new | I18: Add new tasks here before sequencing
A21: Example task-list method from attachment | B21: Garden office example grouped tasks: clear the space, foundations, buy the shed, install shed, legal. Use this area to add unstructured tasks before converting them to WBS.

Sheet EVM Dashboard
A1: OFFICE FIT-OUT - PROJECT CONTROLLING DASHBOARD
A2: EVM Performance Status | Tufte-Compliant Design | Data-Ink Maximized
A4: Status Date: | B4: 46203 | D4: Status Week: | E4: 8 | G4: Sector: | H4: Defense/Engineering | N4: RAG Legend | O4: Rule | P4: Meaning
N5: Green | O5: Good | P5: On/above plan or low exposure
A6: BUDGET AT COMPLETION (BAC) | D6: PLANNED VALUE (PV) | G6: ACTUAL COST (AC) | J6: EARNED VALUE (EV) | N6: Amber | O6: Watch | P6: Near threshold / medium exposure
A7: 267150 | D7: 218733.34 | G7: 141665.44 | J7: 130718 | N7: Red | O7: Action | P7: Behind plan, overrun, or high exposure
A9: COST VARIANCE (CV) | D9: SCHEDULE VARIANCE (SV) | G9: CPI (COST INDEX) | J9: SPI (SCHEDULE INDEX)
A10: -10947.444 | D10: -88015.344 | G10: 0.92272326 | J10: 0.5976135
A12: ESTIMATE AT COMPLETION (EAC) | D12: ESTIMATE TO COMPLETE (ETC) | G12: VARIANCE AT COMPLETION (VAC) | J12: PROJECT PROGRESS %
A13: 289523.43 | D13: 147857.99 | G13: -22373.428 | J13: 0.48930562
A15: WBS Element Performance Breakdown
A17: WBS ID | B17: Activity Name | C17: Type | D17: Budget (BAC) | E17: Planned Value (PV) | F17: Actual Cost (AC) | G17: Progress % | H17: Earned Value (EV) | I17: CV | J17: SV | K17: CPI | L17: SPI | M17: EAC | N17: ETC | O17: VAC | P17: Status
A18: WBS-01 | B18: Project Management | C18: Labor | D18: 16500 | E18: 12000 | F18: 9280 | G18: 0.5 | H18: 8250 | I18: -1030 | J18: -3750 | K18: 0.88900862 | L18: 0.6875 | M18: 18560 | N18: 9280 | O18: -2060 | P18: 🔴 Overrun
A19: WBS-02 | B19: Site Survey & Mobilization | C19: Labor | D19: 8500 | E19: 8500 | F19: 8700 | G19: 1 | H19: 8500 | I19: -200 | J19: 0 | K19: 0.97701149 | L19: 1 | M19: 8700 | N19: 0 | O19: -200 | P19: 🔴 Overrun
A20: WBS-03 | B20: Design & Engineering | C20: Labor | D20: 19200 | E20: 19200 | F20: 18195.04 | G20: 1 | H20: 19200 | I20: 1004.96 | J20: 0 | K20: 1.0552326 | L20: 1 | M20: 18195.04 | N20: 0 | O20: 1004.96 | P20: On Track
A21: WBS-04 | B21: Procurement - Materials | C21: Material | D21: 42000 | E21: 42000 | F21: 41300 | G21: 1 | H21: 42000 | I21: 700 | J21: 0 | K21: 1.0169492 | L21: 1 | M21: 41300 | N21: 0 | O21: 700 | P21: On Track
A22: WBS-05 | B22: Demolition & Prep | C22: Labor | D22: 13200 | E22: 13200 | F22: 13408.16 | G22: 1 | H22: 13200 | I22: -208.16 | J22: 0 | K22: 0.98447513 | L22: 1 | M22: 13408.16 | N22: 0 | O22: -208.16 | P22: 🔴 Overrun
A23: WBS-06 | B23: Electrical Rough-In | C23: Labor | D23: 26000 | E23: 26000 | F23: 26206.24 | G23: 0.7 | H23: 18200 | I23: -8006.24 | J23: -7800 | K23: 0.69449108 | L23: 0.7 | M23: 37437.486 | N23: 11231.246 | O23: -11437.486 | P23: 🔴 Overrun
A24: WBS-07 | B24: HVAC Installation | C24: Subcontractor | D24: 36000 | E24: 36000 | F24: 17476.8 | G24: 0.4 | H24: 14400 | I24: -3076.8 | J24: -21600 | K24: 0.82394946 | L24: 0.4 | M24: 43692 | N24: 26215.2 | O24: -7692 | P24: 🔴 Overrun
A25: WBS-08 | B25: Partitions & Drywall | C25: Subcontractor | D25: 28000 | E25: 28000 | F25: 7099.2 | G25: 0.248857 | H25: 6967.996 | I25: -131.204 | J25: -21032.004 | K25: 0.98151848 | L25: 0.248857 | M25: 28527.226 | N25: 21428.026 | O25: -527.22648 | P25: 🔴 Overrun
A26: WBS-09 | B26: Flooring | C26: Material | D26: 35750 | E26: 23833.34 | F26: 0 | G26: 0 | H26: 0 | I26: 0 | J26: -23833.34 | K26: 1 | L26: 0 | M26: 35750 | N26: 35750 | O26: 0 | P26: 🔴 Overrun
A27: WBS-10 | B27: Fixtures & Furniture | C27: Material | D27: 30000 | E27: 10000 | F27: 0 | G27: 0 | H27: 0 | I27: 0 | J27: -10000 | K27: 1 | L27: 0 | M27: 30000 | N27: 30000 | O27: 0 | P27: 🔴 Overrun
A28: WBS-11 | B28: Testing / Commissioning | C28: Labor | D28: 8400 | E28: 0 | F28: 0 | G28: 0 | H28: 0 | I28: 0 | J28: 0 | K28: 1 | L28: 1 | M28: 8400 | N28: 8400 | O28: 0 | P28: On Track
A29: WBS-12 | B29: Handover & Closeout | C29: Labor | D29: 3600 | E29: 0 | F29: 0 | G29: 0 | H29: 0 | I29: 0 | J29: 0 | K29: 1 | L29: 1 | M29: 3600 | N29: 3600 | O29: 0 | P29: On Track
A30: Total / Project Portfolio | D30: ='Task Plan'!H17 -> 267150 | E30: ='Task Plan'!I17 -> 218733.34 | F30: ='Task Plan'!J17 -> 141665.44 | G30: ='Task Plan'!K17 -> 0.48930562 | H30: ='Task Plan'!L17 -> 130718 | I30: ='Task Plan'!N17 -> -10947.444 | J30: ='Task Plan'!M17 -> -88015.344 | K30: ='Task Plan'!P17 -> 0.92272326 | L30: ='Task Plan'!O17 -> 0.5976135 | M30: ='Task Plan'!Q17 -> 289523.43 | N30: ='Task Plan'!R17 -> 147857.99 | O30: ='Task Plan'!S17 -> -22373.428 | P30: =IF('Task Plan'!T17="Red","🔴 Overrun",IF('Task Plan'!T17="Amber","🟡 Warning","On Track")) -> 🔴 Overrun
A33: Weekly Cumulative Performance Trends
A35: Week | B35: Week Date | C35: Weekly PV | D35: Cum PV | E35: Weekly AC | F35: Cum AC | G35: Cum EV | H35: CV | I35: SV | J35: CPI | K35: SPI
A36: 1 | B36: 46150 | C36: 14900 | D36: 14900 | E36: 15975.04 | F36: 15975.04 | G36: 13588 | H36: -2387.04 | I36: -1312 | J36: 0.8505769 | K36: 0.91194631
A37: 2 | B37: 46157 | C37: 22800 | D37: 37700 | E37: 22654.08 | F37: 38629.12 | G37: 35814.003 | H37: -2815.1169 | I37: -1885.9969 | J37: 0.92712449 | K37: 0.94997356
A38: 3 | B38: 46164 | C38: 22800 | D38: 60500 | E38: 22654.08 | F38: 61283.2 | G38: 56665 | H38: -4618.2 | I38: -3835 | J38: 0.92464166 | K38: 0.93661157
A39: 4 | B39: 46171 | C39: 25066.67 | D39: 85566.67 | E39: 24906.24 | F39: 86189.44 | G39: 79601.329 | H39: -6588.1115 | I39: -5965.3415 | J39: 0.92356243 | K39: 0.93028429
A40: 5 | B40: 46178 | C40: 29666.67 | D40: 115233.34 | E40: 29476.8 | F40: 115666.24 | G40: 106769.67 | H40: -8896.5665 | I40: -8463.6665 | J40: 0.92308416 | K40: 0.92655193
A41: 6 | B41: 46185 | C41: 26166.66 | D41: 141400 | E41: 25999.2 | F41: 141665.44 | G41: 130718 | H41: -10947.444 | I41: -10682.004 | J41: 0.92272326 | K41: 0.92445542
A42: 7 | B42: 46192 | C42: 17500 | D42: 158900 | E42: 0 | F42: 141665.44 | G42: 130718 | H42: -10947.444 | I42: -28182.004 | J42: 0.92272326 | K42: 0.82264315
A43: 8 | B43: 46199 | C43: 29416.67 | D43: 188316.67 | E43: 0 | F43: 141665.44 | G43: 130718 | H43: -10947.444 | I43: -57598.674 | J43: 0.92272326 | K43: 0.69413927
A44: 9 | B44: 46206 | C44: 30416.67 | D44: 218733.34 | E44: 0 | F44: 141665.44 | G44: 130718 | H44: -10947.444 | I44: -88015.344 | J44: 0.92272326 | K44: 0.5976135
A45: 10 | B45: 46213 | C45: 23416.66 | D45: 242150 | E45: 0 | F45: 141665.44 | G45: 130718 | H45: -10947.444 | I45: -111432 | J45: 0.92272326 | K45: 0.53982241
A46: 11 | B46: 46220 | C46: 15700 | D46: 257850 | E46: 0 | F46: 141665.44 | G46: 130718 | H46: -10947.444 | I46: -127132 | J46: 0.92272326 | K46: 0.50695364
A47: 12 | B47: 46227 | C47: 9300 | D47: 267150 | E47: 0 | F47: 141665.44 | G47: 130718 | H47: -10947.444 | I47: -136432 | J47: 0.92272326 | K47: 0.48930562

Sheet Red Actions
A1: Red RAG Action Recommendations
A2: Focused recovery actions for WBS items and control risks currently flagged Red. Evidence is pulled live from tbl_Task_Plan.
A4: STORY IN BRIEF
A5: The red status is mainly schedule-driven: Flooring, Fixtures & Furniture, Partitions & Drywall, HVAC, and Electrical Rough-In are the recovery priorities because their SPI and schedule variances are pulling the project off plan. Cost exposure is concentrated in Electrical Rough-In and HVAC, while completed red tasks need closeout variance review rather than delivery acceleration. The recommended response is a short recovery sprint: remove blockers, confirm subcontractor/material readiness, reset near-term dates, and escalate decision items already logged in the Review sheet.
A9: Red WBS items | C9: Worst red SPI | E9: Largest red SV | G9: Red forecast overrun
A10: =COUNTIF(tbl_Task_Plan[Status],"Red") -> 8 | C10: =_xlfn.MINIFS(tbl_Task_Plan[SPI],tbl_Task_Plan[Status],"Red") -> 0 | E10: =_xlfn.MINIFS(tbl_Task_Plan[SV],tbl_Task_Plan[Status],"Red") -> -23833.34 | G10: =-SUMIFS(tbl_Task_Plan[VAC],tbl_Task_Plan[Status],"Red") -> 22124.872
A13: Priority | B13: WBS ID | C13: Activity | D13: Red driver | E13: Live evidence | F13: Recommended action | G13: Owner | H13: Due date
A14: 1 | B14: WBS-01 | C14: Project Management | D14: Cost overrun | E14: CPI 0.89 / SPI 0.69 | F14: Review scope, resource loading, and remaining forecast for Project Management | G14: Project Manager | H14: 46210
A15: 2 | B15: WBS-02 | C15: Site Survey & Mobilization | D15: Cost overrun | E15: CPI 0.98 / SPI 1.00 | F15: Review scope, resource loading, and remaining forecast for Site Survey & Mobilization | G15: Project Manager | H15: 46210
A16: 3 | B16: WBS-05 | C16: Demolition & Prep | D16: Cost overrun | E16: CPI 0.98 / SPI 1.00 | F16: Review scope, resource loading, and remaining forecast for Demolition & Prep | G16: Project Manager | H16: 46210
A17: 4 | B17: WBS-06 | C17: Electrical Rough-In | D17: Cost overrun | E17: CPI 0.69 / SPI 0.70 | F17: Review scope, resource loading, and remaining forecast for Electrical Rough-In | G17: Project Manager | H17: 46210
A18: 5 | B18: WBS-07 | C18: HVAC Installation | D18: Cost overrun | E18: CPI 0.82 / SPI 0.40 | F18: Review scope, resource loading, and remaining forecast for HVAC Installation | G18: Project Manager | H18: 46210
A19: 6 | B19: WBS-08 | C19: Partitions & Drywall | D19: Cost overrun | E19: CPI 0.98 / SPI 0.25 | F19: Review scope, resource loading, and remaining forecast for Partitions & Drywall | G19: Project Manager | H19: 46210
A20: 7 | B20: WBS-09 | C20: Flooring | D20: Schedule efficiency | E20: CPI 1.00 / SPI 0.00 | F20: Review scope, resource loading, and remaining forecast for Flooring | G20: Project Manager | H20: 46210
A21: 8 | B21: WBS-10 | C21: Fixtures & Furniture | D21: Schedule efficiency | E21: CPI 1.00 / SPI 0.00 | F21: Review scope, resource loading, and remaining forecast for Fixtures & Furniture | G21: Project Manager | H21: 46210

Sheet Pivot Summary
A1: High-Level Pivot Summary & Descriptive Statistics
A2: PivotTables summarize the key project-control tables; descriptive statistics are live formulas linked to the Task Plan source range.
A4: STORY IN BRIEF
A5: The project is Red overall: PV 218,733 NOK, AC 141,665 NOK, EV 130,718 NOK, with 8 red WBS items. The largest schedule gap is visible in later material/subcontractor work where planned value is ahead of earned progress.
A8: Red WBS | B8: Total BAC | C8: Actual Cost | D8: Earned Value | E8: Avg SPI | F8: Avg CPI | G8: Forecast overrun
A9: WBS-01 | B9: 16500 | C9: 9280 | D9: 8250 | E9: 0.6875 | F9: 0.88900862 | G9: -2060
A10: WBS-02 | B10: 8500 | C10: 8700 | D10: 8500 | E10: 1 | F10: 0.97701149 | G10: -200
A11: WBS-05 | B11: 13200 | C11: 13408.16 | D11: 13200 | E11: 1 | F11: 0.98447513 | G11: -208.16
A12: DESCRIPTIVE STATISTICS
A13: Metric | B13: Count | C13: Mean | D13: Median | E13: Std Dev | F13: Min | G13: Max
A14: BAC (NOK) | B14: 12 | C14: 22262.5 | D14: 22600 | E14: 12510.125 | F14: 3600 | G14: 42000
A15: PV @ Status | B15: 12 | C15: 18227.778 | D15: 16200 | E15: 13348.937 | F15: 0 | G15: 42000
A16: AC @ Status | B16: 12 | C16: 11805.453 | D16: 8990 | E16: 12607.776 | F16: 0 | G16: 41300
A17: EV @ Status | B17: 12 | C17: 10893.166 | D17: 8375 | E17: 12099.634 | F17: 0 | G17: 42000
A18: Progress % | B18: 12 | C18: 0.48740475 | D18: 0.45 | E18: 0.43809185 | F18: 0 | G18: 1
A19: SPI | B19: 12 | C19: 0.66969642 | D19: 0.85 | E19: 0.40481944 | F19: 0 | G19: 1
A20: CPI | B20: 12 | C20: 0.95188634 | D20: 0.99223756 | E20: 0.10149718 | F20: 0.69449108 | G20: 1.0552326
A21: SV | B21: 12 | C21: -7334.612 | D21: -1875 | E21: 9564.5054 | F21: -23833.34 | G21: 0
A22: CV | B22: 12 | C22: -912.287 | D22: -65.602 | E22: 2453.9533 | F22: -8006.24 | G22: 1004.96
A23: VAC | B23: 12 | C23: -1701.6593 | D23: -100 | E23: 3829.7882 | F23: -11437.486 | G23: 1004.96
A26: PIVOT: COST / VALUE BY TYPE
A27: PIVOT: COST / VALUE BY TYPE
A28: Row Labels | B28: Sum of BAC (NOK) | C28: Sum of PV @ Status | D28: Sum of AC @ Status | E28: Sum of EV @ Status | F28: Sum of SV | G28: Sum of CV | H28: Sum of VAC
A29: Labor | B29: 95400 | C29: 78900 | D29: 75789.44 | E29: 67350 | F29: -11550 | G29: -8439.44 | H29: -12900.686
A30: Material | B30: 107750 | C30: 75833.34 | D30: 41300 | E30: 42000 | F30: -33833.34 | G30: 700 | H30: 700
A31: Subcontractor | B31: 64000 | C31: 64000 | D31: 24576 | E31: 21367.996 | F31: -42632.004 | G31: -3208.004 | H31: -8219.2265
A32: Grand Total | B32: 267150 | C32: 218733.34 | D32: 141665.44 | E32: 130718 | F32: -88015.344 | G32: -10947.444 | H32: -20419.912
A35: PIVOT: COST / VALUE BY STATUS
A36: Row Labels | B36: Sum of BAC (NOK) | C36: Sum of PV @ Status | D36: Sum of AC @ Status | E36: Sum of EV @ Status | F36: Sum of SV | G36: Sum of CV | H36: Sum of VAC
A37: Red | B37: 193950 | C37: 157533.34 | D37: 82170.4 | E37: 69517.996 | F37: -88015.344 | G37: -12652.404 | H37: -22124.872
A38: Green | B38: 73200 | C38: 61200 | D38: 59495.04 | E38: 61200 | F38: 0 | G38: 1704.96 | H38: 1704.96
A39: Grand Total | B39: 267150 | C39: 218733.34 | D39: 141665.44 | E39: 130718 | F39: -88015.344 | G39: -10947.444 | H39: -20419.912
A43: PIVOT: ACTUAL COSTS BY WBS
A44: Row Labels | B44: Sum of Actual_Cost | C44: Sum of Hours_Worked
A45: WBS-01 | B45: 9280 | C45: 6.09
A46: WBS-02 | B46: 8700 | C46: 3.95
A47: WBS-03 | B47: 18195.04 | C47: 7.6
A48: WBS-04 | B48: 41300 | C48: 0
A49: WBS-05 | B49: 13408.16 | C49: 6.05
A50: WBS-06 | B50: 26206.24 | C50: 10.1
...

Sheet Resource Grid
A1: Resource Allocation Grid
A2: Weekly hours and cost grid adapted from the attached Gantt template: rows are WBS tasks; columns are reporting weeks; totals are live formulas from actual-cost facts.
A4: WBS ID | B4: Activity | C4: Resource / Role | D4: Measure | E4: Wk1 | F4: Wk2 | G4: Wk3 | H4: Wk4 | I4: Wk5 | J4: Wk6 | K4: Wk7 | L4: Wk8 | M4: Wk9 | N4: Wk10 | O4: Wk11 | P4: Wk12 | Q4: Total | R4: BAC | S4: Actual @ Status | T4: Remaining BAC | U4: CPI | V4: RAG | W4: Template source | X4: Notes
A5: WBS-01 | B5: Project Management | C5: Project Manager / Management | D5: Hours | E5: 0.84 | F5: 1.05 | G5: 1.05 | H5: 1.05 | I5: 1.05 | J5: 1.05 | K5: 0 | L5: 0 | M5: 0 | N5: 0 | O5: 0 | P5: 0 | Q5: 6.09 | R5: 16500 | S5: 9280 | T5: 7220 | U5: 0.88900862 | V5: Red | W5: 8.1.2 Gantt template from garden office | X5: Hours row
A6: WBS-01 | B6: Project Management | C6: Project Manager / Management | D6: Cost | E6: 1280 | F6: 1600 | G6: 1600 | H6: 1600 | I6: 1600 | J6: 1600 | K6: 0 | L6: 0 | M6: 0 | N6: 0 | O6: 0 | P6: 0 | Q6: 9280 | R6: 16500 | S6: 9280 | T6: 7220 | U6: 0.88900862 | V6: Red | W6: 8.1.2 Gantt template from garden office | X6: Cost row
A7: WBS-02 | B7: Site Survey & Mobilization | C7: Demolition Crew / Labor | D7: Hours | E7: 3.95 | F7: 0 | G7: 0 | H7: 0 | I7: 0 | J7: 0 | K7: 0 | L7: 0 | M7: 0 | N7: 0 | O7: 0 | P7: 0 | Q7: 3.95 | R7: 8500 | S7: 8700 | T7: -200 | U7: 0.97701149 | V7: Red | W7: 8.1.2 Gantt template from garden office | X7: Hours row
A8: WBS-02 | B8: Site Survey & Mobilization | C8: Demolition Crew / Labor | D8: Cost | E8: 8700 | F8: 0 | G8: 0 | H8: 0 | I8: 0 | J8: 0 | K8: 0 | L8: 0 | M8: 0 | N8: 0 | O8: 0 | P8: 0 | Q8: 8700 | R8: 8500 | S8: 8700 | T8: -200 | U8: 0.97701149 | V8: Red | W8: 8.1.2 Gantt template from garden office | X8: Cost row
A9: WBS-03 | B9: Design & Engineering | C9: Lead Engineer / Engineering | D9: Hours | E9: 2.5 | F9: 2.5 | G9: 2.6 | H9: 0 | I9: 0 | J9: 0 | K9: 0 | L9: 0 | M9: 0 | N9: 0 | O9: 0 | P9: 0 | Q9: 7.6 | R9: 19200 | S9: 18195.04 | T9: 1004.96 | U9: 1.0552326 | V9: Green | W9: 8.1.2 Gantt template from garden office | X9: Hours row
A10: WBS-03 | B10: Design & Engineering | C10: Lead Engineer / Engineering | D10: Cost | E10: 5995.04 | F10: 6000 | G10: 6200 | H10: 0 | I10: 0 | J10: 0 | K10: 0 | L10: 0 | M10: 0 | N10: 0 | O10: 0 | P10: 0 | Q10: 18195.04 | R10: 19200 | S10: 18195.04 | T10: 1004.96 | U10: 1.0552326 | V10: Green | W10: 8.1.2 Gantt template from garden office | X10: Cost row
A11: WBS-04 | B11: Procurement - Materials | C11: Materials Vendor / Vendor | D11: Hours | E11: 0 | F11: 0 | G11: 0 | H11: 0 | I11: 0 | J11: 0 | K11: 0 | L11: 0 | M11: 0 | N11: 0 | O11: 0 | P11: 0 | Q11: 0 | R11: 42000 | S11: 41300 | T11: 700 | U11: 1.0169492 | V11: Green | W11: 8.1.2 Gantt template from garden office | X11: Hours row
A12: WBS-04 | B12: Procurement - Materials | C12: Materials Vendor / Vendor | D12: Cost | E12: 0 | F12: 10500 | G12: 10200 | H12: 10200 | I12: 10400 | J12: 0 | K12: 0 | L12: 0 | M12: 0 | N12: 0 | O12: 0 | P12: 0 | Q12: 41300 | R12: 42000 | S12: 41300 | T12: 700 | U12: 1.0169492 | V12: Green | W12: 8.1.2 Gantt template from garden office | X12: Cost row
A13: WBS-05 | B13: Demolition & Prep | C13: Demolition Crew / Labor | D13: Hours | E13: 0 | F13: 2.05 | G13: 2.1 | H13: 1.9 | I13: 0 | J13: 0 | K13: 0 | L13: 0 | M13: 0 | N13: 0 | O13: 0 | P13: 0 | Q13: 6.05 | R13: 13200 | S13: 13408.16 | T13: -208.16 | U13: 0.98447513 | V13: Red | W13: 8.1.2 Gantt template from garden office | X13: Hours row
A14: WBS-05 | B14: Demolition & Prep | C14: Demolition Crew / Labor | D14: Cost | E14: 0 | F14: 4554.08 | G14: 4654.08 | H14: 4200 | I14: 0 | J14: 0 | K14: 0 | L14: 0 | M14: 0 | N14: 0 | O14: 0 | P14: 0 | Q14: 13408.16 | R14: 13200 | S14: 13408.16 | T14: -208.16 | U14: 0.98447513 | V14: Red | W14: 8.1.2 Gantt template from garden office | X14: Cost row
A15: WBS-06 | B15: Electrical Rough-In | C15: Electrician / Trades | D15: Hours | E15: 0 | F15: 0 | G15: 0 | H15: 3.45 | I15: 3.4 | J15: 3.25 | K15: 0 | L15: 0 | M15: 0 | N15: 0 | O15: 0 | P15: 0 | Q15: 10.1 | R15: 26000 | S15: 26206.24 | T15: -206.24 | U15: 0.69449108 | V15: Red | W15: 8.1.2 Gantt template from garden office | X15: Hours row
A16: WBS-06 | B16: Electrical Rough-In | C16: Electrician / Trades | D16: Cost | E16: 0 | F16: 0 | G16: 0 | H16: 8906.24 | I16: 8800 | J16: 8500 | K16: 0 | L16: 0 | M16: 0 | N16: 0 | O16: 0 | P16: 0 | Q16: 26206.24 | R16: 26000 | S16: 26206.24 | T16: -206.24 | U16: 0.69449108 | V16: Red | W16: 8.1.2 Gantt template from garden office | X16: Cost row
... A28: WBS-12 | B28: Handover & Closeout | C28: Labor | D28: Cost | E28: 0 | F28: 0 | G28: 0 | H28: 0 | I28: 0 | J28: 0 | K28: 0 | L28: 0 | M28: 0 | N28: 0 | O28: 0 | P28: 0 | Q28: 0 | R28: 3600 | S28: 0 | T28: 3600 | U28: 1 | V28: Green | W28: 8.1.2 Gantt template from garden office | X28: Cost row
A31: Gantt of Gantts / monthly workload summary | B31: May-26 | C31: Jun-26 | D31: Jul-26 | E31: Aug-26 | F31: Sep-26 | G31: Oct-26 | H31: Nov-26 | I31: Dec-26 | J31: Total | K31: Source | L31: Interpretation
A32: Planned PV | B32: 85566.67 | C32: 133166.67 | D32: 48416.66 | E32: 0 | F32: 0 | G32: 0 | H32: 0 | I32: 0 | J32: 267150 | K32: 8.1.2 Gantt of Gantts template | L32: Monthly portfolio-style total from current project PV
A33: Actual Cost | B33: 86189.44 | C33: 55476 | D33: 0 | E33: 0 | F33: 0 | G33: 0 | H33: 0 | I33: 0 | J33: 141665.44 | K33: 8.1.2 Gantt of Gantts template | L33: Monthly portfolio-style total from actual costs
A34: Active WBS count | B34: 6 | C34: 7 | D34: 5 | E34: 0 | F34: 0 | G34: 0 | H34: 0 | I34: 0 | J34: 18 | K34: 8.1.2 Gantt of Gantts template | L34: Simple monthly activity indicator

Sheet Dim_Project
A1: Project_ID | B1: Project_Name | C1: Start_Date | D1: End_Date | E1: BAC | F1: Sector
A2: PRJ001 | B2: Generic Master Project | C2: 2026-01-01 | D2: 2026-12-31 | E2: 267150 | F2: Defense/Engineering

Sheet Dim_WBS
A1: WBS_ID | B1: WBS_Code | C1: Activity_Name | D1: Type | E1: Total_Budget
A2: WBS-01 | B2: 1 | C2: Project Management | D2: Labor | E2: 16500
A3: WBS-02 | B3: 2 | C3: Site Survey & Mobilization | D3: Labor | E3: 8500
A4: WBS-03 | B4: 3 | C4: Design & Engineering | D4: Labor | E4: 19200
A5: WBS-04 | B5: 4 | C5: Procurement - Materials | D5: Material | E5: 42000
A6: WBS-05 | B6: 5 | C6: Demolition & Prep | D6: Labor | E6: 13200
A7: WBS-06 | B7: 6 | C7: Electrical Rough-In | D7: Labor | E7: 26000
A8: WBS-07 | B8: 7 | C8: HVAC Installation | D8: Subcontractor | E8: 36000
A9: WBS-08 | B9: 8 | C9: Partitions & Drywall | D9: Subcontractor | E9: 28000
A10: WBS-09 | B10: 9 | C10: Flooring | D10: Material | E10: 35750
A11: WBS-10 | B11: 10 | C11: Fixtures & Furniture | D11: Material | E11: 30000
A12: WBS-11 | B12: 11 | C12: Testing / Commissioning | D12: Labor | E12: 8400
A13: WBS-12 | B13: 12 | C13: Handover & Closeout | D13: Labor | E13: 3600

Sheet Dim_Resource
A1: Resource_ID | B1: Resource_Name | C1: Role | D1: Hourly_Rate
A2: R01 | B2: Project Manager | C2: Management | D2: 1500
A3: R02 | B3: Lead Engineer | C3: Engineering | D3: 2400
A4: R03 | B4: Electrician | C4: Trades | D4: 2600
A5: R04 | B5: Demolition Crew | C5: Labor | D5: 2200
A6: R05 | B6: Testing Engineer | C6: QA | D6: 2100
A7: R06 | B7: Closeout Specialist | C7: QA | D7: 1800
A8: R07 | B8: Materials Vendor | C8: Vendor | D8: 0
A9: R08 | B9: HVAC Contractor | C9: Contractor | D9: 0
A10: R09 | B10: Drywall Contractor | C10: Contractor | D10: 0
A11: R10 | B11: Flooring Supplier | C11: Vendor | D11: 0
A12: R11 | B12: Furniture Supplier | C12: Vendor | D12: 0

Sheet Dim_Calendar
A1: Date | B1: Year | C1: Month | D1: Month_Name | E1: Quarter | F1: Week_Number | G1: Is_Weekday
A2: 46146 | B2: 2026 | C2: 5 | D2: May | E2: 2 | F2: 1 | G2: 1
A3: 46147 | B3: 2026 | C3: 5 | D3: May | E3: 2 | F3: 1 | G3: 1
A4: 46148 | B4: 2026 | C4: 5 | D4: May | E4: 2 | F4: 1 | G4: 1
A5: 46149 | B5: 2026 | C5: 5 | D5: May | E5: 2 | F5: 1 | G5: 1
A6: 46150 | B6: 2026 | C6: 5 | D6: May | E6: 2 | F6: 1 | G6: 1
A7: 46151 | B7: 2026 | C7: 5 | D7: May | E7: 2 | F7: 1 | G7: 0
A8: 46152 | B8: 2026 | C8: 5 | D8: May | E8: 2 | F8: 1 | G8: 0
A9: 46153 | B9: 2026 | C9: 5 | D9: May | E9: 2 | F9: 2 | G9: 1
A10: 46154 | B10: 2026 | C10: 5 | D10: May | E10: 2 | F10: 2 | G10: 1
A11: 46155 | B11: 2026 | C11: 5 | D11: May | E11: 2 | F11: 2 | G11: 1
A12: 46156 | B12: 2026 | C12: 5 | D12: May | E12: 2 | F12: 2 | G12: 1
A13: 46157 | B13: 2026 | C13: 5 | D13: May | E13: 2 | F13: 2 | G13: 1
... A85: 46229 | B85: 2026 | C85: 7 | D85: July | E85: 3 | F85: 12 | G85: 0

Sheet Fact_Baseline_PV
A1: Date | B1: WBS_ID | C1: Planned_Value
A2: 46153 | B2: WBS-01 | C2: 1500
A3: 46160 | B3: WBS-01 | C3: 1500
A4: 46167 | B4: WBS-01 | C4: 1500
A5: 46174 | B5: WBS-01 | C5: 1500
A6: 46181 | B6: WBS-01 | C6: 1500
A7: 46188 | B7: WBS-01 | C7: 1500
A8: 46195 | B8: WBS-01 | C8: 1500
A9: 46202 | B9: WBS-01 | C9: 1500
A10: 46209 | B10: WBS-01 | C10: 1500
A11: 46216 | B11: WBS-01 | C11: 1500
A12: 46223 | B12: WBS-01 | C12: 1500
A13: 46146 | B13: WBS-02 | C13: 8500
... A43: 46223 | B43: WBS-12 | C43: 3600

Sheet Fact_Actual_Costs
A1: Date | B1: WBS_ID | C1: Resource_ID | D1: Actual_Cost | E1: Hours_Worked
A2: 46147 | B2: WBS-01 | C2: R01 | D2: 320 | E2: 0.21
A3: 46148 | B3: WBS-01 | C3: R01 | D3: 320 | E3: 0.21
A4: 46149 | B4: WBS-01 | C4: R01 | D4: 320 | E4: 0.21
A5: 46150 | B5: WBS-01 | C5: R01 | D5: 320 | E5: 0.21
A6: 46146 | B6: WBS-02 | C6: R04 | D6: 1740 | E6: 0.79
A7: 46147 | B7: WBS-02 | C7: R04 | D7: 1740 | E7: 0.79
A8: 46148 | B8: WBS-02 | C8: R04 | D8: 1740 | E8: 0.79
A9: 46149 | B9: WBS-02 | C9: R04 | D9: 1740 | E9: 0.79
A10: 46150 | B10: WBS-02 | C10: R04 | D10: 1740 | E10: 0.79
A11: 46146 | B11: WBS-03 | C11: R02 | D11: 1199.01 | E11: 0.5
A12: 46147 | B12: WBS-03 | C12: R02 | D12: 1199.01 | E12: 0.5
A13: 46148 | B13: WBS-03 | C13: R02 | D13: 1199.01 | E13: 0.5
... A99: 46185 | B99: WBS-08 | C99: R09 | D99: 1419.84 | E99: 0

Sheet Fact_Physical_Progress
A1: Date | B1: WBS_ID | C1: Physical_Progress_Pct
A2: 46150 | B2: WBS-02 | C2: 1
A3: 46150 | B3: WBS-03 | C3: 0.265
A4: 46157 | B4: WBS-01 | C4: 0.166667
A5: 46157 | B5: WBS-02 | C5: 1
A6: 46157 | B6: WBS-03 | C6: 0.6
A7: 46157 | B7: WBS-04 | C7: 0.2
A8: 46157 | B8: WBS-05 | C8: 0.351818
A9: 46164 | B9: WBS-01 | C9: 0.25
A10: 46164 | B10: WBS-02 | C10: 1
A11: 46164 | B11: WBS-03 | C11: 1
A12: 46164 | B12: WBS-04 | C12: 0.45
A13: 46164 | B13: WBS-05 | C13: 0.45
... A34: 46185 | B34: WBS-08 | C34: 0.248857

Sheet EVM
A1: EVM Reporting
A2: Weekly earned value reporting table using the guideline formulas: PV, AC, EV, SV, CV, SPI, CPI, BAC, EAC, ETC, and VAC.
A4: Week | B4: Week Date | C4: Cum PV | D4: Cum AC | E4: Cum EV | F4: SV | G4: CV | H4: SPI | I4: CPI | J4: BAC | K4: EAC | L4: ETC | M4: VAC | N4: Status
A5: 1 | B5: 46150 | C5: 14900 | D5: 15975.04 | E5: 13588 | F5: -1312 | G5: -2387.04 | H5: 0.91194631 | I5: 0.8505769 | J5: 267150 | K5: 314080.95 | L5: 298105.91 | M5: -46930.949 | N5: Red
A6: 2 | B6: 46157 | C6: 37700 | D6: 38629.12 | E6: 35814.003 | F6: -1885.9969 | G6: -2815.1169 | H6: 0.94997356 | I6: 0.92712449 | J6: 267150 | K6: 288149.01 | L6: 249519.89 | M6: -20999.006 | N6: Red
A7: 3 | B7: 46164 | C7: 60500 | D7: 61283.2 | E7: 56665 | F7: -3835 | G7: -4618.2 | H7: 0.93661157 | I7: 0.92464166 | J7: 267150 | K7: 288922.74 | L7: 227639.54 | M7: -21772.737 | N7: Red
A8: 4 | B8: 46171 | C8: 85566.67 | D8: 86189.44 | E8: 79601.329 | F8: -5965.3415 | G8: -6588.1115 | H8: 0.93028429 | I8: 0.92356243 | J8: 267150 | K8: 289260.36 | L8: 203070.92 | M8: -22110.359 | N8: Red
A9: 5 | B9: 46178 | C9: 115233.34 | D9: 115666.24 | E9: 106769.67 | F9: -8463.6665 | G9: -8896.5665 | H9: 0.92655193 | I9: 0.92308416 | J9: 267150 | K9: 289410.23 | L9: 173743.99 | M9: -22260.232 | N9: Red
A10: 6 | B10: 46185 | C10: 141400 | D10: 141665.44 | E10: 130718 | F10: -10682.004 | G10: -10947.444 | H10: 0.92445542 | I10: 0.92272326 | J10: 267150 | K10: 289523.43 | L10: 147857.99 | M10: -22373.428 | N10: Red
A11: 7 | B11: 46192 | C11: 158900 | D11: 141665.44 | E11: 130718 | F11: -28182.004 | G11: -10947.444 | H11: 0.82264315 | I11: 0.92272326 | J11: 267150 | K11: 289523.43 | L11: 147857.99 | M11: -22373.428 | N11: Red
A12: 8 | B12: 46199 | C12: 188316.67 | D12: 141665.44 | E12: 130718 | F12: -57598.674 | G12: -10947.444 | H12: 0.69413927 | I12: 0.92272326 | J12: 267150 | K12: 289523.43 | L12: 147857.99 | M12: -22373.428 | N12: Red
A13: 9 | B13: 46206 | C13: 218733.34 | D13: 141665.44 | E13: 130718 | F13: -88015.344 | G13: -10947.444 | H13: 0.5976135 | I13: 0.92272326 | J13: 267150 | K13: 289523.43 | L13: 147857.99 | M13: -22373.428 | N13: Red
A14: 10 | B14: 46213 | C14: 242150 | D14: 141665.44 | E14: 130718 | F14: -111432 | G14: -10947.444 | H14: 0.53982241 | I14: 0.92272326 | J14: 267150 | K14: 289523.43 | L14: 147857.99 | M14: -22373.428 | N14: Red
A15: 11 | B15: 46220 | C15: 257850 | D15: 141665.44 | E15: 130718 | F15: -127132 | G15: -10947.444 | H15: 0.50695364 | I15: 0.92272326 | J15: 267150 | K15: 289523.43 | L15: 147857.99 | M15: -22373.428 | N15: Red
A16: 12 | B16: 46227 | C16: 267150 | D16: 141665.44 | E16: 130718 | F16: -136432 | G16: -10947.444 | H16: 0.48930562 | I16: 0.92272326 | J16: 267150 | K16: 289523.43 | L16: 147857.99 | M16: -22373.428 | N16: Red
A19: Formula | B19: Workbook implementation | C19: Guideline meaning | D19: Current status-date value | E19: Check | F19: Source | G19: Column1 | H19: Status tie-out | I19: Dashboard value | J19: Task Plan value | K19: Variance | L19: Check2 | M19: Source3
A20: SV = EV - PV | B20: =INDEX(E5:E16,MATCH(Setup!$B$9,B5:B16,0))-INDEX(C5:C16,MATCH(Setup!$B$9,B5:B16,0)) -> #N/A | C20: Schedule variance at status date | D20: -88015.344 | E20: Live | F20: PM-EVM.md lines 145-150 | H20: PV | I20: 218733.34 | J20: 218733.34 | K20: 0 | L20: OK | M20: Task Plan!I17
A21: CV = EV - AC | B21: =INDEX(E5:E16,MATCH(Setup!$B$9,B5:B16,0))-INDEX(D5:D16,MATCH(Setup!$B$9,B5:B16,0)) -> #N/A | C21: Cost variance at status date | D21: -10947.444 | E21: Live | F21: PM-EVM.md lines 145-150 | H21: AC | I21: 141665.44 | J21: 141665.44 | K21: 0 | L21: OK | M21: Task Plan!J17
A22: SPI = EV / PV | B22: =INDEX(E5:E16,MATCH(Setup!$B$9,B5:B16,0))/INDEX(C5:C16,MATCH(Setup!$B$9,B5:B16,0)) -> #N/A | C22: Schedule efficiency | D22: 0.5976135 | E22: Live | F22: PM-EVM.md lines 145-150 | H22: EV | I22: 130718 | J22: 130718 | K22: 0 | L22: OK | M22: Task Plan!L17
A23: CPI = EV / AC | B23: =INDEX(E5:E16,MATCH(Setup!$B$9,B5:B16,0))/INDEX(D5:D16,MATCH(Setup!$B$9,B5:B16,0)) -> #N/A | C23: Cost efficiency | D23: 0.92272326 | E23: Live | F23: PM-EVM.md lines 145-150 | H23: SPI | I23: -10947.444 | J23: -10947.444 | K23: 0 | L23: OK | M23: Task Plan!O17
A24: EAC = BAC / CPI | B24: =Setup!$B$11/B23 -> #N/A | C24: Forecast final cost | D24: 289523.43 | E24: Live | F24: PM-EVM.md lines 203-214 | H24: CPI | I24: 0.5976135 | J24: 0.5976135 | K24: 0 | L24: OK | M24: Task Plan!P17
A25: VAC = BAC - EAC | B25: =Setup!$B$11/B23*-1+Setup!$B$11 -> #N/A | C25: Expected budget variance at completion | D25: 147857.99 | E25: Live | F25: PM-EVM.md lines 203-214 | H25: VAC | I25: 0.92272326 | J25: 0.92272326 | K25: 0 | L25: OK | M25: Task Plan!S17

Sheet EVM Charts
A1: Project Schedule & EVM Curves | N1: Project Start | O1: 46146
A2: Gantt schedule is derived from baseline PV dates by WBS; the S-curve uses cumulative PV, actual cost, and earned value as of each weekly status date. | N2: Project Finish | O2: =Control_Project_End -> 2026-12-31
N3: Status Date | O3: 46203
A4: WBS ID | B4: Activity | C4: Start | D4: Finish | E4: Start Offset | F4: Duration Days | G4: Progress % | H4: RAG
A5: WBS-01 | B5: Project Management | C5: 46153 | D5: 46229 | E5: 7 | F5: 77 | G5: 0.5 | H5: Amber | N5: RAG Legend | O5: Rule | P5: Used in charts
A6: WBS-02 | B6: Site Survey & Mobilization | C6: 46146 | D6: 46152 | E6: 0 | F6: 7 | G6: 1 | H6: Green | N6: Green | O6: Good / baseline target | P6: Gantt good bars; PV line
A7: WBS-03 | B7: Design & Engineering | C7: 46146 | D7: 46166 | E7: 0 | F7: 21 | G7: 1 | H7: Green | N7: Amber | O7: Watch / earned progress | P7: Gantt watch bars; EV line
A8: WBS-04 | B8: Procurement - Materials | C8: 46153 | D8: 46180 | E8: 7 | F8: 28 | G8: 1 | H8: Green | N8: Red | O8: Action / cost exposure | P8: Gantt action bars; AC line
A9: WBS-05 | B9: Demolition & Prep | C9: 46153 | D9: 46173 | E9: 7 | F9: 21 | G9: 1 | H9: Green | N9: White | O9: Hidden helper | P9: Gantt start-offset series
A10: WBS-06 | B10: Electrical Rough-In | C10: 46167 | D10: 46187 | E10: 21 | F10: 21 | G10: 0.7 | H10: Amber | N10: Red dotted | O10: Status date | P10: Vertical marker at 2026-06-30
A11: WBS-07 | B11: HVAC Installation | C11: 46174 | D11: 46201 | E11: 28 | F11: 28 | G11: 0.4 | H11: Red
A12: WBS-08 | B12: Partitions & Drywall | C12: 46181 | D12: 46208 | E12: 35 | F12: 28 | G12: 0.248857 | H12: Red
A13: WBS-09 | B13: Flooring | C13: 46195 | D13: 46215 | E13: 49 | F13: 21 | G13: 0 | H13: Red
A14: WBS-10 | B14: Fixtures & Furniture | C14: 46202 | D14: 46222 | E14: 56 | F14: 21 | G14: 0 | H14: Red
A15: WBS-11 | B15: Testing / Commissioning | C15: 46216 | D15: 46229 | E15: 70 | F15: 14 | G15: 0 | H15: Red
A16: WBS-12 | B16: Handover & Closeout | C16: 46223 | D16: 46229 | E16: 77 | F16: 7 | G16: 0 | H16: Red
