Workbook
Name Actual_Cost_Values: tbl_Fact_Actual_Costs[Actual_Cost]
Name Actual_Hours_Values: tbl_Fact_Actual_Costs[Hours_Worked]
Name Baseline_PV_Values: tbl_Fact_Baseline_PV[Planned_Value]
Name Control_BAC: Dim_Project!$E$2
Name Control_CPI_SPI_Green: Setup!$B$13
Name Control_CPI_SPI_Red: Setup!$B$12
Name Control_Progress_Amber: Setup!$B$14
Name Control_Progress_Green: Setup!$B$15
Name Control_Project_End: Dim_Project!$D$2
Name Control_Project_ID: Dim_Project!$A$2
Name Control_Project_Name: Dim_Project!$B$2
Name Control_Project_Start: Dim_Project!$C$2
Name Control_Sector: Dim_Project!$F$2
Name Control_Status_Date: Setup!$B$9
Name Input_Actual_Costs: tbl_Fact_Actual_Costs[]
Name Input_Baseline_PV: tbl_Fact_Baseline_PV[]
Name Input_Calendar: tbl_Dim_Calendar[]
Name Input_Physical_Progress: tbl_Fact_Physical_Progress[]
Name Input_Project: tbl_Dim_Project[]
Name Input_Resources: tbl_Dim_Resource[]
Name Input_WBS: tbl_Dim_WBS[]
Name Progress_Pct_Values: tbl_Fact_Physical_Progress[Physical_Progress_Pct]
Name Slicer_Category: #N/A
Name Slicer_Measure: #N/A
Name Slicer_Month_Name: #N/A
Name Slicer_Owner: #N/A
Name Slicer_Owner1: #N/A
Name Slicer_Owner2: #N/A
Name Slicer_RAG: #N/A
Name Slicer_RAG1: #N/A
Name Slicer_RAG2: #N/A
Name Slicer_RAG3: #N/A
Name Slicer_Resource_ID: #N/A
Name Slicer_Role: #N/A
Name Slicer_Status: #N/A
Name Slicer_Status1: #N/A
Name Slicer_Status2: #N/A
Name Slicer_Status3: #N/A
Name Slicer_Status4: #N/A
Name Slicer_Type: #N/A
Name Slicer_Type1: #N/A
Name Slicer_Type2: #N/A
Name Slicer_Type3: #N/A
Name Slicer_WBS_ID: #N/A
Name Slicer_WBS_ID1: #N/A
Name Slicer_WBS_ID2: #N/A
Name Slicer_WBS_ID3: #N/A
Name Slicer_WBS_ID4: #N/A
Name Slicer_Week: #N/A
Name Slicer_Week_Number: #N/A
Name WBS_Activities: tbl_Dim_WBS[Activity_Name]
Name WBS_Budgets: tbl_Dim_WBS[Total_Budget]
Name WBS_IDs: tbl_Dim_WBS[WBS_ID]
Name WBS_Types: tbl_Dim_WBS[Type]

Sheet Cover
A1: Office Fit-Out Project Control Workbook
A2: PM-EVM compliant workbook map: setup controls, task plan, Gantt, EVM S-curve, dashboard, source dimensions, and fact tables.
A4: Sheet | B4: Purpose | D4: Tab Color Legend
A5: Setup | B5: Project-level controls: project metadata, status date, reporting period, and RAG thresholds. | D5: Color | E5: Category | F5: Sheets
A6: Task Plan | B6: Integrated WBS/task control table linking baseline dates, BAC, progress, AC, EV, variances, forecasts, and RAG status. | E6: Navigation / Reference | F6: Cover, Glossary
A7: EVM | B7: Weekly EVM reporting table with cumulative PV, AC, EV, SV, CV, SPI, CPI, EAC, ETC, and VAC. | E7: Method / Governance | F7: Method Roadmap, PID, PM-EVM Compliance, Review
A8: EVM Charts | B8: Baseline Gantt schedule and EVM S-curve generated from the same WBS, budget, progress, and actual-cost data. | E8: Controls / Planning | F8: Setup, Task Plan, Task Capture, Resource Grid
A9: EVM Dashboard | B9: Management view with KPI tiles, WBS performance breakdown, trends, and RAG coloring. | E9: Management Outputs | F9: EVM Dashboard, EVM, EVM Charts
A10: PM-EVM Compliance | B10: Checklist mapping the workbook to the attached PM-EVM guideline. | E10: Dimension Data | F10: Dim_Project, Dim_WBS, Dim_Resource, Dim_Calendar
A11: Dim_* / Fact_* | B11: Star-schema source data used by the live formulas and charts. | E11: Fact Data | F11: Fact_Baseline_PV, Fact_Actual_Costs, Fact_Physical_Progress
A12: Glossary | B12: Definitions for the EVM, WBS, Gantt, schedule, cost, RAG, and data-model terms used in the workbook.
A13: Method Roadmap | B13: 12-step project management method mapped to workbook sheets and current project controls. | D13: Input / Control / Output Classification
A14: PID | B14: Project Initiation Document template with business case, scope, controls, risk and financial sections. | D14: Class | E14: Meaning | F14: Sheets
A15: Task Capture | B15: Task-list brainstorming sheet based on the attached list-the-tasks method, linked to current WBS. | D15: Input | E15: Source data or user-entered templates that feed calculations. | F15: Dim_Project, Dim_WBS, Dim_Resource, Dim_Calendar, Fact_Baseline_PV, Fact_Actual_Costs, Fact_Physical_Progress, PID, Task Capture, Review
A16: Resource Grid | B16: Weekly hours/cost resource allocation grid adapted from the attached Gantt template. | D16: Control | E16: Assumptions, governance, validation, methods, and planning logic that manage how inputs are interpreted. | F16: Setup, Method Roadmap, PM-EVM Compliance, Task Plan, Resource Grid
A17: Review | B17: GOOD / BAD / BETTER review template and action log. | D17: Output | E17: Management-facing reports, charts, dashboards, and reference views produced from inputs and controls. | F17: Cover, Glossary, EVM Dashboard, EVM, EVM Charts
A18: Garden Gantt Model | B18: Attached garden-office Gantt template implemented with current project weekly hours and cost data.
A19: PERT Diagram | B19: Visio-style PERT network diagram reflecting the current WBS, schedule, progress and RAG status. | D19: Sheet | E19: Class | F19: Reason
A20: Red Actions | B20: Recommended recovery actions for all current red RAG WBS items and control risks. | D20: Cover | E20: Output | F20: Workbook navigation and summary.
A21: Pivot Summary | B21: High-level PivotTables and descriptive statistics for project cost, schedule, EVM, and RAG performance. | D21: Glossary | E21: Output
D22: Review | E22: Input
D23: Setup | E23: Control
D24: PID | E24: Input
D25: Method Roadmap | E25: Control
D26: PM-EVM Compliance | E26: Control
D27: Task Plan | E27: Control
D28: Task Capture | E28: Input
D29: EVM Dashboard | E29: Output
D30: Resource Grid | E30: Control
D31: Dim_Project | E31: Input
D32: Dim_WBS | E32: Input
D33: Dim_Resource | E33: Input
... D39: EVM Charts | E39: Output

Sheet Slicer Controls
A1: Workbook Slicer Controls
A2: Use this panel to filter the source Excel Tables directly. Slicers are grouped by reporting outputs, source inputs, and governance/control tables.
A4: MANAGEMENT OUTPUTS
A30: SOURCE INPUTS
A56: GOVERNANCE / CONTROL
A105: Slicer name | B105: Source area | C105: Field | D105: Caption
A106: slc_Dashboard_Status | B106: Dashboard | C106: Status | D106: Dashboard: Status
A107: slc_Dashboard_Type | B107: Dashboard | C107: Type | D107: Dashboard: Type
A108: slc_TaskPlan_Status | B108: Task Plan | C108: Status | D108: Task Plan: Status
A109: slc_TaskPlan_Type | B109: Task Plan | C109: Type | D109: Task Plan: Type
A110: slc_TaskPlan_WBSID | B110: Task Plan | C110: WBS ID | D110: Task Plan: WBS ID
A111: slc_EVM_Status | B111: EVM | C111: Status | D111: EVM: Status
A112: slc_EVM_Week | B112: EVM | C112: Week | D112: EVM: Week
A113: slc_PERT_RAG | B113: PERT | C113: RAG | D113: PERT: RAG
A114: slc_Resource_Measure | B114: Resource Grid | C114: Measure | D114: Resource Grid: Measure
A115: slc_Resource_RAG | B115: Resource Grid | C115: RAG | D115: Resource Grid: RAG
A116: slc_Calendar_Month | B116: Calendar | C116: Month | D116: Calendar: Month
... A133: slc_Method_Owner | B133: Method Roadmap | C133: Owner | D133: Method Roadmap: Owner

Sheet Glossary
A1: Project Control Glossary
A2: Definitions for the EVM, WBS, Gantt, schedule, cost, and RAG terms used across this workbook.
A4: Category | B4: Term | C4: Abbrev. | D4: Definition | E4: Workbook reference
A5: Project setup | B5: Project Start | D5: Approved start date for the project control baseline. | E5: Setup!B7 / Dim_Project!C2
A6: Project setup | B6: Project End | D6: Approved planned end date for the project. | E6: Setup!B8 / Dim_Project!D2
A7: Project setup | B7: Status Date | D7: Cut-off date for reported progress, actual costs, and EVM metrics. | E7: Setup!B9 / EVM Dashboard!B4
A8: Scope / WBS | B8: Work Breakdown Structure | C8: WBS | D8: Hierarchical breakdown of project scope into controllable work packages or activities. | E8: Dim_WBS / Task Plan
A9: Scope / WBS | B9: WBS ID | D9: Unique identifier used to connect WBS activities to baseline PV, actual costs, and progress facts. | E9: Dim_WBS!A:A
A10: Scope / WBS | B10: Activity / Task | D10: A controllable unit of project work with budget, schedule, progress, and cost tracking. | E10: Task Plan!C:C
A11: Schedule | B11: Baseline Start | D11: Planned start date for a WBS activity from the approved baseline. | E11: Task Plan!E:E
A12: Schedule | B12: Baseline Finish | D12: Planned finish date for a WBS activity from the approved baseline. | E12: Task Plan!F:F
A13: Schedule | B13: Duration Days | D13: Calendar-day span between baseline start and finish dates. | E13: Task Plan!G:G
A14: Schedule | B14: Gantt Chart | D14: Timeline chart showing planned activity timing and duration by WBS activity. | E14: EVM Charts!Gantt Schedule
A15: Cost / EVM | B15: Budget at Completion | C15: BAC | D15: Approved total budget for the project or WBS activity. | E15: Setup!B11 / Task Plan!H:H
A16: Cost / EVM | B16: Planned Value | C16: PV | D16: Budgeted value of work planned to be complete by a given date. | E16: Task Plan!I:I / EVM!C:C
A17: Cost / EVM | B17: Actual Cost | C17: AC | D17: Actual cost incurred by a given date. | E17: Task Plan!J:J / EVM!D:D
A18: Cost / EVM | B18: Physical Progress | C18: Progress % | D18: Latest reported percent complete for each WBS activity as of the status date. | E18: Task Plan!K:K
A19: Cost / EVM | B19: Earned Value | C19: EV | D19: Budgeted value of the work actually completed; calculated as BAC × progress. | E19: Task Plan!L:L / EVM!E:E
A20: Variance | B20: Schedule Variance | C20: SV | D20: EV minus PV; negative means less work completed than planned. | E20: Task Plan!M:M / EVM!F:F
A21: Variance | B21: Cost Variance | C21: CV | D21: EV minus AC; negative means cost overrun for completed work. | E21: Task Plan!N:N / EVM!G:G
A22: Performance index | B22: Schedule Performance Index | C22: SPI | D22: EV divided by PV; below 1.0 indicates unfavorable schedule efficiency. | E22: Task Plan!O:O / EVM!H:H
A23: Performance index | B23: Cost Performance Index | C23: CPI | D23: EV divided by AC; below 1.0 indicates unfavorable cost efficiency. | E23: Task Plan!P:P / EVM!I:I
A24: Forecast | B24: Estimate at Completion | C24: EAC | D24: Forecast final project or WBS cost, typically BAC divided by CPI. | E24: Task Plan!Q:Q / EVM!K:K
A25: Forecast | B25: Estimate to Complete | C25: ETC | D25: Forecast remaining cost to complete the work; EAC minus AC. | E25: Task Plan!R:R / EVM!L:L
A26: Forecast | B26: Variance at Completion | C26: VAC | D26: Expected budget variance at completion; BAC minus EAC. | E26: Task Plan!S:S / EVM!M:M
A27: Chart | B27: EVM S-Curve | D27: Line chart comparing cumulative PV, EV, and AC over time. | E27: EVM Charts!EVM S-Curve
A28: RAG | B28: Green | D28: Good condition: on/above plan, favorable variance, or acceptable performance threshold. | E28: Setup!A18:D18
A29: RAG | B29: Amber | D29: Watch condition: close to threshold or mid-progress; monitor closely. | E29: Setup!A19:D19
A30: RAG | B30: Red | D30: Action condition: negative variance, low progress, CPI/SPI below threshold, or overrun. | E30: Setup!A20:D20
A31: Reporting | B31: Dashboard | D31: Management summary view showing KPIs, WBS performance, trend data, and RAG status. | E31: EVM Dashboard!A1:P47
A32: Reporting | B32: Tie-out | D32: Validation that dashboard KPIs match the detailed EVM reporting table at the status date. | E32: EVM!H19:M25
A33: Data model | B33: Dimension Table | C33: Dim | D33: Reference table describing projects, WBS, resources, or calendar dates. | E33: Dim_Project / Dim_WBS / Dim_Resource / Dim_Calendar
A34: Data model | B34: Fact Table | C34: Fact | D34: Transaction or event table containing planned values, actual costs, or progress observations. | E34: Fact_Baseline_PV / Fact_Actual_Costs / Fact_Physical_Progress
A36: Workbook classification | B36: Input | D36: Source data or user-entered content that feeds project calculations and reports. | E36: Cover!D13:H39
A37: Workbook classification | B37: Control | D37: Assumptions, thresholds, validation, governance, and planning logic used to interpret inputs. | E37: Cover!D13:H39
A38: Workbook classification | B38: Output | D38: Reports, charts, dashboards, and references produced from the input data and control logic. | E38: Cover!D13:H39

Sheet Review
A1: Project Review & Lessons
A2: Review template from attachment: GOOD / BAD / BETTER plus action log for plan adjustments and lessons learned.
A4: Project Description | B4: =Control_Project_Name -> Shipyard Assembly Beta
A5: Project Period | B5: =TEXT(Control_Project_Start,"yyyy-mm-dd")&" to "&TEXT(Control_Project_End,"yyyy-mm-dd") -> 2026-09-01 to 2026-10-31
A6: Status Date | B6: =Control_Status_Date -> 2026-06-30 00:00:00
A7: Review Owner | B7: Frank Ellingsen
A8: Review Date | B8: =TODAY() -> 46238
A10: GOOD — what went well that others should repeat?
A15: BAD — what mistakes were made or unexpected issues occurred?
A20: BETTER / ACTION LOG | B20: Owner | C20: Due date | D20: Decision required? | E20: RAG | F20: Linked workbook evidence
A21: ACT-01 | B21: 2026-09-10 | C21: Verify steel delivery delay impact | D21: Alex Smith | E21: High | F21: Open
A22: Review cost efficiency and current EAC forecast | B22: Project Controls | D22: Yes | E22: Red | F22: EVM Dashboard!G10 / Task Plan!Q17
A23: Confirm mitigation for red WBS activities in Gantt | B23: Project Manager | D23: Yes | E23: Red | F23: EVM Charts!Gantt Schedule
A24: Check future material/subcontractor dependencies | B24: Planner | D24: No | E24: Amber | F24: Task Plan / Resource Grid
A25: Capture lessons from completed WBS items | B25: Project Team | D25: No | E25: Amber | F25: Task Capture / Review
A30: Review source | B30: 13.1.2 Review Template.pdf

Sheet PID
A1: Project Initiation Document (PID)
A2: PID template from the attached method, prefilled with current workbook metadata where available. Fill yellow cells during project definition.
A4: Project header
A5: Project Name | B5: =Control_Project_Name -> Shipyard Assembly Beta
A6: Project Number | B6: =Control_Project_ID -> PRJ999
A7: Project Risk Level | B7: H/M/L
A8: Prepared by | B8: Frank Ellingsen
A9: Date | B9: =TODAY() -> 46238
A10: Persons consulted
A11: Key Driver | B11: Cost / Quality / Time
A13: 1. Business Case
A14: Why this project; why now; options considered; what if we do not do it; benefits; payback period.
A18: 2.1 In Scope / Included
A19: Work and deliverables included in the project.
A23: 2.2 Out of Scope / Excluded
A24: Work explicitly excluded from the project.
A28: 2.3 Dependencies
A29: How the project impacts or is impacted by other projects or programmes.
A33: 2.4 Constraints
A34: Deadlines, budget limits, resource limitations or other delivery constraints.
A38: 2.5 Assumptions
A39: Assumptions currently being used for planning.
... A49: How progress will be reported, frequency, method and responsibility.
A53: Frequency / timing | B53: How control is reported | C53: Responsibility | D53: Next report date | E53: Status
A54: Project Controller | B54: Cost and Schedule control Lead | C54: Frank Ellingsen | D54: frank@company.com | E54: Approved
A55: Stage end | B55: PID / Review pack | C55: Project Manager | E55: Planned
A56: Monthly | B56: Board summary | C56: Project Manager | E56: Planned
A58: 5. Risk Control
A59: Project risks and containment measures.
A63: Project Risk | B63: Containment Measures | C63: Owner | D63: Due Date | E63: RAG
A64: RSK-01 | B64: Steel Price Fluctuation | C64: Medium | D64: High | E64: Fixed-price supply contracts
A65: Cost overrun | B65: Monitor CPI/CV/EAC and review WBS cost drivers. | C65: Project Controls | E65: Red
A66: Resource availability | B66: Use weekly Resource Grid to identify conflicts. | C66: Resource Manager | E66: Amber
A67: Scope creep | B67: Confirm in/out of scope and change-control route in PID. | C67: Project Manager | E67: Amber
A68: Quality issue | B68: Define acceptance criteria and quality checks by task. | C68: Project Manager | E68: Amber
A69: Supplier delay | B69: Track procurement/material activities and delivery milestones. | C69: Project Manager | E69: Amber
A72: 6. Financial Implications
A73: Quarterly/annual financial profile adapted from the PID template; Year 1 is linked to the current baseline planned value.
A74: Financial Implications | B74: Q1 | C74: Q2 | D74: Q3 | E74: Q4 | F74: Total
A75: Labor | B75: 35000 | C75: 33500 | D75: 1500 | E75: On track | F75: Green
...

Sheet Method Roadmap
A1: 12-Step Project Management Method Roadmap
A2: Course method embedded into the workbook: define, list, sequence, estimate, check, Gantt, resource, risk, monitor progress/cost, adjust, and review.
A4: Step | B4: Method step | C4: Purpose | D4: Workbook implementation | E4: Primary sheet / range | F4: Owner | G4: Status | H4: Source
A5: 1 | B5: Define the project | C5: Create the project definition and controls. | D5: PID template added with live project metadata. | E5: PID!A1:H50 | F5: Project Manager | G5: Active | H5: 1.2 12 Step Process / 2.1.2 PID template
A6: 2 | B6: List the tasks | C6: Capture all tasks without initially worrying about order, cost, or time. | D6: Task Capture sheet added; WBS imported from current Dim_WBS and grouped by type. | E6: Task Capture!A4:J18 | F6: Project Team | G6: Active | H6: 3.1.5 List the Tasks / 4.1 List of Tasks
A7: 3 | B7: Establish task order | C7: Convert brainstormed tasks into planned sequencing. | D7: Task Plan and Gantt use WBS order and baseline dates. | E7: Task Plan!A4:T17 | F7: Planner | G7: Active | H7: 1.2 12 Step Process
A8: 4 | B8: Estimate time | C8: Estimate duration by task. | D8: Baseline start, finish, and duration calculated per WBS. | E8: Task Plan!E5:G17 | F8: Planner | G8: Active | H8: 1.2 12 Step Process
A9: 5 | B9: Margin check & reality check | C9: Check whether dates, budget, and resource assumptions are feasible. | D9: Status tie-out, EVM checks, and RAG indicators added. | E9: EVM!H19:M25 | F9: Project Controls | G9: Active | H9: 1.2 12 Step Process
A10: 6 | B10: Gantt Chart | C10: Show planned timing and status. | D10: Gantt chart with RAG bars and status-date marker exists. | E10: EVM Charts!Gantt Schedule | F10: Project Controls | G10: Active | H10: 8.1.2 Gantt templates
A11: 7 | B11: Resource allocation | C11: Map tasks to people/resources and weekly loading. | D11: Resource Grid added with weekly hours and costs by WBS. | E11: Resource Grid!A4:Z35 | F11: Resource Manager | G11: Active | H11: 8.1.2 Gantt template from garden office
A12: 8 | B12: Predicting & reducing risk | C12: Identify project risks and containment measures. | D12: PID risk-control register added. | E12: PID!A63:E70 | F12: Project Manager | G12: Template ready | H12: 2.1.2 PID template
A13: 9 | B13: Monitoring progress | C13: Track completion against plan. | D13: Progress is linked from Fact_Physical_Progress to Task Plan and dashboard. | E13: Task Plan!K5:K17 | F13: Project Controls | G13: Active | H13: 1.2 12 Step Process
A14: 10 | B14: Monitoring cost | C14: Track actual cost and forecast. | D14: EVM reporting monitors AC, CV, CPI, EAC, ETC, VAC. | E14: EVM!A4:N16 | F14: Project Controls | G14: Active | H14: 1.2 12 Step Process
A15: 11 | B15: Adjusting the plan | C15: Use EVM and RAG exceptions to trigger decisions. | D15: Decision/action log added to Review. | E15: Review!A20:F28 | F15: Project Board | G15: Template ready | H15: 1.2 12 Step Process
A16: 12 | B16: Review & lessons | C16: Capture good, bad, better after delivery. | D16: Review sheet added with GOOD / BAD / BETTER structure. | E16: Review!A4:F17 | F16: Project Team | G16: Template ready | H16: 13.1.2 Review Template

Sheet PM-EVM Compliance
A1: PM-EVM Compliance Checklist
A2: Workbook compliance map against the attached PM-EVM guideline: WBS, Gantt, EVM, dashboard, live formulas, and exception-focused reporting.
A4: Guideline requirement | B4: Workbook implementation | C4: Location | D4: Status | E4: Evidence
A5: Setup controls: project metadata, status date, reporting period, rates/thresholds | B5: Added setup control sheet with live project metadata and thresholds | C5: Setup!A4:D20 | D5: Compliant | E5: PM-EVM.md lines 117-126
A6: Task Plan as integrated WBS/task control view | B6: Added live task table combining WBS, dates, BAC, PV, AC, progress, EV, variances, forecasts and RAG | C6: Task Plan!A4:T17 | D6: Compliant | E6: PM-EVM.md lines 120-125
A7: Gantt display tied to WBS baseline dates | B7: Existing EVM Charts Gantt uses WBS activities, baseline start/finish and duration | C7: EVM Charts!Gantt Schedule | D7: Compliant | E7: PM-EVM.md lines 122-125
A8: EVM by reporting period with PV, EV, AC, SV, CV, SPI, CPI, BAC, EAC, ETC, VAC | B8: Added EVM reporting table with weekly live formulas | C8: EVM!A4:N16 | D8: Compliant | E8: PM-EVM.md lines 123-124
A9: S-curve shows cumulative PV, EV, and AC over time | B9: Existing EVM S-curve chart is sourced from weekly cumulative helper table | C9: EVM Charts!EVM S-Curve | D9: Compliant | E9: PM-EVM.md lines 50-54
A10: Dashboard summarizes management KPIs and top WBS exceptions | B10: Existing dashboard has KPI tiles, WBS table, RAG, variance/status fields | C10: EVM Dashboard!A1:P47 | D10: Compliant | E10: PM-EVM.md lines 781-785
A11: Exception-focused reporting with RAG / traffic-light indicators | B11: RAG rules applied across performance indices, progress, variances, and status cells | C11: EVM Dashboard, Task Plan, EVM | D11: Compliant | E11: PM-EVM.md lines 781-785
A12: Consistent WBS codes, budgets, dates, and actuals across views | B12: Task Plan, EVM, Gantt and dashboard all reference Dim_WBS and fact tables | C12: Dim_WBS / Fact_* | D12: Compliant | E12: PM-EVM.md lines 270-274
A13: Validate formulas and totals | B13: Added formula validation and status-date tie-out to dashboard KPIs | C13: EVM!H19:M25 | D13: Compliant | E13: PM-EVM.md lines 783-785

Sheet Setup
A1: Setup Controls
A2: Single place to review project metadata, status date, reporting period, and RAG thresholds used by the control workbook.
A4: Control | B4: Value
A5: Project ID | B5: P101
A6: Project Name | B6: Office Fit-Out
A7: Project Start | B7: 2026-05-04 00:00:00
A8: Project End | B8: 2026-07-26 00:00:00
A9: Status Date | B9: 2026-06-30 00:00:00
A10: Reporting Period | B10: Weekly
A11: Budget at Completion (BAC) | B11: 268650
A12: CPI/SPI Red Threshold | B12: 0.95
A13: CPI/SPI Green Threshold | B13: 1
A14: Progress Amber Threshold | B14: 0.5
A15: Progress Green Threshold | B15: 0.8
A17: RAG | B17: Metric | C17: Rule | D17: Interpretation
A18: Green | B18: CPI/SPI | C18: >= 1.00 | D18: On or above plan
A19: Amber | B19: CPI/SPI | C19: 0.95 to < 1.00 | D19: Near threshold / watch
A20: Red | B20: CPI/SPI | C20: < 0.95 | D20: Action required

Sheet Task Plan
A1: Task Plan
A2: Integrated WBS control table: one live task-level view for scope, schedule, budget, progress, actuals, forecasts, and RAG status.
A4: WBS ID | B4: WBS Code | C4: Task / Activity | D4: Type | E4: Baseline Start | F4: Baseline Finish | G4: Duration Days | H4: BAC (NOK) | I4: PV @ Status | J4: AC @ Status | K4: Progress % | L4: EV @ Status | M4: SV | N4: CV | O4: SPI | P4: CPI | Q4: EAC | R4: ETC | S4: VAC | T4: Status
A5: WBS001 | B5: Design Phase | C5: 2026-09-01 | D5: 2026-09-14 | E5: 14 | F5: Predecessors | G5: RES101 | H5: Complete | I5: =SUMIFS(Fact_Baseline_PV!$C:$C,Fact_Baseline_PV!$B:$B,A5,Fact_Baseline_PV!$A:$A,"<="&Setup!$B$9) -> 0 | J5: =SUMIFS(Fact_Actual_Costs!$D:$D,Fact_Actual_Costs!$B:$B,A5,Fact_Actual_Costs!$A:$A,"<="&Setup!$B$9) -> 0 | K5: {=IFERROR(LOOKUP(2,1/(Fact_Physical_Progress!$B$2:$B$35=A5)/(Fact_Physical_Progress!$A$2:$A$35<=Setup!$B$9),Fact_Physical_Progress!$C$2:$C$35),0)} -> 0 | L5: =H5*K5 -> #VALUE! | M5: =L5-I5 -> #VALUE! | N5: =L5-J5 -> #VALUE! | O5: =IFERROR(L5/I5,1) -> 1 | P5: =IFERROR(L5/J5,1) -> 1 | Q5: =IF(P5>0,H5/P5,H5) -> #VALUE! | R5: =Q5-J5 -> #VALUE! | S5: =H5-Q5 -> #VALUE! | T5: =IF(OR(N5<0,P5<Setup!$B$12,O5<Setup!$B$12),"Red",IF(OR(P5<Setup!$B$13,O5<Setup!$B$13),"Amber","Green")) -> #VALUE!
A6: WBS002 | B6: Structural Steel Work | C6: 2026-09-15 | D6: 2026-09-28 | E6: 14 | F6: WBS001 | G6: RES101 | H6: In Progress | I6: =SUMIFS(Fact_Baseline_PV!$C:$C,Fact_Baseline_PV!$B:$B,A6,Fact_Baseline_PV!$A:$A,"<="&Setup!$B$9) -> 0 | J6: =SUMIFS(Fact_Actual_Costs!$D:$D,Fact_Actual_Costs!$B:$B,A6,Fact_Actual_Costs!$A:$A,"<="&Setup!$B$9) -> 0 | K6: {=IFERROR(LOOKUP(2,1/(Fact_Physical_Progress!$B$2:$B$35=A6)/(Fact_Physical_Progress!$A$2:$A$35<=Setup!$B$9),Fact_Physical_Progress!$C$2:$C$35),0)} -> 0 | L6: =H6*K6 -> #VALUE! | M6: =L6-I6 -> #VALUE! | N6: =L6-J6 -> #VALUE! | O6: =IFERROR(L6/I6,1) -> 1 | P6: =IFERROR(L6/J6,1) -> 1 | Q6: =IF(P6>0,H6/P6,H6) -> #VALUE! | R6: =Q6-J6 -> #VALUE! | S6: =H6-Q6 -> #VALUE! | T6: =IF(OR(N6<0,P6<Setup!$B$12,O6<Setup!$B$12),"Red",IF(OR(P6<Setup!$B$13,O6<Setup!$B$13),"Amber","Green")) -> #VALUE!
A7: WBS003 | B7: Electrical & Outfitting | C7: 2026-09-29 | D7: 2026-10-12 | E7: 14 | F7: WBS002 | G7: RES102 | H7: Not Started | I7: =SUMIFS(Fact_Baseline_PV!$C:$C,Fact_Baseline_PV!$B:$B,A7,Fact_Baseline_PV!$A:$A,"<="&Setup!$B$9) -> 0 | J7: =SUMIFS(Fact_Actual_Costs!$D:$D,Fact_Actual_Costs!$B:$B,A7,Fact_Actual_Costs!$A:$A,"<="&Setup!$B$9) -> 0 | K7: {=IFERROR(LOOKUP(2,1/(Fact_Physical_Progress!$B$2:$B$35=A7)/(Fact_Physical_Progress!$A$2:$A$35<=Setup!$B$9),Fact_Physical_Progress!$C$2:$C$35),0)} -> 0 | L7: =H7*K7 -> #VALUE! | M7: =L7-I7 -> #VALUE! | N7: =L7-J7 -> #VALUE! | O7: =IFERROR(L7/I7,1) -> 1 | P7: =IFERROR(L7/J7,1) -> 1 | Q7: =IF(P7>0,H7/P7,H7) -> #VALUE! | R7: =Q7-J7 -> #VALUE! | S7: =H7-Q7 -> #VALUE! | T7: =IF(OR(N7<0,P7<Setup!$B$12,O7<Setup!$B$12),"Red",IF(OR(P7<Setup!$B$13,O7<Setup!$B$13),"Amber","Green")) -> #VALUE!
A8: =Dim_WBS!A5 -> WBS-04 | B8: =Dim_WBS!B5 -> 4 | C8: =Dim_WBS!C5 -> Procurement - Materials | D8: =Dim_WBS!D5 -> Material | E8: =_xlfn.MINIFS(Fact_Baseline_PV!$A:$A,Fact_Baseline_PV!$B:$B,A8) -> 46153 | F8: =_xlfn.MAXIFS(Fact_Baseline_PV!$A:$A,Fact_Baseline_PV!$B:$B,A8)+6 -> 46180 | G8: =F8-E8+1 -> 28 | H8: =Dim_WBS!E5 -> 42000 | I8: =SUMIFS(Fact_Baseline_PV!$C:$C,Fact_Baseline_PV!$B:$B,A8,Fact_Baseline_PV!$A:$A,"<="&Setup!$B$9) -> 42000 | J8: =SUMIFS(Fact_Actual_Costs!$D:$D,Fact_Actual_Costs!$B:$B,A8,Fact_Actual_Costs!$A:$A,"<="&Setup!$B$9) -> 41300 | K8: {=IFERROR(LOOKUP(2,1/(Fact_Physical_Progress!$B$2:$B$35=A8)/(Fact_Physical_Progress!$A$2:$A$35<=Setup!$B$9),Fact_Physical_Progress!$C$2:$C$35),0)} -> 1 | L8: =H8*K8 -> 42000 | M8: =L8-I8 -> 0 | N8: =L8-J8 -> 700 | O8: =IFERROR(L8/I8,1) -> 1 | P8: =IFERROR(L8/J8,1) -> 1.0169492 | Q8: =IF(P8>0,H8/P8,H8) -> 41300 | R8: =Q8-J8 -> 0 | S8: =H8-Q8 -> 700 | T8: =IF(OR(N8<0,P8<Setup!$B$12,O8<Setup!$B$12),"Red",IF(OR(P8<Setup!$B$13,O8<Setup!$B$13),"Amber","Green")) -> Green
A9: =Dim_WBS!A6 -> WBS-05 | B9: =Dim_WBS!B6 -> 5 | C9: =Dim_WBS!C6 -> Demolition & Prep | D9: =Dim_WBS!D6 -> Labor | E9: =_xlfn.MINIFS(Fact_Baseline_PV!$A:$A,Fact_Baseline_PV!$B:$B,A9) -> 46153 | F9: =_xlfn.MAXIFS(Fact_Baseline_PV!$A:$A,Fact_Baseline_PV!$B:$B,A9)+6 -> 46173 | G9: =F9-E9+1 -> 21 | H9: =Dim_WBS!E6 -> 13200 | I9: =SUMIFS(Fact_Baseline_PV!$C:$C,Fact_Baseline_PV!$B:$B,A9,Fact_Baseline_PV!$A:$A,"<="&Setup!$B$9) -> 13200 | J9: =SUMIFS(Fact_Actual_Costs!$D:$D,Fact_Actual_Costs!$B:$B,A9,Fact_Actual_Costs!$A:$A,"<="&Setup!$B$9) -> 13408.16 | K9: {=IFERROR(LOOKUP(2,1/(Fact_Physical_Progress!$B$2:$B$35=A9)/(Fact_Physical_Progress!$A$2:$A$35<=Setup!$B$9),Fact_Physical_Progress!$C$2:$C$35),0)} -> 1 | L9: =H9*K9 -> 13200 | M9: =L9-I9 -> 0 | N9: =L9-J9 -> -208.16 | O9: =IFERROR(L9/I9,1) -> 1 | P9: =IFERROR(L9/J9,1) -> 0.98447513 | Q9: =IF(P9>0,H9/P9,H9) -> 13408.16 | R9: =Q9-J9 -> 0 | S9: =H9-Q9 -> -208.16 | T9: =IF(OR(N9<0,P9<Setup!$B$12,O9<Setup!$B$12),"Red",IF(OR(P9<Setup!$B$13,O9<Setup!$B$13),"Amber","Green")) -> Red
A10: =Dim_WBS!A7 -> WBS-06 | B10: =Dim_WBS!B7 -> 6 | C10: =Dim_WBS!C7 -> Electrical Rough-In | D10: =Dim_WBS!D7 -> Labor | E10: =_xlfn.MINIFS(Fact_Baseline_PV!$A:$A,Fact_Baseline_PV!$B:$B,A10) -> 46167 | F10: =_xlfn.MAXIFS(Fact_Baseline_PV!$A:$A,Fact_Baseline_PV!$B:$B,A10)+6 -> 46187 | G10: =F10-E10+1 -> 21 | H10: =Dim_WBS!E7 -> 26000 | I10: =SUMIFS(Fact_Baseline_PV!$C:$C,Fact_Baseline_PV!$B:$B,A10,Fact_Baseline_PV!$A:$A,"<="&Setup!$B$9) -> 26000 | J10: =SUMIFS(Fact_Actual_Costs!$D:$D,Fact_Actual_Costs!$B:$B,A10,Fact_Actual_Costs!$A:$A,"<="&Setup!$B$9) -> 26206.24 | K10: {=IFERROR(LOOKUP(2,1/(Fact_Physical_Progress!$B$2:$B$35=A10)/(Fact_Physical_Progress!$A$2:$A$35<=Setup!$B$9),Fact_Physical_Progress!$C$2:$C$35),0)} -> 0.7 | L10: =H10*K10 -> 18200 | M10: =L10-I10 -> -7800 | N10: =L10-J10 -> -8006.24 | O10: =IFERROR(L10/I10,1) -> 0.7 | P10: =IFERROR(L10/J10,1) -> 0.69449108 | Q10: =IF(P10>0,H10/P10,H10) -> 37437.486 | R10: =Q10-J10 -> 11231.246 | S10: =H10-Q10 -> -11437.486 | T10: =IF(OR(N10<0,P10<Setup!$B$12,O10<Setup!$B$12),"Red",IF(OR(P10<Setup!$B$13,O10<Setup!$B$13),"Amber","Green")) -> Red
A11: =Dim_WBS!A8 -> WBS-07 | B11: =Dim_WBS!B8 -> 7 | C11: =Dim_WBS!C8 -> HVAC Installation | D11: =Dim_WBS!D8 -> Subcontractor | E11: =_xlfn.MINIFS(Fact_Baseline_PV!$A:$A,Fact_Baseline_PV!$B:$B,A11) -> 46174 | F11: =_xlfn.MAXIFS(Fact_Baseline_PV!$A:$A,Fact_Baseline_PV!$B:$B,A11)+6 -> 46201 | G11: =F11-E11+1 -> 28 | H11: =Dim_WBS!E8 -> 36000 | I11: =SUMIFS(Fact_Baseline_PV!$C:$C,Fact_Baseline_PV!$B:$B,A11,Fact_Baseline_PV!$A:$A,"<="&Setup!$B$9) -> 36000 | J11: =SUMIFS(Fact_Actual_Costs!$D:$D,Fact_Actual_Costs!$B:$B,A11,Fact_Actual_Costs!$A:$A,"<="&Setup!$B$9) -> 17476.8 | K11: {=IFERROR(LOOKUP(2,1/(Fact_Physical_Progress!$B$2:$B$35=A11)/(Fact_Physical_Progress!$A$2:$A$35<=Setup!$B$9),Fact_Physical_Progress!$C$2:$C$35),0)} -> 0.4 | L11: =H11*K11 -> 14400 | M11: =L11-I11 -> -21600 | N11: =L11-J11 -> -3076.8 | O11: =IFERROR(L11/I11,1) -> 0.4 | P11: =IFERROR(L11/J11,1) -> 0.82394946 | Q11: =IF(P11>0,H11/P11,H11) -> 43692 | R11: =Q11-J11 -> 26215.2 | S11: =H11-Q11 -> -7692 | T11: =IF(OR(N11<0,P11<Setup!$B$12,O11<Setup!$B$12),"Red",IF(OR(P11<Setup!$B$13,O11<Setup!$B$13),"Amber","Green")) -> Red
A12: =Dim_WBS!A9 -> WBS-08 | B12: =Dim_WBS!B9 -> 8 | C12: =Dim_WBS!C9 -> Partitions & Drywall | D12: =Dim_WBS!D9 -> Subcontractor | E12: =_xlfn.MINIFS(Fact_Baseline_PV!$A:$A,Fact_Baseline_PV!$B:$B,A12) -> 46181 | F12: =_xlfn.MAXIFS(Fact_Baseline_PV!$A:$A,Fact_Baseline_PV!$B:$B,A12)+6 -> 46208 | G12: =F12-E12+1 -> 28 | H12: =Dim_WBS!E9 -> 28000 | I12: =SUMIFS(Fact_Baseline_PV!$C:$C,Fact_Baseline_PV!$B:$B,A12,Fact_Baseline_PV!$A:$A,"<="&Setup!$B$9) -> 28000 | J12: =SUMIFS(Fact_Actual_Costs!$D:$D,Fact_Actual_Costs!$B:$B,A12,Fact_Actual_Costs!$A:$A,"<="&Setup!$B$9) -> 7099.2 | K12: {=IFERROR(LOOKUP(2,1/(Fact_Physical_Progress!$B$2:$B$35=A12)/(Fact_Physical_Progress!$A$2:$A$35<=Setup!$B$9),Fact_Physical_Progress!$C$2:$C$35),0)} -> 0.248857 | L12: =H12*K12 -> 6967.996 | M12: =L12-I12 -> -21032.004 | N12: =L12-J12 -> -131.204 | O12: =IFERROR(L12/I12,1) -> 0.248857 | P12: =IFERROR(L12/J12,1) -> 0.98151848 | Q12: =IF(P12>0,H12/P12,H12) -> 28527.226 | R12: =Q12-J12 -> 21428.026 | S12: =H12-Q12 -> -527.22648 | T12: =IF(OR(N12<0,P12<Setup!$B$12,O12<Setup!$B$12),"Red",IF(OR(P12<Setup!$B$13,O12<Setup!$B$13),"Amber","Green")) -> Red
A13: =Dim_WBS!A10 -> WBS-09 | B13: =Dim_WBS!B10 -> 9 | C13: =Dim_WBS!C10 -> Flooring | D13: =Dim_WBS!D10 -> Material | E13: =_xlfn.MINIFS(Fact_Baseline_PV!$A:$A,Fact_Baseline_PV!$B:$B,A13) -> 46195 | F13: =_xlfn.MAXIFS(Fact_Baseline_PV!$A:$A,Fact_Baseline_PV!$B:$B,A13)+6 -> 46215 | G13: =F13-E13+1 -> 21 | H13: =Dim_WBS!E10 -> 35750 | I13: =SUMIFS(Fact_Baseline_PV!$C:$C,Fact_Baseline_PV!$B:$B,A13,Fact_Baseline_PV!$A:$A,"<="&Setup!$B$9) -> 23833.34 | J13: =SUMIFS(Fact_Actual_Costs!$D:$D,Fact_Actual_Costs!$B:$B,A13,Fact_Actual_Costs!$A:$A,"<="&Setup!$B$9) -> 0 | K13: {=IFERROR(LOOKUP(2,1/(Fact_Physical_Progress!$B$2:$B$35=A13)/(Fact_Physical_Progress!$A$2:$A$35<=Setup!$B$9),Fact_Physical_Progress!$C$2:$C$35),0)} -> 0 | L13: =H13*K13 -> 0 | M13: =L13-I13 -> -23833.34 | N13: =L13-J13 -> 0 | O13: =IFERROR(L13/I13,1) -> 0 | P13: =IFERROR(L13/J13,1) -> 1 | Q13: =IF(P13>0,H13/P13,H13) -> 35750 | R13: =Q13-J13 -> 35750 | S13: =H13-Q13 -> 0 | T13: =IF(OR(N13<0,P13<Setup!$B$12,O13<Setup!$B$12),"Red",IF(OR(P13<Setup!$B$13,O13<Setup!$B$13),"Amber","Green")) -> Red
A14: =Dim_WBS!A11 -> WBS-10 | B14: =Dim_WBS!B11 -> 10 | C14: =Dim_WBS!C11 -> Fixtures & Furniture | D14: =Dim_WBS!D11 -> Material | E14: =_xlfn.MINIFS(Fact_Baseline_PV!$A:$A,Fact_Baseline_PV!$B:$B,A14) -> 46202 | F14: =_xlfn.MAXIFS(Fact_Baseline_PV!$A:$A,Fact_Baseline_PV!$B:$B,A14)+6 -> 46222 | G14: =F14-E14+1 -> 21 | H14: =Dim_WBS!E11 -> 30000 | I14: =SUMIFS(Fact_Baseline_PV!$C:$C,Fact_Baseline_PV!$B:$B,A14,Fact_Baseline_PV!$A:$A,"<="&Setup!$B$9) -> 10000 | J14: =SUMIFS(Fact_Actual_Costs!$D:$D,Fact_Actual_Costs!$B:$B,A14,Fact_Actual_Costs!$A:$A,"<="&Setup!$B$9) -> 0 | K14: {=IFERROR(LOOKUP(2,1/(Fact_Physical_Progress!$B$2:$B$35=A14)/(Fact_Physical_Progress!$A$2:$A$35<=Setup!$B$9),Fact_Physical_Progress!$C$2:$C$35),0)} -> 0 | L14: =H14*K14 -> 0 | M14: =L14-I14 -> -10000 | N14: =L14-J14 -> 0 | O14: =IFERROR(L14/I14,1) -> 0 | P14: =IFERROR(L14/J14,1) -> 1 | Q14: =IF(P14>0,H14/P14,H14) -> 30000 | R14: =Q14-J14 -> 30000 | S14: =H14-Q14 -> 0 | T14: =IF(OR(N14<0,P14<Setup!$B$12,O14<Setup!$B$12),"Red",IF(OR(P14<Setup!$B$13,O14<Setup!$B$13),"Amber","Green")) -> Red
A15: =Dim_WBS!A12 -> WBS-11 | B15: =Dim_WBS!B12 -> 11 | C15: =Dim_WBS!C12 -> Testing / Commissioning | D15: =Dim_WBS!D12 -> Labor | E15: =_xlfn.MINIFS(Fact_Baseline_PV!$A:$A,Fact_Baseline_PV!$B:$B,A15) -> 46216 | F15: =_xlfn.MAXIFS(Fact_Baseline_PV!$A:$A,Fact_Baseline_PV!$B:$B,A15)+6 -> 46229 | G15: =F15-E15+1 -> 14 | H15: =Dim_WBS!E12 -> 8400 | I15: =SUMIFS(Fact_Baseline_PV!$C:$C,Fact_Baseline_PV!$B:$B,A15,Fact_Baseline_PV!$A:$A,"<="&Setup!$B$9) -> 0 | J15: =SUMIFS(Fact_Actual_Costs!$D:$D,Fact_Actual_Costs!$B:$B,A15,Fact_Actual_Costs!$A:$A,"<="&Setup!$B$9) -> 0 | K15: {=IFERROR(LOOKUP(2,1/(Fact_Physical_Progress!$B$2:$B$35=A15)/(Fact_Physical_Progress!$A$2:$A$35<=Setup!$B$9),Fact_Physical_Progress!$C$2:$C$35),0)} -> 0 | L15: =H15*K15 -> 0 | M15: =L15-I15 -> 0 | N15: =L15-J15 -> 0 | O15: =IFERROR(L15/I15,1) -> 1 | P15: =IFERROR(L15/J15,1) -> 1 | Q15: =IF(P15>0,H15/P15,H15) -> 8400 | R15: =Q15-J15 -> 8400 | S15: =H15-Q15 -> 0 | T15: =IF(OR(N15<0,P15<Setup!$B$12,O15<Setup!$B$12),"Red",IF(OR(P15<Setup!$B$13,O15<Setup!$B$13),"Amber","Green")) -> Green
A16: =Dim_WBS!A13 -> WBS-12 | B16: =Dim_WBS!B13 -> 12 | C16: =Dim_WBS!C13 -> Handover & Closeout | D16: =Dim_WBS!D13 -> Labor | E16: =_xlfn.MINIFS(Fact_Baseline_PV!$A:$A,Fact_Baseline_PV!$B:$B,A16) -> 46223 | F16: =_xlfn.MAXIFS(Fact_Baseline_PV!$A:$A,Fact_Baseline_PV!$B:$B,A16)+6 -> 46229 | G16: =F16-E16+1 -> 7 | H16: =Dim_WBS!E13 -> 3600 | I16: =SUMIFS(Fact_Baseline_PV!$C:$C,Fact_Baseline_PV!$B:$B,A16,Fact_Baseline_PV!$A:$A,"<="&Setup!$B$9) -> 0 | J16: =SUMIFS(Fact_Actual_Costs!$D:$D,Fact_Actual_Costs!$B:$B,A16,Fact_Actual_Costs!$A:$A,"<="&Setup!$B$9) -> 0 | K16: {=IFERROR(LOOKUP(2,1/(Fact_Physical_Progress!$B$2:$B$35=A16)/(Fact_Physical_Progress!$A$2:$A$35<=Setup!$B$9),Fact_Physical_Progress!$C$2:$C$35),0)} -> 0 | L16: =H16*K16 -> 0 | M16: =L16-I16 -> 0 | N16: =L16-J16 -> 0 | O16: =IFERROR(L16/I16,1) -> 1 | P16: =IFERROR(L16/J16,1) -> 1 | Q16: =IF(P16>0,H16/P16,H16) -> 3600 | R16: =Q16-J16 -> 3600 | S16: =H16-Q16 -> 0 | T16: =IF(OR(N16<0,P16<Setup!$B$12,O16<Setup!$B$12),"Red",IF(OR(P16<Setup!$B$13,O16<Setup!$B$13),"Amber","Green")) -> Green
A17: Total / Project Portfolio | G17: =MAX(F5:F16)-MIN(E5:E16)+1 -> 46216 | H17: =SUM(H5:H16) -> 222950 | I17: =SUM(I5:I16) -> 179033.34 | J17: =SUM(J5:J16) -> 105490.4 | K17: =SUMPRODUCT(H5:H16,K5:K16)/SUM(H5:H16) -> 0.4250639 | L17: =SUM(L5:L16) -> #VALUE! | M17: =SUM(M5:M16) -> #VALUE! | N17: =SUM(N5:N16) -> #VALUE! | O17: =IFERROR(L17/I17,1) -> 1 | P17: =IFERROR(L17/J17,1) -> 1 | Q17: =IF(P17>0,H17/P17,H17) -> 222950 | R17: =Q17-J17 -> 117459.6 | S17: =H17-Q17 -> 0 | T17: =IF(OR(N17<0,P17<Setup!$B$12,O17<Setup!$B$12),"Red",IF(OR(P17<Setup!$B$13,O17<Setup!$B$13),"Amber","Green")) -> #VALUE!

Sheet Task Capture
A1: Task Capture / List the Tasks
A2: Method: first list all tasks without worrying about order, cost, or time; then group into phases and convert into the controlled Task Plan.
A4: Phase / Area | B4: Task | C4: WBS ID | D4: Type | E4: Included? | F4: Event / Milestone? | G4: Owner | H4: Notes | I4: Source / next action | J4: Mapped to Task Plan
A5: WBS001 | B5: 2026-09-07 | C5: RES101 | D5: 22.5 | E5: 4500 | F5: 0.25 | G5: In Progress | H5: Design initial drafting | I5: Imported from current WBS | J5: =IFERROR(MATCH(C5,'Task Plan'!A:A,0),"")
A6: WBS001 | B6: 2026-09-14 | C6: RES101 | D6: 80 | E6: 16000 | F6: 1 | G6: Complete | H6: Approved by client | I6: Imported from current WBS | J6: =IFERROR(MATCH(C6,'Task Plan'!A:A,0),"")
A7: =Dim_WBS!D4 -> Activity | B7: =Dim_WBS!C4 -> Electrical & Outfitting | C7: =Dim_WBS!A4 -> WBS003 | D7: =Dim_WBS!D4 -> Activity | E7: Yes | I7: Imported from current WBS | J7: =IFERROR(MATCH(C7,'Task Plan'!A:A,0),"") -> 7
A8: =Dim_WBS!D5 -> Material | B8: =Dim_WBS!C5 -> Procurement - Materials | C8: =Dim_WBS!A5 -> WBS-04 | D8: =Dim_WBS!D5 -> Material | E8: Yes | I8: Imported from current WBS | J8: =IFERROR(MATCH(C8,'Task Plan'!A:A,0),"") -> 8
A9: =Dim_WBS!D6 -> Labor | B9: =Dim_WBS!C6 -> Demolition & Prep | C9: =Dim_WBS!A6 -> WBS-05 | D9: =Dim_WBS!D6 -> Labor | E9: Yes | I9: Imported from current WBS | J9: =IFERROR(MATCH(C9,'Task Plan'!A:A,0),"") -> 9
A10: =Dim_WBS!D7 -> Labor | B10: =Dim_WBS!C7 -> Electrical Rough-In | C10: =Dim_WBS!A7 -> WBS-06 | D10: =Dim_WBS!D7 -> Labor | E10: Yes | I10: Imported from current WBS | J10: =IFERROR(MATCH(C10,'Task Plan'!A:A,0),"") -> 10
A11: =Dim_WBS!D8 -> Subcontractor | B11: =Dim_WBS!C8 -> HVAC Installation | C11: =Dim_WBS!A8 -> WBS-07 | D11: =Dim_WBS!D8 -> Subcontractor | E11: Yes | I11: Imported from current WBS | J11: =IFERROR(MATCH(C11,'Task Plan'!A:A,0),"") -> 11
A12: =Dim_WBS!D9 -> Subcontractor | B12: =Dim_WBS!C9 -> Partitions & Drywall | C12: =Dim_WBS!A9 -> WBS-08 | D12: =Dim_WBS!D9 -> Subcontractor | E12: Yes | I12: Imported from current WBS | J12: =IFERROR(MATCH(C12,'Task Plan'!A:A,0),"") -> 12
A13: =Dim_WBS!D10 -> Material | B13: =Dim_WBS!C10 -> Flooring | C13: =Dim_WBS!A10 -> WBS-09 | D13: =Dim_WBS!D10 -> Material | E13: Yes | I13: Imported from current WBS | J13: =IFERROR(MATCH(C13,'Task Plan'!A:A,0),"") -> 13
A14: =Dim_WBS!D11 -> Material | B14: =Dim_WBS!C11 -> Fixtures & Furniture | C14: =Dim_WBS!A11 -> WBS-10 | D14: =Dim_WBS!D11 -> Material | E14: Yes | I14: Imported from current WBS | J14: =IFERROR(MATCH(C14,'Task Plan'!A:A,0),"") -> 14
A15: =Dim_WBS!D12 -> Labor | B15: =Dim_WBS!C12 -> Testing / Commissioning | C15: =Dim_WBS!A12 -> WBS-11 | D15: =Dim_WBS!D12 -> Labor | E15: Yes | I15: Imported from current WBS | J15: =IFERROR(MATCH(C15,'Task Plan'!A:A,0),"") -> 15
A16: =Dim_WBS!D13 -> Labor | B16: =Dim_WBS!C13 -> Handover & Closeout | C16: =Dim_WBS!A13 -> WBS-12 | D16: =Dim_WBS!D13 -> Labor | E16: Yes | I16: Imported from current WBS | J16: =IFERROR(MATCH(C16,'Task Plan'!A:A,0),"") -> 16
A17: Brainstorm / new | I17: Add new tasks here before sequencing
A18: Brainstorm / new | I18: Add new tasks here before sequencing
A21: Example task-list method from attachment | B21: Garden office example grouped tasks: clear the space, foundations, buy the shed, install shed, legal. Use this area to add unstructured tasks before converting them to WBS.

Sheet EVM Dashboard
A1: OFFICE FIT-OUT - PROJECT CONTROLLING DASHBOARD
A2: EVM Performance Status | Tufte-Compliant Design | Data-Ink Maximized
A4: Status Date: | B4: =Control_Status_Date -> 2026-06-30 00:00:00 | D4: Status Week: | E4: =MATCH(B4,EVM!B5:B16,1) -> 8 | G4: Sector: | H4: =Control_Sector -> Maritime | N4: RAG Legend | O4: Rule | P4: Meaning
N5: Green | O5: Good | P5: On/above plan or low exposure
A6: BUDGET AT COMPLETION (BAC) | D6: PLANNED VALUE (PV) | G6: ACTUAL COST (AC) | J6: EARNED VALUE (EV) | N6: Amber | O6: Watch | P6: Near threshold / medium exposure
A7: =Setup!B11 -> 268650 | D7: ='Task Plan'!I17 -> 179033.34 | G7: ='Task Plan'!J17 -> 105490.4 | J7: ='Task Plan'!L17 -> #VALUE! | N7: Red | O7: Action | P7: Behind plan, overrun, or high exposure
A9: COST VARIANCE (CV) | D9: SCHEDULE VARIANCE (SV) | G9: CPI (COST INDEX) | J9: SPI (SCHEDULE INDEX)
A10: ='Task Plan'!N17 -> #VALUE! | D10: ='Task Plan'!M17 -> #VALUE! | G10: ='Task Plan'!P17 -> 1 | J10: ='Task Plan'!O17 -> 1
A12: ESTIMATE AT COMPLETION (EAC) | D12: ESTIMATE TO COMPLETE (ETC) | G12: VARIANCE AT COMPLETION (VAC) | J12: PROJECT PROGRESS %
A13: ='Task Plan'!Q17 -> 222950 | D13: ='Task Plan'!R17 -> 117459.6 | G13: ='Task Plan'!S17 -> 0 | J13: ='Task Plan'!K17 -> 0.4250639
A15: WBS Element Performance Breakdown
A17: WBS ID | B17: Activity Name | C17: Type | D17: Budget (BAC) | E17: Planned Value (PV) | F17: Actual Cost (AC) | G17: Progress % | H17: Earned Value (EV) | I17: CV | J17: SV | K17: CPI | L17: SPI | M17: EAC | N17: ETC | O17: VAC | P17: Status
A18: WBS-01 | B18: Project Management | C18: Labor | D18: 18000 | E18: 13500 | F18: 9600 | G18: 0.5 | H18: 9000 | I18: -600 | J18: -4500 | K18: 0.9375 | L18: 0.66666667 | M18: 19200 | N18: 9600 | O18: -1200 | P18: 🔴 Overrun
A19: WBS-02 | B19: Site Survey & Mobilization | C19: Labor | D19: 8500 | E19: 8500 | F19: 8700 | G19: 1 | H19: 8500 | I19: -200 | J19: 0 | K19: 0.97701149 | L19: 1 | M19: 8700 | N19: 0 | O19: -200 | P19: 🔴 Overrun
A20: WBS-03 | B20: Design & Engineering | C20: Labor | D20: 19200 | E20: 19200 | F20: 18195.04 | G20: 1 | H20: 19200 | I20: 1004.96 | J20: 0 | K20: 1.0552326 | L20: 1 | M20: 18195.04 | N20: 0 | O20: 1004.96 | P20: On Track
A21: WBS-04 | B21: Procurement - Materials | C21: Material | D21: 42000 | E21: 42000 | F21: 41300 | G21: 1 | H21: 42000 | I21: 700 | J21: 0 | K21: 1.0169492 | L21: 1 | M21: 41300 | N21: 0 | O21: 700 | P21: On Track
A22: WBS-05 | B22: Demolition & Prep | C22: Labor | D22: 13200 | E22: 13200 | F22: 13408.16 | G22: 1 | H22: 13200 | I22: -208.16 | J22: 0 | K22: 0.98447513 | L22: 1 | M22: 13408.16 | N22: 0 | O22: -208.16 | P22: 🔴 Overrun
A23: WBS-06 | B23: Electrical Rough-In | C23: Labor | D23: 26000 | E23: 26000 | F23: 26206.24 | G23: 0.7 | H23: 18200 | I23: -8006.24 | J23: -7800 | K23: 0.69449108 | L23: 0.7 | M23: 37437.486 | N23: 11231.246 | O23: -11437.486 | P23: 🔴 Overrun
A24: WBS-07 | B24: HVAC Installation | C24: Subcontractor | D24: 36000 | E24: 36000 | F24: 17476.8 | G24: 0.4 | H24: 14400 | I24: -3076.8 | J24: -21600 | K24: 0.82394946 | L24: 0.4 | M24: 43692 | N24: 26215.2 | O24: -7692 | P24: 🔴 Overrun
A25: WBS-08 | B25: Partitions & Drywall | C25: Subcontractor | D25: 28000 | E25: 28000 | F25: 7099.2 | G25: 0.248857 | H25: 6967.996 | I25: -131.204 | J25: -21032.004 | K25: 0.98151848 | L25: 0.248857 | M25: 28527.226 | N25: 21428.026 | O25: -527.22648 | P25: 🔴 Overrun
A26: WBS-09 | B26: Flooring | C26: Material | D26: 35750 | E26: 23833.34 | F26: 0 | G26: 0 | H26: 0 | I26: 0 | J26: -23833.34 | K26: 1 | L26: 0 | M26: 35750 | N26: 35750 | O26: 0 | P26: 🔴 Overrun
A27: WBS-10 | B27: Fixtures & Furniture | C27: Material | D27: 30000 | E27: 10000 | F27: 0 | G27: 0 | H27: 0 | I27: 0 | J27: -10000 | K27: 1 | L27: 0 | M27: 30000 | N27: 30000 | O27: 0 | P27: 🔴 Overrun
A28: WBS-11 | B28: Testing / Commissioning | C28: Labor | D28: 8400 | E28: 0 | F28: 0 | G28: 0 | H28: 0 | I28: 0 | J28: 0 | K28: 1 | L28: 1 | M28: 8400 | N28: 8400 | O28: 0 | P28: On Track
A29: WBS-12 | B29: Handover & Closeout | C29: Labor | D29: 3600 | E29: 0 | F29: 0 | G29: 0 | H29: 0 | I29: 0 | J29: 0 | K29: 1 | L29: 1 | M29: 3600 | N29: 3600 | O29: 0 | P29: On Track
A30: Total / Project Portfolio | D30: ='Task Plan'!H17 -> 222950 | E30: ='Task Plan'!I17 -> 179033.34 | F30: ='Task Plan'!J17 -> 105490.4 | G30: ='Task Plan'!K17 -> 0.4250639 | H30: ='Task Plan'!L17 -> #VALUE! | I30: ='Task Plan'!N17 -> #VALUE! | J30: ='Task Plan'!M17 -> #VALUE! | K30: ='Task Plan'!P17 -> 1 | L30: ='Task Plan'!O17 -> 1 | M30: ='Task Plan'!Q17 -> 222950 | N30: ='Task Plan'!R17 -> 117459.6 | O30: ='Task Plan'!S17 -> 0 | P30: =IF('Task Plan'!T17="Red","🔴 Overrun",IF('Task Plan'!T17="Amber","🟡 Warning","On Track")) -> #VALUE!
A33: Weekly Cumulative Performance Trends
A35: Week | B35: Week Date | C35: Weekly PV | D35: Cum PV | E35: Weekly AC | F35: Cum AC | G35: Cum EV | H35: CV | I35: SV | J35: CPI | K35: SPI
A36: 1 | B36: 2026-05-04 00:00:00 | C36: 16400 | D36: 16400 | E36: 16295.04 | F36: 16295.04 | G36: 15087.994 | H36: -1207.046 | I36: -1312.006 | J36: 0.92592556 | K36: 0.91999963
A37: 2 | B37: 2026-05-11 00:00:00 | C37: 22800 | D37: 39200 | E37: 22654.08 | F37: 38949.12 | G37: 51151.998 | H37: 12202.878 | I37: 11951.998 | J37: 1.313303 | K37: 1.3048979
A38: 3 | B38: 2026-05-18 00:00:00 | C38: 22800 | D38: 62000 | E38: 22654.08 | F38: 61603.2 | G38: 108192 | H38: 46588.798 | I38: 46191.998 | J38: 1.7562724 | K38: 1.7450322
A39: 4 | B39: 2026-05-25 00:00:00 | C39: 25066.67 | D39: 87066.67 | E39: 24906.24 | F39: 86509.44 | G39: 188293.33 | H39: 101783.89 | I39: 101226.66 | J39: 2.1765639 | K39: 2.1626338
A40: 5 | B40: 2026-06-01 00:00:00 | C40: 29666.67 | D40: 116733.34 | E40: 29476.8 | F40: 115986.24 | G40: 295688 | H40: 179701.76 | I40: 178954.66 | J40: 2.5493369 | K40: 2.533021
A41: 6 | B41: 2026-06-08 00:00:00 | C41: 26166.66 | D41: 142900 | E41: 25999.2 | F41: 141985.44 | G41: 427156 | H41: 285170.56 | I41: 284256 | J41: 3.0084493 | K41: 2.9891952
A42: 7 | B42: 2026-06-15 00:00:00 | C42: 17500 | D42: 160400 | E42: 0 | F42: 141985.44 | G42: 427156 | H42: 285170.56 | I42: 266756 | J42: 3.0084493 | K42: 2.6630673
A43: 8 | B43: 2026-06-22 00:00:00 | C43: 29416.67 | D43: 189816.67 | E43: 0 | F43: 141985.44 | G43: 427156 | H43: 285170.56 | I43: 237339.33 | J43: 3.0084493 | K43: 2.2503608
A44: 9 | B44: 2026-06-29 00:00:00 | C44: 30416.67 | D44: 220233.34 | E44: 0 | F44: 141985.44 | G44: 427156 | H44: 285170.56 | I44: 206922.66 | J44: 3.0084493 | K44: 1.939561
A45: 10 | B45: 2026-07-06 00:00:00 | C45: 23416.66 | D45: 243650 | E45: 0 | F45: 141985.44 | G45: 427156 | H45: 285170.56 | I45: 183506 | J45: 3.0084493 | K45: 1.7531541
A46: 11 | B46: 2026-07-13 00:00:00 | C46: 15700 | D46: 259350 | E46: 0 | F46: 141985.44 | G46: 427156 | H46: 285170.56 | I46: 167806 | J46: 3.0084493 | K46: 1.6470252
A47: 12 | B47: 2026-07-20 00:00:00 | C47: 9300 | D47: 268650 | E47: 0 | F47: 141985.44 | G47: 427156 | H47: 285170.56 | I47: 158506 | J47: 3.0084493 | K47: 1.5900093

Sheet Red Actions
A1: Red RAG Action Recommendations
A2: Focused recovery actions for WBS items and control risks currently flagged Red. Evidence is pulled live from tbl_Task_Plan.
A4: STORY IN BRIEF
A5: The red status is mainly schedule-driven: Flooring, Fixtures & Furniture, Partitions & Drywall, HVAC, and Electrical Rough-In are the recovery priorities because their SPI and schedule variances are pulling the project off plan. Cost exposure is concentrated in Electrical Rough-In and HVAC, while completed red tasks need closeout variance review rather than delivery acceleration. The recommended response is a short recovery sprint: remove blockers, confirm subcontractor/material readiness, reset near-term dates, and escalate decision items already logged in the Review sheet.
A9: Red WBS items | C9: Worst red SPI | E9: Largest red SV | G9: Red forecast overrun
A10: =COUNTIF(tbl_Task_Plan[Status],"Red") -> 0 | C10: =_xlfn.MINIFS(tbl_Task_Plan[SPI],tbl_Task_Plan[Status],"Red") -> 0 | E10: =_xlfn.MINIFS(tbl_Task_Plan[SV],tbl_Task_Plan[Status],"Red") -> 0 | G10: =-SUMIFS(tbl_Task_Plan[VAC],tbl_Task_Plan[Status],"Red") -> 0
A13: Priority | B13: WBS ID | C13: Activity | D13: Red driver | E13: Live evidence | F13: Recommended action | G13: Owner | H13: Due date
A14: REC-01 | B14: Design Phase Actual Cost slightly overran baseline | C14: CPI: 0.98 | D14: Low | E14: Monitor labor rates | F14: Frank Ellingsen | G14: 2026-09-15 | H14: Closed
A15: 2 | B15: WBS-08 | C15: =_xlfn.XLOOKUP(B15,tbl_Task_Plan[WBS ID],tbl_Task_Plan[Task / Activity],"") | D15: Low progress / schedule | E15: =TEXT(_xlfn.XLOOKUP(B15,tbl_Task_Plan[WBS ID],tbl_Task_Plan[Progress %]),"0%")&" complete; SPI "&TEXT(_xlfn.XLOOKUP(B15,tbl_Task_Plan[WBS ID],tbl_Task_Plan[SPI]),"0.00")&"; CPI "&TEXT(_xlfn.XLOOKUP(B15,tbl_Task_Plan[WBS ID],tbl_Task_Plan[CPI]),"0.00")&"; SV "&TEXT(_xlfn.XLOOKUP(B15,tbl_Task_Plan[WBS ID],tbl_Task_Plan[SV]),"#,##0")&" NOK" -> #N/A | F15: Run a blocker review with electrical rough-in and subcontractor leads; add resources or resequence drylining areas to recover the critical path. | G15: Project Manager | H15: =Control_Status_Date+2 -> 46205
A16: 3 | B16: WBS-07 | C16: =_xlfn.XLOOKUP(B16,tbl_Task_Plan[WBS ID],tbl_Task_Plan[Task / Activity],"") | D16: Subcontractor schedule + cost | E16: =TEXT(_xlfn.XLOOKUP(B16,tbl_Task_Plan[WBS ID],tbl_Task_Plan[Progress %]),"0%")&" complete; SPI "&TEXT(_xlfn.XLOOKUP(B16,tbl_Task_Plan[WBS ID],tbl_Task_Plan[SPI]),"0.00")&"; CPI "&TEXT(_xlfn.XLOOKUP(B16,tbl_Task_Plan[WBS ID],tbl_Task_Plan[CPI]),"0.00")&"; SV "&TEXT(_xlfn.XLOOKUP(B16,tbl_Task_Plan[WBS ID],tbl_Task_Plan[SV]),"#,##0")&" NOK" -> #N/A | F16: Require a subcontractor recovery plan: committed crew levels, daily output targets, and commercial review of cost burn versus earned progress. | G16: Project Manager | H16: =Control_Status_Date+2 -> 46205
A17: 4 | B17: WBS-06 | C17: =_xlfn.XLOOKUP(B17,tbl_Task_Plan[WBS ID],tbl_Task_Plan[Task / Activity],"") | D17: Cost + schedule | E17: =TEXT(_xlfn.XLOOKUP(B17,tbl_Task_Plan[WBS ID],tbl_Task_Plan[Progress %]),"0%")&" complete; SPI "&TEXT(_xlfn.XLOOKUP(B17,tbl_Task_Plan[WBS ID],tbl_Task_Plan[SPI]),"0.00")&"; CPI "&TEXT(_xlfn.XLOOKUP(B17,tbl_Task_Plan[WBS ID],tbl_Task_Plan[CPI]),"0.00")&"; SV "&TEXT(_xlfn.XLOOKUP(B17,tbl_Task_Plan[WBS ID],tbl_Task_Plan[SV]),"#,##0")&" NOK" -> #N/A | F17: Hold a root-cause review on low CPI/SPI; separate scope change from productivity loss, update EAC, and escalate any funding/date decision. | G17: Project Controls | H17: =Control_Status_Date+2 -> 46205
A18: 5 | B18: WBS-10 | C18: =_xlfn.XLOOKUP(B18,tbl_Task_Plan[WBS ID],tbl_Task_Plan[Task / Activity],"") | D18: Future work at risk | E18: =TEXT(_xlfn.XLOOKUP(B18,tbl_Task_Plan[WBS ID],tbl_Task_Plan[Progress %]),"0%")&" complete; SPI "&TEXT(_xlfn.XLOOKUP(B18,tbl_Task_Plan[WBS ID],tbl_Task_Plan[SPI]),"0.00")&"; CPI "&TEXT(_xlfn.XLOOKUP(B18,tbl_Task_Plan[WBS ID],tbl_Task_Plan[CPI]),"0.00")&"; SV "&TEXT(_xlfn.XLOOKUP(B18,tbl_Task_Plan[WBS ID],tbl_Task_Plan[SV]),"#,##0")&" NOK" -> #N/A | F18: Confirm fixture/furniture procurement, delivery slots, and installation dependency on flooring; prepare fallback suppliers if dates slip. | G18: Procurement / Planner | H18: =Control_Status_Date+5 -> 46208
A19: 6 | B19: WBS-01 | C19: =_xlfn.XLOOKUP(B19,tbl_Task_Plan[WBS ID],tbl_Task_Plan[Task / Activity],"") | D19: Management effort behind plan | E19: =TEXT(_xlfn.XLOOKUP(B19,tbl_Task_Plan[WBS ID],tbl_Task_Plan[Progress %]),"0%")&" complete; SPI "&TEXT(_xlfn.XLOOKUP(B19,tbl_Task_Plan[WBS ID],tbl_Task_Plan[SPI]),"0.00")&"; CPI "&TEXT(_xlfn.XLOOKUP(B19,tbl_Task_Plan[WBS ID],tbl_Task_Plan[CPI]),"0.00")&"; SV "&TEXT(_xlfn.XLOOKUP(B19,tbl_Task_Plan[WBS ID],tbl_Task_Plan[SV]),"#,##0")&" NOK" -> #N/A | F19: Increase recovery cadence: daily issue log, weekly decision pack, and named owners for every red WBS mitigation. | G19: Project Manager | H19: =Control_Status_Date+2 -> 46205
A20: 7 | B20: WBS-02 | C20: =_xlfn.XLOOKUP(B20,tbl_Task_Plan[WBS ID],tbl_Task_Plan[Task / Activity],"") | D20: Completed cost variance | E20: =TEXT(_xlfn.XLOOKUP(B20,tbl_Task_Plan[WBS ID],tbl_Task_Plan[Progress %]),"0%")&" complete; SPI "&TEXT(_xlfn.XLOOKUP(B20,tbl_Task_Plan[WBS ID],tbl_Task_Plan[SPI]),"0.00")&"; CPI "&TEXT(_xlfn.XLOOKUP(B20,tbl_Task_Plan[WBS ID],tbl_Task_Plan[CPI]),"0.00")&"; SV "&TEXT(_xlfn.XLOOKUP(B20,tbl_Task_Plan[WBS ID],tbl_Task_Plan[SV]),"#,##0")&" NOK" -> #N/A | F20: Close out the small overrun: validate final actuals, code any one-off cost correctly, and prevent it from distorting future forecasts. | G20: Project Controls | H20: =Control_Status_Date+7 -> 46210
A21: 8 | B21: WBS-05 | C21: =_xlfn.XLOOKUP(B21,tbl_Task_Plan[WBS ID],tbl_Task_Plan[Task / Activity],"") | D21: Completed cost variance | E21: =TEXT(_xlfn.XLOOKUP(B21,tbl_Task_Plan[WBS ID],tbl_Task_Plan[Progress %]),"0%")&" complete; SPI "&TEXT(_xlfn.XLOOKUP(B21,tbl_Task_Plan[WBS ID],tbl_Task_Plan[SPI]),"0.00")&"; CPI "&TEXT(_xlfn.XLOOKUP(B21,tbl_Task_Plan[WBS ID],tbl_Task_Plan[CPI]),"0.00")&"; SV "&TEXT(_xlfn.XLOOKUP(B21,tbl_Task_Plan[WBS ID],tbl_Task_Plan[SV]),"#,##0")&" NOK" -> #N/A | F21: Close out demolition/prep variance and capture lessons learned for estimate accuracy and crew productivity assumptions. | G21: Project Controls | H21: =Control_Status_Date+7 -> 46210
A24: ESCALATE / TRACK
A25: Use Review!A21:F23 as the decision log for schedule slippage, EAC/cost review, and red WBS mitigation. Use PID!A64:E65 as the risk register entries for schedule slippage and cost overrun. Refresh this sheet after changing the source Task Plan or thresholds.

Sheet Pivot Summary
A1: High-Level Pivot Summary & Descriptive Statistics
A2: PivotTables summarize the key project-control tables; descriptive statistics are live formulas linked to the Task Plan source range.
A4: STORY IN BRIEF
A5: The project is under schedule pressure, with red WBS items concentrated in unfinished material/subcontractor and rough-in work. The PivotTables summarize exposure by Type, Status, WBS, and week; the descriptive statistics quantify central tendency and outliers across task-level cost and schedule metrics.
A8: Red WBS | B8: Total BAC | C8: Actual Cost | D8: Earned Value | E8: Avg SPI | F8: Avg CPI | G8: Forecast overrun
A9: =COUNTIF('Task Plan'!T5:T16,"Red") -> 6 | B9: =SUM('Task Plan'!H5:H16) -> 222950 | C9: =SUM('Task Plan'!J5:J16) -> 105490.4 | D9: =SUM('Task Plan'!L5:L16) -> #VALUE! | E9: =AVERAGE('Task Plan'!O5:O16) -> 0.69573808 | F9: =AVERAGE('Task Plan'!P5:P16) -> 0.95844861 | G9: =-SUM('Task Plan'!S5:S16) -> #VALUE!
A12: DESCRIPTIVE STATISTICS
A13: Metric | B13: Count | C13: Mean | D13: Median | E13: Std Dev | F13: Min | G13: Max
A14: BAC (NOK) | B14: 0 | C14: 0 | D14: 0 | E14: 0 | F14: 0 | G14: 0
A15: PV @ Status | B15: 0 | C15: 0 | D15: 0 | E15: 0 | F15: 0 | G15: 0
A16: AC @ Status | B16: 0 | C16: 0 | D16: 0 | E16: 0 | F16: 0 | G16: 0
A17: EV @ Status | B17: 0 | C17: 0 | D17: 0 | E17: 0 | F17: 0 | G17: 0
A18: Progress % | B18: 0 | C18: 0 | D18: 0 | E18: 0 | F18: 0 | G18: 0
A19: SPI | B19: 0 | C19: 0 | D19: 0 | E19: 0 | F19: 0 | G19: 0
A20: CPI | B20: 0 | C20: 0 | D20: 0 | E20: 0 | F20: 0 | G20: 0
A21: SV | B21: 0 | C21: 0 | D21: 0 | E21: 0 | F21: 0 | G21: 0
A22: CV | B22: 0 | C22: 0 | D22: 0 | E22: 0 | F22: 0 | G22: 0
A23: VAC | B23: 0 | C23: 0 | D23: 0 | E23: 0 | F23: 0 | G23: 0
A26: PIVOT: COST / VALUE BY TYPE
A27: Row Labels | B27: Sum of BAC (NOK) | C27: Sum of PV @ Status | D27: Sum of AC @ Status | E27: Sum of EV @ Status | F27: Sum of SV | G27: Sum of CV | H27: Sum of VAC
A28: Labor | B28: 96900 | C28: 80400 | D28: 76109.44 | E28: 68100 | F28: -12300 | G28: -8009.44 | H28: -12040.686
A29: Material | B29: 107750 | C29: 75833.34 | D29: 41300 | E29: 42000 | F29: -33833.34 | G29: 700 | H29: 700
A30: Subcontractor | B30: 64000 | C30: 64000 | D30: 24576 | E30: 21367.996 | F30: -42632.004 | G30: -3208.004 | H30: -8219.2265
A31: Grand Total | B31: 268650 | C31: 220233.34 | D31: 141985.44 | E31: 131468 | F31: -88765.344 | G31: -10517.444 | H31: -19559.912
A35: PIVOT: COST / VALUE BY STATUS
A36: Row Labels | B36: Sum of BAC (NOK) | C36: Sum of PV @ Status | D36: Sum of AC @ Status | E36: Sum of EV @ Status | F36: Sum of SV | G36: Sum of CV | H36: Sum of VAC
A37: Green | B37: 73200 | C37: 61200 | D37: 59495.04 | E37: 61200 | F37: 0 | G37: 1704.96 | H37: 1704.96
A38: Red | B38: 195450 | C38: 159033.34 | D38: 82490.4 | E38: 70267.996 | F38: -88765.344 | G38: -12222.404 | H38: -21264.872
A39: Grand Total | B39: 268650 | C39: 220233.34 | D39: 141985.44 | E39: 131468 | F39: -88765.344 | G39: -10517.444 | H39: -19559.912
A44: PIVOT: ACTUAL COSTS BY WBS
A45: Row Labels | B45: Sum of Actual_Cost | C45: Sum of Hours_Worked
A46: WBS-01 | B46: 9600 | C46: 6.3
A47: WBS-02 | B47: 8700 | C47: 3.95
A48: WBS-03 | B48: 18195.04 | C48: 7.6
A49: WBS-04 | B49: 41300 | C49: 0
A50: WBS-05 | B50: 13408.16 | C50: 6.05
A51: WBS-06 | B51: 26206.24 | C51: 10.1
A52: WBS-07 | B52: 17476.8 | C52: 0
A53: WBS-08 | B53: 7099.2 | C53: 0
A54: Grand Total | B54: 141985.44 | C54: 34
...

Sheet Resource Grid
A1: Resource Allocation Grid
A2: Weekly hours and cost grid adapted from the attached Gantt template: rows are WBS tasks; columns are reporting weeks; totals are live formulas from actual-cost facts.
A4: WBS ID | B4: Activity | C4: Resource / Role | D4: Measure | E4: Wk1 | F4: Wk2 | G4: Wk3 | H4: Wk4 | I4: Wk5 | J4: Wk6 | K4: Wk7 | L4: Wk8 | M4: Wk9 | N4: Wk10 | O4: Wk11 | P4: Wk12 | Q4: Total | R4: BAC | S4: Actual @ Status | T4: Remaining BAC | U4: CPI | V4: RAG | W4: Template source | X4: Notes
A5: WBS-01 | B5: Project Management | C5: Labor | D5: Hours | E5: 1.05 | F5: 1.05 | G5: 1.05 | H5: 1.05 | I5: 1.05 | J5: 1.05 | K5: 0 | L5: 0 | M5: 0 | N5: 0 | O5: 0 | P5: 0 | Q5: 6.3 | R5: 18000 | S5: 9600 | T5: 8400 | U5: 0.9375 | V5: Red | W5: 8.1.2 Gantt template from garden office | X5: Hours row
A6: WBS-01 | B6: Project Management | C6: Labor | D6: Cost | E6: 1600 | F6: 1600 | G6: 1600 | H6: 1600 | I6: 1600 | J6: 1600 | K6: 0 | L6: 0 | M6: 0 | N6: 0 | O6: 0 | P6: 0 | Q6: 9600 | R6: 18000 | S6: 9600 | T6: 8400 | U6: 0.9375 | V6: Red | W6: 8.1.2 Gantt template from garden office | X6: Cost row
A7: WBS-02 | B7: Site Survey & Mobilization | C7: Labor | D7: Hours | E7: 3.95 | F7: 0 | G7: 0 | H7: 0 | I7: 0 | J7: 0 | K7: 0 | L7: 0 | M7: 0 | N7: 0 | O7: 0 | P7: 0 | Q7: 3.95 | R7: 8500 | S7: 8700 | T7: -200 | U7: 0.97701149 | V7: Amber | W7: 8.1.2 Gantt template from garden office | X7: Hours row
A8: WBS-02 | B8: Site Survey & Mobilization | C8: Labor | D8: Cost | E8: 8700 | F8: 0 | G8: 0 | H8: 0 | I8: 0 | J8: 0 | K8: 0 | L8: 0 | M8: 0 | N8: 0 | O8: 0 | P8: 0 | Q8: 8700 | R8: 8500 | S8: 8700 | T8: -200 | U8: 0.97701149 | V8: Amber | W8: 8.1.2 Gantt template from garden office | X8: Cost row
A9: WBS-03 | B9: Design & Engineering | C9: Labor | D9: Hours | E9: 2.5 | F9: 2.5 | G9: 2.6 | H9: 0 | I9: 0 | J9: 0 | K9: 0 | L9: 0 | M9: 0 | N9: 0 | O9: 0 | P9: 0 | Q9: 7.6 | R9: 19200 | S9: 18195.04 | T9: 1004.96 | U9: 1.0552326 | V9: Green | W9: 8.1.2 Gantt template from garden office | X9: Hours row
A10: WBS-03 | B10: Design & Engineering | C10: Labor | D10: Cost | E10: 5995.04 | F10: 6000 | G10: 6200 | H10: 0 | I10: 0 | J10: 0 | K10: 0 | L10: 0 | M10: 0 | N10: 0 | O10: 0 | P10: 0 | Q10: 18195.04 | R10: 19200 | S10: 18195.04 | T10: 1004.96 | U10: 1.0552326 | V10: Green | W10: 8.1.2 Gantt template from garden office | X10: Cost row
A11: WBS-04 | B11: Procurement - Materials | C11: Material | D11: Hours | E11: 0 | F11: 0 | G11: 0 | H11: 0 | I11: 0 | J11: 0 | K11: 0 | L11: 0 | M11: 0 | N11: 0 | O11: 0 | P11: 0 | Q11: 0 | R11: 42000 | S11: 41300 | T11: 700 | U11: 1.0169492 | V11: Green | W11: 8.1.2 Gantt template from garden office | X11: Hours row
A12: WBS-04 | B12: Procurement - Materials | C12: Material | D12: Cost | E12: 0 | F12: 10500 | G12: 10200 | H12: 10200 | I12: 10400 | J12: 0 | K12: 0 | L12: 0 | M12: 0 | N12: 0 | O12: 0 | P12: 0 | Q12: 41300 | R12: 42000 | S12: 41300 | T12: 700 | U12: 1.0169492 | V12: Green | W12: 8.1.2 Gantt template from garden office | X12: Cost row
A13: WBS-05 | B13: Demolition & Prep | C13: Labor | D13: Hours | E13: 0 | F13: 2.05 | G13: 2.1 | H13: 1.9 | I13: 0 | J13: 0 | K13: 0 | L13: 0 | M13: 0 | N13: 0 | O13: 0 | P13: 0 | Q13: 6.05 | R13: 13200 | S13: 13408.16 | T13: -208.16 | U13: 0.98447513 | V13: Amber | W13: 8.1.2 Gantt template from garden office | X13: Hours row
