Workbook

Sheet Project Plan
A1: EVM Mock Project Plan — Office Fit-Out
A2: Mock EVM baseline: activity budgets are spread across planned weeks; weekly PV and cumulative PV roll up to BAC.
A4: Activity | B4: Type | C4: Unit Quantity | D4: Rate | E4: Total Budget | F4: wk1 | G4: wk2 | H4: wk3 | I4: wk4 | J4: wk5 | K4: wk6 | L4: wk7 | M4: wk8 | N4: wk9 | O4: wk10 | P4: wk11 | Q4: wk12 | R4: Start Week | S4: End Week
A5: Project Management | B5: Labor | C5: 12 | D5: 1500 | E5: =C5*D5 -> 18000 | F5: =IF(AND(1>=$R5,1<=$S5),$E5/($S5-$R5+1),0) -> 1500 | G5: =IF(AND(2>=$R5,2<=$S5),$E5/($S5-$R5+1),0) -> 1500 | H5: =IF(AND(3>=$R5,3<=$S5),$E5/($S5-$R5+1),0) -> 1500 | I5: =IF(AND(4>=$R5,4<=$S5),$E5/($S5-$R5+1),0) -> 1500 | J5: =IF(AND(5>=$R5,5<=$S5),$E5/($S5-$R5+1),0) -> 1500 | K5: =IF(AND(6>=$R5,6<=$S5),$E5/($S5-$R5+1),0) -> 1500 | L5: =IF(AND(7>=$R5,7<=$S5),$E5/($S5-$R5+1),0) -> 1500 | M5: =IF(AND(8>=$R5,8<=$S5),$E5/($S5-$R5+1),0) -> 1500 | N5: =IF(AND(9>=$R5,9<=$S5),$E5/($S5-$R5+1),0) -> 1500 | O5: =IF(AND(10>=$R5,10<=$S5),$E5/($S5-$R5+1),0) -> 1500 | P5: =IF(AND(11>=$R5,11<=$S5),$E5/($S5-$R5+1),0) -> 1500 | Q5: =IF(AND(12>=$R5,12<=$S5),$E5/($S5-$R5+1),0) -> 1500 | R5: 1 | S5: 12
A6: Site Survey & Mobilization | B6: Labor | C6: 1 | D6: 8500 | E6: =C6*D6 -> 8500 | F6: =IF(AND(1>=$R6,1<=$S6),$E6/($S6-$R6+1),0) -> 8500 | G6: =IF(AND(2>=$R6,2<=$S6),$E6/($S6-$R6+1),0) -> 0 | H6: =IF(AND(3>=$R6,3<=$S6),$E6/($S6-$R6+1),0) -> 0 | I6: =IF(AND(4>=$R6,4<=$S6),$E6/($S6-$R6+1),0) -> 0 | J6: =IF(AND(5>=$R6,5<=$S6),$E6/($S6-$R6+1),0) -> 0 | K6: =IF(AND(6>=$R6,6<=$S6),$E6/($S6-$R6+1),0) -> 0 | L6: =IF(AND(7>=$R6,7<=$S6),$E6/($S6-$R6+1),0) -> 0 | M6: =IF(AND(8>=$R6,8<=$S6),$E6/($S6-$R6+1),0) -> 0 | N6: =IF(AND(9>=$R6,9<=$S6),$E6/($S6-$R6+1),0) -> 0 | O6: =IF(AND(10>=$R6,10<=$S6),$E6/($S6-$R6+1),0) -> 0 | P6: =IF(AND(11>=$R6,11<=$S6),$E6/($S6-$R6+1),0) -> 0 | Q6: =IF(AND(12>=$R6,12<=$S6),$E6/($S6-$R6+1),0) -> 0 | R6: 1 | S6: 1
A7: Design & Engineering | B7: Labor | C7: 8 | D7: 2400 | E7: =C7*D7 -> 19200 | F7: =IF(AND(1>=$R7,1<=$S7),$E7/($S7-$R7+1),0) -> 6400 | G7: =IF(AND(2>=$R7,2<=$S7),$E7/($S7-$R7+1),0) -> 6400 | H7: =IF(AND(3>=$R7,3<=$S7),$E7/($S7-$R7+1),0) -> 6400 | I7: =IF(AND(4>=$R7,4<=$S7),$E7/($S7-$R7+1),0) -> 0 | J7: =IF(AND(5>=$R7,5<=$S7),$E7/($S7-$R7+1),0) -> 0 | K7: =IF(AND(6>=$R7,6<=$S7),$E7/($S7-$R7+1),0) -> 0 | L7: =IF(AND(7>=$R7,7<=$S7),$E7/($S7-$R7+1),0) -> 0 | M7: =IF(AND(8>=$R7,8<=$S7),$E7/($S7-$R7+1),0) -> 0 | N7: =IF(AND(9>=$R7,9<=$S7),$E7/($S7-$R7+1),0) -> 0 | O7: =IF(AND(10>=$R7,10<=$S7),$E7/($S7-$R7+1),0) -> 0 | P7: =IF(AND(11>=$R7,11<=$S7),$E7/($S7-$R7+1),0) -> 0 | Q7: =IF(AND(12>=$R7,12<=$S7),$E7/($S7-$R7+1),0) -> 0 | R7: 1 | S7: 3
A8: Procurement - Materials | B8: Material | C8: 1 | D8: 42000 | E8: =C8*D8 -> 42000 | F8: =IF(AND(1>=$R8,1<=$S8),$E8/($S8-$R8+1),0) -> 0 | G8: =IF(AND(2>=$R8,2<=$S8),$E8/($S8-$R8+1),0) -> 10500 | H8: =IF(AND(3>=$R8,3<=$S8),$E8/($S8-$R8+1),0) -> 10500 | I8: =IF(AND(4>=$R8,4<=$S8),$E8/($S8-$R8+1),0) -> 10500 | J8: =IF(AND(5>=$R8,5<=$S8),$E8/($S8-$R8+1),0) -> 10500 | K8: =IF(AND(6>=$R8,6<=$S8),$E8/($S8-$R8+1),0) -> 0 | L8: =IF(AND(7>=$R8,7<=$S8),$E8/($S8-$R8+1),0) -> 0 | M8: =IF(AND(8>=$R8,8<=$S8),$E8/($S8-$R8+1),0) -> 0 | N8: =IF(AND(9>=$R8,9<=$S8),$E8/($S8-$R8+1),0) -> 0 | O8: =IF(AND(10>=$R8,10<=$S8),$E8/($S8-$R8+1),0) -> 0 | P8: =IF(AND(11>=$R8,11<=$S8),$E8/($S8-$R8+1),0) -> 0 | Q8: =IF(AND(12>=$R8,12<=$S8),$E8/($S8-$R8+1),0) -> 0 | R8: 2 | S8: 5
A9: Demolition & Prep | B9: Labor | C9: 6 | D9: 2200 | E9: =C9*D9 -> 13200 | F9: =IF(AND(1>=$R9,1<=$S9),$E9/($S9-$R9+1),0) -> 0 | G9: =IF(AND(2>=$R9,2<=$S9),$E9/($S9-$R9+1),0) -> 4400 | H9: =IF(AND(3>=$R9,3<=$S9),$E9/($S9-$R9+1),0) -> 4400 | I9: =IF(AND(4>=$R9,4<=$S9),$E9/($S9-$R9+1),0) -> 4400 | J9: =IF(AND(5>=$R9,5<=$S9),$E9/($S9-$R9+1),0) -> 0 | K9: =IF(AND(6>=$R9,6<=$S9),$E9/($S9-$R9+1),0) -> 0 | L9: =IF(AND(7>=$R9,7<=$S9),$E9/($S9-$R9+1),0) -> 0 | M9: =IF(AND(8>=$R9,8<=$S9),$E9/($S9-$R9+1),0) -> 0 | N9: =IF(AND(9>=$R9,9<=$S9),$E9/($S9-$R9+1),0) -> 0 | O9: =IF(AND(10>=$R9,10<=$S9),$E9/($S9-$R9+1),0) -> 0 | P9: =IF(AND(11>=$R9,11<=$S9),$E9/($S9-$R9+1),0) -> 0 | Q9: =IF(AND(12>=$R9,12<=$S9),$E9/($S9-$R9+1),0) -> 0 | R9: 2 | S9: 4
A10: Electrical Rough-In | B10: Labor | C10: 10 | D10: 2600 | E10: =C10*D10 -> 26000 | F10: =IF(AND(1>=$R10,1<=$S10),$E10/($S10-$R10+1),0) -> 0 | G10: =IF(AND(2>=$R10,2<=$S10),$E10/($S10-$R10+1),0) -> 0 | H10: =IF(AND(3>=$R10,3<=$S10),$E10/($S10-$R10+1),0) -> 0 | I10: =IF(AND(4>=$R10,4<=$S10),$E10/($S10-$R10+1),0) -> 8666.6667 | J10: =IF(AND(5>=$R10,5<=$S10),$E10/($S10-$R10+1),0) -> 8666.6667 | K10: =IF(AND(6>=$R10,6<=$S10),$E10/($S10-$R10+1),0) -> 8666.6667 | L10: =IF(AND(7>=$R10,7<=$S10),$E10/($S10-$R10+1),0) -> 0 | M10: =IF(AND(8>=$R10,8<=$S10),$E10/($S10-$R10+1),0) -> 0 | N10: =IF(AND(9>=$R10,9<=$S10),$E10/($S10-$R10+1),0) -> 0 | O10: =IF(AND(10>=$R10,10<=$S10),$E10/($S10-$R10+1),0) -> 0 | P10: =IF(AND(11>=$R10,11<=$S10),$E10/($S10-$R10+1),0) -> 0 | Q10: =IF(AND(12>=$R10,12<=$S10),$E10/($S10-$R10+1),0) -> 0 | R10: 4 | S10: 6
A11: HVAC Installation | B11: Subcontractor | C11: 1 | D11: 36000 | E11: =C11*D11 -> 36000 | F11: =IF(AND(1>=$R11,1<=$S11),$E11/($S11-$R11+1),0) -> 0 | G11: =IF(AND(2>=$R11,2<=$S11),$E11/($S11-$R11+1),0) -> 0 | H11: =IF(AND(3>=$R11,3<=$S11),$E11/($S11-$R11+1),0) -> 0 | I11: =IF(AND(4>=$R11,4<=$S11),$E11/($S11-$R11+1),0) -> 0 | J11: =IF(AND(5>=$R11,5<=$S11),$E11/($S11-$R11+1),0) -> 9000 | K11: =IF(AND(6>=$R11,6<=$S11),$E11/($S11-$R11+1),0) -> 9000 | L11: =IF(AND(7>=$R11,7<=$S11),$E11/($S11-$R11+1),0) -> 9000 | M11: =IF(AND(8>=$R11,8<=$S11),$E11/($S11-$R11+1),0) -> 9000 | N11: =IF(AND(9>=$R11,9<=$S11),$E11/($S11-$R11+1),0) -> 0 | O11: =IF(AND(10>=$R11,10<=$S11),$E11/($S11-$R11+1),0) -> 0 | P11: =IF(AND(11>=$R11,11<=$S11),$E11/($S11-$R11+1),0) -> 0 | Q11: =IF(AND(12>=$R11,12<=$S11),$E11/($S11-$R11+1),0) -> 0 | R11: 5 | S11: 8
A12: Partitions & Drywall | B12: Subcontractor | C12: 1 | D12: 28000 | E12: =C12*D12 -> 28000 | F12: =IF(AND(1>=$R12,1<=$S12),$E12/($S12-$R12+1),0) -> 0 | G12: =IF(AND(2>=$R12,2<=$S12),$E12/($S12-$R12+1),0) -> 0 | H12: =IF(AND(3>=$R12,3<=$S12),$E12/($S12-$R12+1),0) -> 0 | I12: =IF(AND(4>=$R12,4<=$S12),$E12/($S12-$R12+1),0) -> 0 | J12: =IF(AND(5>=$R12,5<=$S12),$E12/($S12-$R12+1),0) -> 0 | K12: =IF(AND(6>=$R12,6<=$S12),$E12/($S12-$R12+1),0) -> 7000 | L12: =IF(AND(7>=$R12,7<=$S12),$E12/($S12-$R12+1),0) -> 7000 | M12: =IF(AND(8>=$R12,8<=$S12),$E12/($S12-$R12+1),0) -> 7000 | N12: =IF(AND(9>=$R12,9<=$S12),$E12/($S12-$R12+1),0) -> 7000 | O12: =IF(AND(10>=$R12,10<=$S12),$E12/($S12-$R12+1),0) -> 0 | P12: =IF(AND(11>=$R12,11<=$S12),$E12/($S12-$R12+1),0) -> 0 | Q12: =IF(AND(12>=$R12,12<=$S12),$E12/($S12-$R12+1),0) -> 0 | R12: 6 | S12: 9
A13: Flooring | B13: Material | C13: 650 | D13: 55 | E13: =C13*D13 -> 35750 | F13: =IF(AND(1>=$R13,1<=$S13),$E13/($S13-$R13+1),0) -> 0 | G13: =IF(AND(2>=$R13,2<=$S13),$E13/($S13-$R13+1),0) -> 0 | H13: =IF(AND(3>=$R13,3<=$S13),$E13/($S13-$R13+1),0) -> 0 | I13: =IF(AND(4>=$R13,4<=$S13),$E13/($S13-$R13+1),0) -> 0 | J13: =IF(AND(5>=$R13,5<=$S13),$E13/($S13-$R13+1),0) -> 0 | K13: =IF(AND(6>=$R13,6<=$S13),$E13/($S13-$R13+1),0) -> 0 | L13: =IF(AND(7>=$R13,7<=$S13),$E13/($S13-$R13+1),0) -> 0 | M13: =IF(AND(8>=$R13,8<=$S13),$E13/($S13-$R13+1),0) -> 11916.667 | N13: =IF(AND(9>=$R13,9<=$S13),$E13/($S13-$R13+1),0) -> 11916.667 | O13: =IF(AND(10>=$R13,10<=$S13),$E13/($S13-$R13+1),0) -> 11916.667 | P13: =IF(AND(11>=$R13,11<=$S13),$E13/($S13-$R13+1),0) -> 0 | Q13: =IF(AND(12>=$R13,12<=$S13),$E13/($S13-$R13+1),0) -> 0 | R13: 8 | S13: 10
A14: Fixtures & Furniture | B14: Material | C14: 1 | D14: 30000 | E14: =C14*D14 -> 30000 | F14: =IF(AND(1>=$R14,1<=$S14),$E14/($S14-$R14+1),0) -> 0 | G14: =IF(AND(2>=$R14,2<=$S14),$E14/($S14-$R14+1),0) -> 0 | H14: =IF(AND(3>=$R14,3<=$S14),$E14/($S14-$R14+1),0) -> 0 | I14: =IF(AND(4>=$R14,4<=$S14),$E14/($S14-$R14+1),0) -> 0 | J14: =IF(AND(5>=$R14,5<=$S14),$E14/($S14-$R14+1),0) -> 0 | K14: =IF(AND(6>=$R14,6<=$S14),$E14/($S14-$R14+1),0) -> 0 | L14: =IF(AND(7>=$R14,7<=$S14),$E14/($S14-$R14+1),0) -> 0 | M14: =IF(AND(8>=$R14,8<=$S14),$E14/($S14-$R14+1),0) -> 0 | N14: =IF(AND(9>=$R14,9<=$S14),$E14/($S14-$R14+1),0) -> 10000 | O14: =IF(AND(10>=$R14,10<=$S14),$E14/($S14-$R14+1),0) -> 10000 | P14: =IF(AND(11>=$R14,11<=$S14),$E14/($S14-$R14+1),0) -> 10000 | Q14: =IF(AND(12>=$R14,12<=$S14),$E14/($S14-$R14+1),0) -> 0 | R14: 9 | S14: 11
A15: Testing / Commissioning | B15: Labor | C15: 4 | D15: 2100 | E15: =C15*D15 -> 8400 | F15: =IF(AND(1>=$R15,1<=$S15),$E15/($S15-$R15+1),0) -> 0 | G15: =IF(AND(2>=$R15,2<=$S15),$E15/($S15-$R15+1),0) -> 0 | H15: =IF(AND(3>=$R15,3<=$S15),$E15/($S15-$R15+1),0) -> 0 | I15: =IF(AND(4>=$R15,4<=$S15),$E15/($S15-$R15+1),0) -> 0 | J15: =IF(AND(5>=$R15,5<=$S15),$E15/($S15-$R15+1),0) -> 0 | K15: =IF(AND(6>=$R15,6<=$S15),$E15/($S15-$R15+1),0) -> 0 | L15: =IF(AND(7>=$R15,7<=$S15),$E15/($S15-$R15+1),0) -> 0 | M15: =IF(AND(8>=$R15,8<=$S15),$E15/($S15-$R15+1),0) -> 0 | N15: =IF(AND(9>=$R15,9<=$S15),$E15/($S15-$R15+1),0) -> 0 | O15: =IF(AND(10>=$R15,10<=$S15),$E15/($S15-$R15+1),0) -> 0 | P15: =IF(AND(11>=$R15,11<=$S15),$E15/($S15-$R15+1),0) -> 4200 | Q15: =IF(AND(12>=$R15,12<=$S15),$E15/($S15-$R15+1),0) -> 4200 | R15: 11 | S15: 12
A16: Handover & Closeout | B16: Labor | C16: 2 | D16: 1800 | E16: =C16*D16 -> 3600 | F16: =IF(AND(1>=$R16,1<=$S16),$E16/($S16-$R16+1),0) -> 0 | G16: =IF(AND(2>=$R16,2<=$S16),$E16/($S16-$R16+1),0) -> 0 | H16: =IF(AND(3>=$R16,3<=$S16),$E16/($S16-$R16+1),0) -> 0 | I16: =IF(AND(4>=$R16,4<=$S16),$E16/($S16-$R16+1),0) -> 0 | J16: =IF(AND(5>=$R16,5<=$S16),$E16/($S16-$R16+1),0) -> 0 | K16: =IF(AND(6>=$R16,6<=$S16),$E16/($S16-$R16+1),0) -> 0 | L16: =IF(AND(7>=$R16,7<=$S16),$E16/($S16-$R16+1),0) -> 0 | M16: =IF(AND(8>=$R16,8<=$S16),$E16/($S16-$R16+1),0) -> 0 | N16: =IF(AND(9>=$R16,9<=$S16),$E16/($S16-$R16+1),0) -> 0 | O16: =IF(AND(10>=$R16,10<=$S16),$E16/($S16-$R16+1),0) -> 0 | P16: =IF(AND(11>=$R16,11<=$S16),$E16/($S16-$R16+1),0) -> 0 | Q16: =IF(AND(12>=$R16,12<=$S16),$E16/($S16-$R16+1),0) -> 3600 | R16: 12 | S16: 12
A18: EVM Roll-up | F18: wk1 | G18: wk2 | H18: wk3 | I18: wk4 | J18: wk5 | K18: wk6 | L18: wk7 | M18: wk8 | N18: wk9 | O18: wk10 | P18: wk11 | Q18: wk12
A19: Total (BAC) | E19: =SUM(tblProjectPlan[Total Budget]) -> 268650
A20: Weekly PV | F20: =SUM(F5:F16) -> 16400 | G20: =SUM(G5:G16) -> 22800 | H20: =SUM(H5:H16) -> 22800 | I20: =SUM(I5:I16) -> 25066.667 | J20: =SUM(J5:J16) -> 29666.667 | K20: =SUM(K5:K16) -> 26166.667 | L20: =SUM(L5:L16) -> 17500 | M20: =SUM(M5:M16) -> 29416.667 | ... Q20: =SUM(Q5:Q16) -> 9300
A21: Cumulative PV | F21: =SUM($F$20:F$20) -> 16400 | G21: =SUM($F$20:G$20) -> 39200 | H21: =SUM($F$20:H$20) -> 62000 | I21: =SUM($F$20:I$20) -> 87066.667 | J21: =SUM($F$20:J$20) -> 116733.33 | K21: =SUM($F$20:K$20) -> 142900 | L21: =SUM($F$20:L$20) -> 160400 | M21: =SUM($F$20:M$20) -> 189816.67 | ... Q21: =SUM($F$20:Q$20) -> 268650
A22: Current Week | E22: 6
A23: Earned Value (EV) | F23: =IF(COLUMN()-5<=$E$22,F$21*0.92,NA()) -> 15088 | G23: =IF(COLUMN()-5<=$E$22,G$21*0.92,NA()) -> 36064 | H23: =IF(COLUMN()-5<=$E$22,H$21*0.92,NA()) -> 57040 | I23: =IF(COLUMN()-5<=$E$22,I$21*0.92,NA()) -> 80101.333 | J23: =IF(COLUMN()-5<=$E$22,J$21*0.92,NA()) -> 107394.67 | K23: =IF(COLUMN()-5<=$E$22,K$21*0.92,NA()) -> 131468 | L23: =IF(COLUMN()-5<=$E$22,L$21*0.92,NA()) -> #N/A | M23: =IF(COLUMN()-5<=$E$22,M$21*0.92,NA()) -> #N/A | ... Q23: =IF(COLUMN()-5<=$E$22,Q$21*0.92,NA()) -> #N/A
A24: Actual Cost (AC) | F24: =IF(COLUMN()-5<=$E$22,F$23*1.08,NA()) -> 16295.04 | G24: =IF(COLUMN()-5<=$E$22,G$23*1.08,NA()) -> 38949.12 | H24: =IF(COLUMN()-5<=$E$22,H$23*1.08,NA()) -> 61603.2 | I24: =IF(COLUMN()-5<=$E$22,I$23*1.08,NA()) -> 86509.44 | J24: =IF(COLUMN()-5<=$E$22,J$23*1.08,NA()) -> 115986.24 | K24: =IF(COLUMN()-5<=$E$22,K$23*1.08,NA()) -> 141985.44 | L24: =IF(COLUMN()-5<=$E$22,L$23*1.08,NA()) -> #N/A | M24: =IF(COLUMN()-5<=$E$22,M$23*1.08,NA()) -> #N/A | ... Q24: =IF(COLUMN()-5<=$E$22,Q$23*1.08,NA()) -> #N/A
A25: Status Marker | F25: =IF(COLUMN()-5=$E$22,MAX($F$21:$Q$21),NA()) -> #N/A | G25: =IF(COLUMN()-5=$E$22,MAX($F$21:$Q$21),NA()) -> #N/A | H25: =IF(COLUMN()-5=$E$22,MAX($F$21:$Q$21),NA()) -> #N/A | I25: =IF(COLUMN()-5=$E$22,MAX($F$21:$Q$21),NA()) -> #N/A | J25: =IF(COLUMN()-5=$E$22,MAX($F$21:$Q$21),NA()) -> #N/A | K25: =IF(COLUMN()-5=$E$22,MAX($F$21:$Q$21),NA()) -> 268650 | L25: =IF(COLUMN()-5=$E$22,MAX($F$21:$Q$21),NA()) -> #N/A | M25: =IF(COLUMN()-5=$E$22,MAX($F$21:$Q$21),NA()) -> #N/A | ... Q25: =IF(COLUMN()-5=$E$22,MAX($F$21:$Q$21),NA()) -> #N/A
A26: PV | B26: Planned Value: authorized budget assigned to scheduled work.
A27: EVM Metric | B27: Formula / Status | C27: RAG | D27: Metric | E27: Definition | F27: Formula | G27: Favorable | H27: Unfavorable
A28: BAC | B28: =$E$19 -> 268650 | D28: CPI | E28: Cost Performance Index: cost efficiency of the project. | F28: EV / AC | G28: > 1 under budget | H28: < 1 over budget
A29: PV @ Current Week | B29: {=INDEX($F$21:$Q$21,1,$E$22)} -> 142900 | D29: SPI | E29: Schedule Performance Index: schedule efficiency of the project. | F29: EV / PV | G29: > 1 ahead of schedule | H29: < 1 behind schedule
A30: EV @ Current Week | B30: {=INDEX($F$23:$Q$23,1,$E$22)} -> 131468 | D30: EAC | E30: Estimate at Completion: forecast total cost at completion. | F30: BAC / CPI | G30: Lower than BAC is favorable | H30: Higher than BAC is unfavorable
A31: AC @ Current Week | B31: {=INDEX($F$24:$Q$24,1,$E$22)} -> 141985.44 | D31: VAC | E31: Variance at Completion: original budget less forecast completion cost. | F31: BAC - EAC | G31: Positive = under budget | H31: Negative = over budget
A32: CPI | B32: =B30/B31 -> 0.92592593 | C32: =IF(B32>=1,"🟢 Green",IF(B32>=0.95,"🟠 Amber","🔴 Red")) -> 🔴 Red | D32: EV | E32: Budgeted value of work actually performed. | F32: Mocked as 92% of cumulative PV through status week
A33: SPI | B33: =B30/B29 -> 0.92 | C33: =IF(B33>=1,"🟢 Green",IF(B33>=0.95,"🟠 Amber","🔴 Red")) -> 🔴 Red | D33: AC | E33: Actual cost incurred for work performed. | F33: Mocked as EV × 1.08 through status week
A34: EAC | B34: =B28/B32 -> 290142 | C34: =IF(B34<=B28,"🟢 Green",IF(B34<=B28*1.05,"🟠 Amber","🔴 Red")) -> 🔴 Red | D34: PV | E34: Authorized budget assigned to scheduled work. | F34: Cumulative planned value through status week
A35: VAC | B35: =B28-B34 -> -21492 | C35: =IF(B35>=0,"🟢 Green",IF(B35>=-B28*5%,"🟠 Amber","🔴 Red")) -> 🔴 Red | D35: Status Week | E35: Present time marker used in Gantt and S-curve. | F35: Project Plan E22
A36: Status | B36: =IF(B32>1,"Under budget",IF(B32<1,"Over budget","On budget"))&" / "&IF(B33>1,"Ahead of schedule",IF(B33<1,"Behind schedule","On schedule")) -> Over budget / Behind schedule | C36: =IF(OR(C32="🔴 Red",C33="🔴 Red",C35="🔴 Red",C37="🔴 Red",C38="🔴 Red"),"🔴 Red",IF(OR(C32="🟠 Amber",C33="🟠 Amber",C35="🟠 Amber",C37="🟠 Amber",C38="🟠 Amber"),"🟠 Amber","🟢 Green")) -> 🔴 Red | D36: Note | E36: EV/AC are mock assumptions so CPI/SPI/EAC/VAC can be demonstrated. | F36: Edit EV/AC rows to reflect actuals.
A37: SV | B37: =B30-B29 -> -11432 | C37: =IF(B37>=0,"🟢 Green",IF(B37>=-B28*5%,"🟠 Amber","🔴 Red")) -> 🟠 Amber
A38: CV | B38: =B30-B31 -> -10517.44 | C38: =IF(B38>=0,"🟢 Green",IF(B38>=-B28*5%,"🟠 Amber","🔴 Red")) -> 🟠 Amber
A39: Variance Note | B39: ="SV "&TEXT(B37,"$#,##0;-$#,##0")&" / CV "&TEXT(B38,"$#,##0;-$#,##0") -> SV -$11,432 / CV -$10,517 | C39: =C36 -> 🔴 Red

Sheet EVM Dashboard
A1: EVM Dashboard — Gantt + Planned Value S-Curve
A2: The Gantt grid and S-curve share the same weekly PV formulas; the red dotted marker indicates the present time / status week.
A4: BAC | D4: PV @ Current Week | G4: % Planned Complete | J4: Status Week | M4: CPI / SPI
A5: ='Project Plan'!E19 -> 268650 | D5: {=INDEX('Project Plan'!F21:Q21,1,'Project Plan'!E22)} -> 142900 | G5: =D5/A5 -> 0.53191885 | J5: ='Project Plan'!E22 -> 6 | M5: =TEXT('Project Plan'!B32,"0.00")&" / "&TEXT('Project Plan'!B33,"0.00") -> 0.93 / 0.92
M6: ='Project Plan'!C36 -> 🔴 Red
A7: Story in Brief
A8: ="At status week "&'Project Plan'!E22&", the baseline plan should have earned "&TEXT(D5,"$#,##0")&" of planned value, or "&TEXT(G5,"0.0%")&" of the BAC. The bars below show which activities are scheduled before and after the status date, while the S-curve converts those same weekly bars into cumulative planned value." -> At status week 6, the baseline plan should have earned $142,900 of planned value, or 53.2% of the BAC. The bars below show which activities are scheduled before and after the status date, while the S-curve converts those same weekly bars into cumulative planned value.
A12: Gantt Baseline with Present-Time Marker
A13: Activity | B13: Type | C13: wk1 | D13: wk2 | E13: wk3 | F13: wk4 | G13: wk5 | H13: wk6 | I13: wk7 | J13: wk8 | K13: wk9 | L13: wk10 | M13: wk11 | N13: wk12
A14: ='Project Plan'!A5 -> Project Management | B14: ='Project Plan'!B5 -> Labor | C14: ■ | D14: ■ | E14: ■ | F14: ■ | G14: ■ | H14: ■ | I14: ■ | J14: ■ | K14: ■ | L14: ■ | M14: ■ | N14: ■
A15: ='Project Plan'!A6 -> Site Survey & Mobilization | B15: ='Project Plan'!B6 -> Labor | C15: ■
A16: ='Project Plan'!A7 -> Design & Engineering | B16: ='Project Plan'!B7 -> Labor | C16: ■ | D16: ■ | E16: ■
A17: ='Project Plan'!A8 -> Procurement - Materials | B17: ='Project Plan'!B8 -> Material | D17: ■ | E17: ■ | F17: ■ | G17: ■
A18: ='Project Plan'!A9 -> Demolition & Prep | B18: ='Project Plan'!B9 -> Labor | D18: ■ | E18: ■ | F18: ■
A19: ='Project Plan'!A10 -> Electrical Rough-In | B19: ='Project Plan'!B10 -> Labor | F19: ■ | G19: ■ | H19: ■
A20: ='Project Plan'!A11 -> HVAC Installation | B20: ='Project Plan'!B11 -> Subcontractor | G20: ■ | H20: ■ | I20: ■ | J20: ■
A21: ='Project Plan'!A12 -> Partitions & Drywall | B21: ='Project Plan'!B12 -> Subcontractor | H21: ■ | I21: ■ | J21: ■ | K21: ■
A22: ='Project Plan'!A13 -> Flooring | B22: ='Project Plan'!B13 -> Material | J22: ■ | K22: ■ | L22: ■
A23: ='Project Plan'!A14 -> Fixtures & Furniture | B23: ='Project Plan'!B14 -> Material | K23: ■ | L23: ■ | M23: ■
A24: ='Project Plan'!A15 -> Testing / Commissioning | B24: ='Project Plan'!B15 -> Labor | M24: ■ | N24: ■
A25: ='Project Plan'!A16 -> Handover & Closeout | B25: ='Project Plan'!B16 -> Labor | N25: ■
A30: Week | B30: BAC | C30: EAC | D30: PV | E30: EV | F30: AC | G30: VAC | H30: Status Timeline | I30: Data Label | J30: SV | K30: CV | M30: Forecast / Variance
A31: wk1 | B31: ='Project Plan'!$E$19 -> 268650 | C31: ='Project Plan'!$B$34 -> 290142 | D31: ='Project Plan'!F21 -> 16400 | E31: ='Project Plan'!F23 -> 15088 | F31: ='Project Plan'!F24 -> 16295.04 | G31: ='Project Plan'!$B$35 -> -21492 | H31: =IF(ROW()-30='Project Plan'!$E$22,MAX($B$31:$F$42)*1.08,0) -> 0 | I31: =IF(ROW()-30='Project Plan'!$E$22,"Status wk"&'Project Plan'!$E$22,"") | J31: =IF(ROW()-30='Project Plan'!$E$22,'Project Plan'!$B$37,NA()) -> #N/A | K31: =IF(ROW()-30='Project Plan'!$E$22,'Project Plan'!$B$38,NA()) -> #N/A | M31: Metric | N31: Value / Meaning
A32: wk2 | B32: ='Project Plan'!$E$19 -> 268650 | C32: ='Project Plan'!$B$34 -> 290142 | D32: ='Project Plan'!G21 -> 39200 | E32: ='Project Plan'!G23 -> 36064 | F32: ='Project Plan'!G24 -> 38949.12 | G32: ='Project Plan'!$B$35 -> -21492 | H32: =IF(ROW()-30='Project Plan'!$E$22,MAX($B$31:$F$42)*1.08,0) -> 0 | I32: =IF(ROW()-30='Project Plan'!$E$22,"Status wk"&'Project Plan'!$E$22,"") | J32: =IF(ROW()-30='Project Plan'!$E$22,'Project Plan'!$B$37,NA()) -> #N/A | K32: =IF(ROW()-30='Project Plan'!$E$22,'Project Plan'!$B$38,NA()) -> #N/A | M32: EAC | N32: ='Project Plan'!C34&" "&TEXT('Project Plan'!B34,"$#,##0")&" forecast total cost" -> 🔴 Red $290,142 forecast total cost
A33: wk3 | B33: ='Project Plan'!$E$19 -> 268650 | C33: ='Project Plan'!$B$34 -> 290142 | D33: ='Project Plan'!H21 -> 62000 | E33: ='Project Plan'!H23 -> 57040 | F33: ='Project Plan'!H24 -> 61603.2 | G33: ='Project Plan'!$B$35 -> -21492 | H33: =IF(ROW()-30='Project Plan'!$E$22,MAX($B$31:$F$42)*1.08,0) -> 0 | I33: =IF(ROW()-30='Project Plan'!$E$22,"Status wk"&'Project Plan'!$E$22,"") | J33: =IF(ROW()-30='Project Plan'!$E$22,'Project Plan'!$B$37,NA()) -> #N/A | K33: =IF(ROW()-30='Project Plan'!$E$22,'Project Plan'!$B$38,NA()) -> #N/A | M33: VAC | N33: ='Project Plan'!C35&" "&TEXT('Project Plan'!B35,"$#,##0;-$#,##0")&" BAC - EAC" -> 🔴 Red -$21,492 BAC - EAC
A34: wk4 | B34: ='Project Plan'!$E$19 -> 268650 | C34: ='Project Plan'!$B$34 -> 290142 | D34: ='Project Plan'!I21 -> 87066.667 | E34: ='Project Plan'!I23 -> 80101.333 | F34: ='Project Plan'!I24 -> 86509.44 | G34: ='Project Plan'!$B$35 -> -21492 | H34: =IF(ROW()-30='Project Plan'!$E$22,MAX($B$31:$F$42)*1.08,0) -> 0 | I34: =IF(ROW()-30='Project Plan'!$E$22,"Status wk"&'Project Plan'!$E$22,"") | J34: =IF(ROW()-30='Project Plan'!$E$22,'Project Plan'!$B$37,NA()) -> #N/A | K34: =IF(ROW()-30='Project Plan'!$E$22,'Project Plan'!$B$38,NA()) -> #N/A | M34: SV | N34: ='Project Plan'!C37&" "&TEXT('Project Plan'!B37,"$#,##0;-$#,##0")&" EV - PV" -> 🟠 Amber -$11,432 EV - PV
A35: wk5 | B35: ='Project Plan'!$E$19 -> 268650 | C35: ='Project Plan'!$B$34 -> 290142 | D35: ='Project Plan'!J21 -> 116733.33 | E35: ='Project Plan'!J23 -> 107394.67 | F35: ='Project Plan'!J24 -> 115986.24 | G35: ='Project Plan'!$B$35 -> -21492 | H35: =IF(ROW()-30='Project Plan'!$E$22,MAX($B$31:$F$42)*1.08,0) -> 0 | I35: =IF(ROW()-30='Project Plan'!$E$22,"Status wk"&'Project Plan'!$E$22,"") | J35: =IF(ROW()-30='Project Plan'!$E$22,'Project Plan'!$B$37,NA()) -> #N/A | K35: =IF(ROW()-30='Project Plan'!$E$22,'Project Plan'!$B$38,NA()) -> #N/A | M35: CV | N35: ='Project Plan'!C38&" "&TEXT('Project Plan'!B38,"$#,##0;-$#,##0")&" EV - AC" -> 🟠 Amber -$10,517 EV - AC
A36: wk6 | B36: ='Project Plan'!$E$19 -> 268650 | C36: ='Project Plan'!$B$34 -> 290142 | D36: ='Project Plan'!K21 -> 142900 | E36: ='Project Plan'!K23 -> 131468 | F36: ='Project Plan'!K24 -> 141985.44 | G36: ='Project Plan'!$B$35 -> -21492 | H36: =IF(ROW()-30='Project Plan'!$E$22,MAX($B$31:$F$42)*1.08,0) -> #N/A | I36: =IF(ROW()-30='Project Plan'!$E$22,"Status wk"&'Project Plan'!$E$22,"") -> Status wk6 | J36: =IF(ROW()-30='Project Plan'!$E$22,'Project Plan'!$B$37,NA()) -> -11432 | K36: =IF(ROW()-30='Project Plan'!$E$22,'Project Plan'!$B$38,NA()) -> -10517.44 | M36: CPI | N36: ='Project Plan'!C32&" "&TEXT('Project Plan'!B32,"0.00")&" cost efficiency" -> 🔴 Red 0.93 cost efficiency
A37: wk7 | B37: ='Project Plan'!$E$19 -> 268650 | C37: ='Project Plan'!$B$34 -> 290142 | D37: ='Project Plan'!L21 -> 160400 | E37: ='Project Plan'!L23 -> #N/A | F37: ='Project Plan'!L24 -> #N/A | G37: ='Project Plan'!$B$35 -> -21492 | H37: =IF(ROW()-30='Project Plan'!$E$22,MAX($B$31:$F$42)*1.08,0) -> 0 | I37: =IF(ROW()-30='Project Plan'!$E$22,"Status wk"&'Project Plan'!$E$22,"") | J37: =IF(ROW()-30='Project Plan'!$E$22,'Project Plan'!$B$37,NA()) -> #N/A | K37: =IF(ROW()-30='Project Plan'!$E$22,'Project Plan'!$B$38,NA()) -> #N/A | M37: SPI | N37: ='Project Plan'!C33&" "&TEXT('Project Plan'!B33,"0.00")&" schedule efficiency" -> 🔴 Red 0.92 schedule efficiency
A38: wk8 | B38: ='Project Plan'!$E$19 -> 268650 | C38: ='Project Plan'!$B$34 -> 290142 | D38: ='Project Plan'!M21 -> 189816.67 | E38: ='Project Plan'!M23 -> #N/A | F38: ='Project Plan'!M24 -> #N/A | G38: ='Project Plan'!$B$35 -> -21492 | H38: =IF(ROW()-30='Project Plan'!$E$22,MAX($B$31:$F$42)*1.08,0) -> 0 | I38: =IF(ROW()-30='Project Plan'!$E$22,"Status wk"&'Project Plan'!$E$22,"") | J38: =IF(ROW()-30='Project Plan'!$E$22,'Project Plan'!$B$37,NA()) -> #N/A | K38: =IF(ROW()-30='Project Plan'!$E$22,'Project Plan'!$B$38,NA()) -> #N/A | M38: Status | N38: ='Project Plan'!C36&" "&'Project Plan'!B36 -> 🔴 Red Over budget / Behind schedule
A39: wk9 | B39: ='Project Plan'!$E$19 -> 268650 | C39: ='Project Plan'!$B$34 -> 290142 | D39: ='Project Plan'!N21 -> 220233.33 | E39: ='Project Plan'!N23 -> #N/A | F39: ='Project Plan'!N24 -> #N/A | G39: ='Project Plan'!$B$35 -> -21492 | H39: =IF(ROW()-30='Project Plan'!$E$22,MAX($B$31:$F$42)*1.08,0) -> 0 | I39: =IF(ROW()-30='Project Plan'!$E$22,"Status wk"&'Project Plan'!$E$22,"") | J39: =IF(ROW()-30='Project Plan'!$E$22,'Project Plan'!$B$37,NA()) -> #N/A | K39: =IF(ROW()-30='Project Plan'!$E$22,'Project Plan'!$B$38,NA()) -> #N/A
A40: wk10 | B40: ='Project Plan'!$E$19 -> 268650 | C40: ='Project Plan'!$B$34 -> 290142 | D40: ='Project Plan'!O21 -> 243650 | E40: ='Project Plan'!O23 -> #N/A | F40: ='Project Plan'!O24 -> #N/A | G40: ='Project Plan'!$B$35 -> -21492 | H40: =IF(ROW()-30='Project Plan'!$E$22,MAX($B$31:$F$42)*1.08,0) -> 0 | I40: =IF(ROW()-30='Project Plan'!$E$22,"Status wk"&'Project Plan'!$E$22,"") | J40: =IF(ROW()-30='Project Plan'!$E$22,'Project Plan'!$B$37,NA()) -> #N/A | K40: =IF(ROW()-30='Project Plan'!$E$22,'Project Plan'!$B$38,NA()) -> #N/A | M40: RAG Legend | N40: Rule of thumb
A41: wk11 | B41: ='Project Plan'!$E$19 -> 268650 | C41: ='Project Plan'!$B$34 -> 290142 | D41: ='Project Plan'!P21 -> 259350 | E41: ='Project Plan'!P23 -> #N/A | F41: ='Project Plan'!P24 -> #N/A | G41: ='Project Plan'!$B$35 -> -21492 | H41: =IF(ROW()-30='Project Plan'!$E$22,MAX($B$31:$F$42)*1.08,0) -> 0 | I41: =IF(ROW()-30='Project Plan'!$E$22,"Status wk"&'Project Plan'!$E$22,"") | J41: =IF(ROW()-30='Project Plan'!$E$22,'Project Plan'!$B$37,NA()) -> #N/A | K41: =IF(ROW()-30='Project Plan'!$E$22,'Project Plan'!$B$38,NA()) -> #N/A | M41: 🟢 Green | N41: On track / favorable
A42: wk12 | B42: ='Project Plan'!$E$19 -> 268650 | C42: ='Project Plan'!$B$34 -> 290142 | D42: ='Project Plan'!Q21 -> 268650 | E42: ='Project Plan'!Q23 -> #N/A | F42: ='Project Plan'!Q24 -> #N/A | G42: ='Project Plan'!$B$35 -> -21492 | H42: =IF(ROW()-30='Project Plan'!$E$22,MAX($B$31:$F$42)*1.08,0) -> 0 | I42: =IF(ROW()-30='Project Plan'!$E$22,"Status wk"&'Project Plan'!$E$22,"") | J42: =IF(ROW()-30='Project Plan'!$E$22,'Project Plan'!$B$37,NA()) -> #N/A | K42: =IF(ROW()-30='Project Plan'!$E$22,'Project Plan'!$B$38,NA()) -> #N/A | M42: 🟠 Amber | N42: Watch: within tolerance
M43: 🔴 Red | N43: Action required
A44: EVM Performance Metrics
A45: Metric | B45: Value | C45: Interpretation | D45: Formula / Meaning | E45: RAG
A46: CPI | B46: ='Project Plan'!B32 -> 0.92592593 | C46: =IF(B46>1,"Under budget",IF(B46<1,"Over budget","On budget")) -> Over budget | D46: EV / AC: >1 under budget, <1 over budget | E46: =IF(B46>=1,"🟢 Green",IF(B46>=0.95,"🟠 Amber","🔴 Red")) -> 🔴 Red
A47: SPI | B47: ='Project Plan'!B33 -> 0.92 | C47: =IF(B47>1,"Ahead of schedule",IF(B47<1,"Behind schedule","On schedule")) -> Behind schedule | D47: EV / PV: >1 ahead of schedule, <1 behind schedule | E47: =IF(B47>=1,"🟢 Green",IF(B47>=0.95,"🟠 Amber","🔴 Red")) -> 🔴 Red
A48: EAC | B48: ='Project Plan'!B34 -> 290142 | C48: =IF(B48<'Project Plan'!B28,"Forecast under BAC","Forecast over BAC") -> Forecast over BAC | D48: BAC / CPI forecast completion cost | E48: =IF(B48<='Project Plan'!B28,"🟢 Green",IF(B48<='Project Plan'!B28*1.05,"🟠 Amber","🔴 Red")) -> 🔴 Red
...
