Workbook
Name Actual_Cost_Values: tbl_Fact_Actual_Costs[Actual_Cost]
Name Actual_Hours_Values: tbl_Fact_Actual_Costs[Hours_Worked]
Name Baseline_PV_Values: tbl_Fact_Baseline_PV[Planned_Value]
Name Control_BAC: Dim_Project!$E$2
Name Control_CPI_SPI_Green: Setup!$B$13
Name Control_CPI_SPI_Red: Setup!$B$12
Name Control_Progress_Amber: Setup!$B$14
Name Control_Progress_Green: Setup!$B$15
Name Control_Project_End: Dim_Project!$D$2
Name Control_Project_ID: Dim_Project!$A$2
Name Control_Project_Name: Dim_Project!$B$2
Name Control_Project_Start: Dim_Project!$C$2
Name Control_Sector: Dim_Project!$F$2
Name Control_Status_Date: Setup!$B$9
Name Input_Actual_Costs: tbl_Fact_Actual_Costs[]
Name Input_Baseline_PV: tbl_Fact_Baseline_PV[]
Name Input_Calendar: tbl_Dim_Calendar[]
Name Input_Physical_Progress: tbl_Fact_Physical_Progress[]
Name Input_Project: tbl_Dim_Project[]
Name Input_Resources: tbl_Dim_Resource[]
Name Input_WBS: tbl_Dim_WBS[]
Name Progress_Pct_Values: tbl_Fact_Physical_Progress[Physical_Progress_Pct]
Name Slicer_Category: #N/A
Name Slicer_Measure: #N/A
Name Slicer_Month_Name: #N/A
Name Slicer_Owner: #N/A
Name Slicer_Owner1: #N/A
Name Slicer_Owner2: #N/A
Name Slicer_RAG: #N/A
Name Slicer_RAG1: #N/A
Name Slicer_RAG2: #N/A
Name Slicer_RAG3: #N/A
Name Slicer_Resource_ID: #N/A
Name Slicer_Role: #N/A
Name Slicer_Status: #N/A
Name Slicer_Status1: #N/A
Name Slicer_Status2: #N/A
Name Slicer_Status3: #N/A
Name Slicer_Status4: #N/A
Name Slicer_Type: #N/A
Name Slicer_Type1: #N/A
Name Slicer_Type2: #N/A
Name Slicer_Type3: #N/A
Name Slicer_WBS_ID: #N/A
Name Slicer_WBS_ID1: #N/A
Name Slicer_WBS_ID2: #N/A
Name Slicer_WBS_ID3: #N/A
Name Slicer_WBS_ID4: #N/A
Name Slicer_Week: #N/A
Name Slicer_Week_Number: #N/A
Name WBS_Activities: tbl_Dim_WBS[Activity_Name]
Name WBS_Budgets: tbl_Dim_WBS[Total_Budget]
Name WBS_IDs: tbl_Dim_WBS[WBS_ID]
Name WBS_Types: tbl_Dim_WBS[Type]

Sheet Cover
A1: Office Fit-Out Project Control Workbook
A2: PM-EVM compliant workbook map: setup controls, task plan, Gantt, EVM S-curve, dashboard, source dimensions, and fact tables.
A4: Sheet | B4: Purpose | D4: Tab Color Legend
A5: Setup | B5: Project-level controls: project metadata, status date, reporting period, and RAG thresholds. | D5: Color | E5: Category | F5: Sheets
A6: Task Plan | B6: Integrated WBS/task control table linking baseline dates, BAC, progress, AC, EV, variances, forecasts, and RAG status. | E6: Navigation / Reference | F6: Cover, Glossary
A7: EVM | B7: Weekly EVM reporting table with cumulative PV, AC, EV, SV, CV, SPI, CPI, EAC, ETC, and VAC. | E7: Method / Governance | F7: Method Roadmap, PID, PM-EVM Compliance, Review
A8: EVM Charts | B8: Baseline Gantt schedule and EVM S-curve generated from the same WBS, budget, progress, and actual-cost data. | E8: Controls / Planning | F8: Setup, Task Plan, Task Capture, Resource Grid
A9: EVM Dashboard | B9: Management view with KPI tiles, WBS performance breakdown, trends, and RAG coloring. | E9: Management Outputs | F9: EVM Dashboard, EVM, EVM Charts
A10: PM-EVM Compliance | B10: Checklist mapping the workbook to the attached PM-EVM guideline. | E10: Dimension Data | F10: Dim_Project, Dim_WBS, Dim_Resource, Dim_Calendar
A11: Dim_* / Fact_* | B11: Star-schema source data used by the live formulas and charts. | E11: Fact Data | F11: Fact_Baseline_PV, Fact_Actual_Costs, Fact_Physical_Progress
A12: Glossary | B12: Definitions for the EVM, WBS, Gantt, schedule, cost, RAG, and data-model terms used in the workbook.
A13: Method Roadmap | B13: 12-step project management method mapped to workbook sheets and current project controls. | D13: Input / Control / Output Classification
A14: PID | B14: Project Initiation Document template with business case, scope, controls, risk and financial sections. | D14: Class | E14: Meaning | F14: Sheets
A15: Task Capture | B15: Task-list brainstorming sheet based on the attached list-the-tasks method, linked to current WBS. | D15: Input | E15: Source data or user-entered templates that feed calculations. | F15: Dim_Project, Dim_WBS, Dim_Resource, Dim_Calendar, Fact_Baseline_PV, Fact_Actual_Costs, Fact_Physical_Progress, PID, Task Capture, Review
A16: Resource Grid | B16: Weekly hours/cost resource allocation grid adapted from the attached Gantt template. | D16: Control | E16: Assumptions, governance, validation, methods, and planning logic that manage how inputs are interpreted. | F16: Setup, Method Roadmap, PM-EVM Compliance, Task Plan, Resource Grid
A17: Review | B17: GOOD / BAD / BETTER review template and action log. | D17: Output | E17: Management-facing reports, charts, dashboards, and reference views produced from inputs and controls. | F17: Cover, Glossary, EVM Dashboard, EVM, EVM Charts
A18: Garden Gantt Model | B18: Attached garden-office Gantt template implemented with current project weekly hours and cost data.
A19: PERT Diagram | B19: Visio-style PERT network diagram reflecting the current WBS, schedule, progress and RAG status. | D19: Sheet | E19: Class | F19: Reason
A20: Red Actions | B20: Recommended recovery actions for all current red RAG WBS items and control risks. | D20: Cover | E20: Output | F20: Workbook navigation and summary.
A21: Pivot Summary | B21: High-level PivotTables and descriptive statistics for project cost, schedule, EVM, and RAG performance. | D21: Glossary | E21: Output
D22: Review | E22: Input
D23: Setup | E23: Control
D24: PID | E24: Input
D25: Method Roadmap | E25: Control
D26: PM-EVM Compliance | E26: Control
D27: Task Plan | E27: Control
D28: Task Capture | E28: Input
D29: EVM Dashboard | E29: Output
D30: Resource Grid | E30: Control
D31: Dim_Project | E31: Input
D32: Dim_WBS | E32: Input
D33: Dim_Resource | E33: Input
... D39: EVM Charts | E39: Output

Sheet Slicer Controls
A1: Workbook Slicer Controls
A2: Use this panel to filter the source Excel Tables directly. Slicers are grouped by reporting outputs, source inputs, and governance/control tables.
A4: MANAGEMENT OUTPUTS
A30: SOURCE INPUTS
A56: GOVERNANCE / CONTROL
A105: Slicer name | B105: Source area | C105: Field | D105: Caption
A106: slc_Dashboard_Status | B106: Dashboard | C106: Status | D106: Dashboard: Status
A107: slc_Dashboard_Type | B107: Dashboard | C107: Type | D107: Dashboard: Type
A108: slc_TaskPlan_Status | B108: Task Plan | C108: Status | D108: Task Plan: Status
A109: slc_TaskPlan_Type | B109: Task Plan | C109: Type | D109: Task Plan: Type
A110: slc_TaskPlan_WBSID | B110: Task Plan | C110: WBS ID | D110: Task Plan: WBS ID
A111: slc_EVM_Status | B111: EVM | C111: Status | D111: EVM: Status
A112: slc_EVM_Week | B112: EVM | C112: Week | D112: EVM: Week
A113: slc_PERT_RAG | B113: PERT | C113: RAG | D113: PERT: RAG
A114: slc_Resource_Measure | B114: Resource Grid | C114: Measure | D114: Resource Grid: Measure
A115: slc_Resource_RAG | B115: Resource Grid | C115: RAG | D115: Resource Grid: RAG
A116: slc_Calendar_Month | B116: Calendar | C116: Month | D116: Calendar: Month
... A133: slc_Method_Owner | B133: Method Roadmap | C133: Owner | D133: Method Roadmap: Owner

Sheet Glossary
A1: Project Control Glossary
A2: Definitions for the EVM, WBS, Gantt, schedule, cost, and RAG terms used across this workbook.
A4: Category | B4: Term | C4: Abbrev. | D4: Definition | E4: Workbook reference
A5: Project setup | B5: Project Start | D5: Approved start date for the project control baseline. | E5: Setup!B7 / Dim_Project!C2
A6: Project setup | B6: Project End | D6: Approved planned end date for the project. | E6: Setup!B8 / Dim_Project!D2
A7: Project setup | B7: Status Date | D7: Cut-off date for reported progress, actual costs, and EVM metrics. | E7: Setup!B9 / EVM Dashboard!B4
A8: Scope / WBS | B8: Work Breakdown Structure | C8: WBS | D8: Hierarchical breakdown of project scope into controllable work packages or activities. | E8: Dim_WBS / Task Plan
A9: Scope / WBS | B9: WBS ID | D9: Unique identifier used to connect WBS activities to baseline PV, actual costs, and progress facts. | E9: Dim_WBS!A:A
A10: Scope / WBS | B10: Activity / Task | D10: A controllable unit of project work with budget, schedule, progress, and cost tracking. | E10: Task Plan!C:C
A11: Schedule | B11: Baseline Start | D11: Planned start date for a WBS activity from the approved baseline. | E11: Task Plan!E:E
A12: Schedule | B12: Baseline Finish | D12: Planned finish date for a WBS activity from the approved baseline. | E12: Task Plan!F:F
A13: Schedule | B13: Duration Days | D13: Calendar-day span between baseline start and finish dates. | E13: Task Plan!G:G
A14: Schedule | B14: Gantt Chart | D14: Timeline chart showing planned activity timing and duration by WBS activity. | E14: EVM Charts!Gantt Schedule
A15: Cost / EVM | B15: Budget at Completion | C15: BAC | D15: Approved total budget for the project or WBS activity. | E15: Setup!B11 / Task Plan!H:H
A16: Cost / EVM | B16: Planned Value | C16: PV | D16: Budgeted value of work planned to be complete by a given date. | E16: Task Plan!I:I / EVM!C:C
A17: Cost / EVM | B17: Actual Cost | C17: AC | D17: Actual cost incurred by a given date. | E17: Task Plan!J:J / EVM!D:D
A18: Cost / EVM | B18: Physical Progress | C18: Progress % | D18: Latest reported percent complete for each WBS activity as of the status date. | E18: Task Plan!K:K
A19: Cost / EVM | B19: Earned Value | C19: EV | D19: Budgeted value of the work actually completed; calculated as BAC × progress. | E19: Task Plan!L:L / EVM!E:E
A20: Variance | B20: Schedule Variance | C20: SV | D20: EV minus PV; negative means less work completed than planned. | E20: Task Plan!M:M / EVM!F:F
A21: Variance | B21: Cost Variance | C21: CV | D21: EV minus AC; negative means cost overrun for completed work. | E21: Task Plan!N:N / EVM!G:G
A22: Performance index | B22: Schedule Performance Index | C22: SPI | D22: EV divided by PV; below 1.0 indicates unfavorable schedule efficiency. | E22: Task Plan!O:O / EVM!H:H
A23: Performance index | B23: Cost Performance Index | C23: CPI | D23: EV divided by AC; below 1.0 indicates unfavorable cost efficiency. | E23: Task Plan!P:P / EVM!I:I
A24: Forecast | B24: Estimate at Completion | C24: EAC | D24: Forecast final project or WBS cost, typically BAC divided by CPI. | E24: Task Plan!Q:Q / EVM!K:K
A25: Forecast | B25: Estimate to Complete | C25: ETC | D25: Forecast remaining cost to complete the work; EAC minus AC. | E25: Task Plan!R:R / EVM!L:L
A26: Forecast | B26: Variance at Completion | C26: VAC | D26: Expected budget variance at completion; BAC minus EAC. | E26: Task Plan!S:S / EVM!M:M
A27: Chart | B27: EVM S-Curve | D27: Line chart comparing cumulative PV, EV, and AC over time. | E27: EVM Charts!EVM S-Curve
A28: RAG | B28: Green | D28: Good condition: on/above plan, favorable variance, or acceptable performance threshold. | E28: Setup!A18:D18
A29: RAG | B29: Amber | D29: Watch condition: close to threshold or mid-progress; monitor closely. | E29: Setup!A19:D19
A30: RAG | B30: Red | D30: Action condition: negative variance, low progress, CPI/SPI below threshold, or overrun. | E30: Setup!A20:D20
A31: Reporting | B31: Dashboard | D31: Management summary view showing KPIs, WBS performance, trend data, and RAG status. | E31: EVM Dashboard!A1:P47
A32: Reporting | B32: Tie-out | D32: Validation that dashboard KPIs match the detailed EVM reporting table at the status date. | E32: EVM!H19:M25
A33: Data model | B33: Dimension Table | C33: Dim | D33: Reference table describing projects, WBS, resources, or calendar dates. | E33: Dim_Project / Dim_WBS / Dim_Resource / Dim_Calendar
A34: Data model | B34: Fact Table | C34: Fact | D34: Transaction or event table containing planned values, actual costs, or progress observations. | E34: Fact_Baseline_PV / Fact_Actual_Costs / Fact_Physical_Progress
A36: Workbook classification | B36: Input | D36: Source data or user-entered content that feeds project calculations and reports. | E36: Cover!D13:H39
A37: Workbook classification | B37: Control | D37: Assumptions, thresholds, validation, governance, and planning logic used to interpret inputs. | E37: Cover!D13:H39
A38: Workbook classification | B38: Output | D38: Reports, charts, dashboards, and references produced from the input data and control logic. | E38: Cover!D13:H39

Sheet Review
A1: Project Review & Lessons
A2: Review template from attachment: GOOD / BAD / BETTER plus action log for plan adjustments and lessons learned.
A4: Project Description | B4: =Control_Project_Name -> Office Fit-Out
A5: Project Period | B5: =TEXT(Control_Project_Start,"yyyy-mm-dd")&" to "&TEXT(Control_Project_End,"yyyy-mm-dd") -> 2026-05-04 to 2026-07-26
A6: Status Date | B6: =Control_Status_Date -> 46203
A7: Review Owner | B7: Frank Ellingsen
A8: Review Date | B8: =TODAY() -> 46238
A10: GOOD — what went well that others should repeat?
A15: BAD — what mistakes were made or unexpected issues occurred?
A20: BETTER / ACTION LOG | B20: Owner | C20: Due date | D20: Decision required? | E20: RAG | F20: Linked workbook evidence
A21: Investigate schedule slippage driving SPI below 1.0 | B21: Project Controls | D21: Yes | E21: Red | F21: EVM Dashboard!J10 / Task Plan!O17
A22: Review cost efficiency and current EAC forecast | B22: Project Controls | D22: Yes | E22: Red | F22: EVM Dashboard!G10 / Task Plan!Q17
A23: Confirm mitigation for red WBS activities in Gantt | B23: Project Manager | D23: Yes | E23: Red | F23: EVM Charts!Gantt Schedule
A24: Check future material/subcontractor dependencies | B24: Planner | D24: No | E24: Amber | F24: Task Plan / Resource Grid
A25: Capture lessons from completed WBS items | B25: Project Team | D25: No | E25: Amber | F25: Task Capture / Review
A30: Review source | B30: 13.1.2 Review Template.pdf

Sheet PID
A1: Project Initiation Document (PID)
A2: PID template from the attached method, prefilled with current workbook metadata where available. Fill yellow cells during project definition.
A4: Project header
A5: Project Name | B5: =Control_Project_Name -> Office Fit-Out
A6: Project Number | B6: =Control_Project_ID -> P101
A7: Project Risk Level | B7: H/M/L
A8: Prepared by | B8: Frank Ellingsen
A9: Date | B9: =TODAY() -> 46238
A10: Persons consulted
A11: Key Driver | B11: Cost / Quality / Time
A13: 1. Business Case
A14: Why this project; why now; options considered; what if we do not do it; benefits; payback period.
A18: 2.1 In Scope / Included
A19: Work and deliverables included in the project.
A23: 2.2 Out of Scope / Excluded
A24: Work explicitly excluded from the project.
A28: 2.3 Dependencies
A29: How the project impacts or is impacted by other projects or programmes.
A33: 2.4 Constraints
A34: Deadlines, budget limits, resource limitations or other delivery constraints.
A38: 2.5 Assumptions
A39: Assumptions currently being used for planning.
... A49: How progress will be reported, frequency, method and responsibility.
A53: Frequency / timing | B53: How control is reported | C53: Responsibility | D53: Next report date | E53: Status
A54: Weekly | B54: EVM Dashboard + EVM Charts | C54: Project Controls | E54: Active
A55: Stage end | B55: PID / Review pack | C55: Project Manager | E55: Planned
A56: Monthly | B56: Board summary | C56: Project Manager | E56: Planned
A58: 5. Risk Control
A59: Project risks and containment measures.
A63: Project Risk | B63: Containment Measures | C63: Owner | D63: Due Date | E63: RAG
A64: Schedule slippage | B64: Monitor SPI and Gantt status line; escalate red WBS tasks. | C64: Project Controls | E64: Red
A65: Cost overrun | B65: Monitor CPI/CV/EAC and review WBS cost drivers. | C65: Project Controls | E65: Red
A66: Resource availability | B66: Use weekly Resource Grid to identify conflicts. | C66: Resource Manager | E66: Amber
A67: Scope creep | B67: Confirm in/out of scope and change-control route in PID. | C67: Project Manager | E67: Amber
A68: Quality issue | B68: Define acceptance criteria and quality checks by task. | C68: Project Manager | E68: Amber
A69: Supplier delay | B69: Track procurement/material activities and delivery milestones. | C69: Project Manager | E69: Amber
A72: 6. Financial Implications
A73: Quarterly/annual financial profile adapted from the PID template; Year 1 is linked to the current baseline planned value.
A74: Financial Implications | B74: Q1 | C74: Q2 | D74: Q3 | E74: Q4 | F74: Total
A75: Amount Year 1 | B75: =SUMIFS(Fact_Baseline_PV!$C$2:$C$44,Fact_Baseline_PV!$A$2:$A$44,"<="&DATE(2026,6,30)) -> 220233.34 | C75: =SUMIFS(Fact_Baseline_PV!$C$2:$C$44,Fact_Baseline_PV!$A$2:$A$44,">"&DATE(2026,6,30),Fact_Baseline_PV!$A$2:$A$44,"<="&DATE(2026,9,30)) -> 48416.66 | D75: 0 | E75: 0 | F75: =SUM(B75:E75) -> 268650
...

Sheet Method Roadmap
A1: 12-Step Project Management Method Roadmap
A2: Course method embedded into the workbook: define, list, sequence, estimate, check, Gantt, resource, risk, monitor progress/cost, adjust, and review.
A4: Step | B4: Method step | C4: Purpose | D4: Workbook implementation | E4: Primary sheet / range | F4: Owner | G4: Status | H4: Source
A5: 1 | B5: Define the project | C5: Create the project definition and controls. | D5: PID template added with live project metadata. | E5: PID!A1:H50 | F5: Project Manager | G5: Active | H5: 1.2 12 Step Process / 2.1.2 PID template
A6: 2 | B6: List the tasks | C6: Capture all tasks without initially worrying about order, cost, or time. | D6: Task Capture sheet added; WBS imported from current Dim_WBS and grouped by type. | E6: Task Capture!A4:J18 | F6: Project Team | G6: Active | H6: 3.1.5 List the Tasks / 4.1 List of Tasks
A7: 3 | B7: Establish task order | C7: Convert brainstormed tasks into planned sequencing. | D7: Task Plan and Gantt use WBS order and baseline dates. | E7: Task Plan!A4:T17 | F7: Planner | G7: Active | H7: 1.2 12 Step Process
A8: 4 | B8: Estimate time | C8: Estimate duration by task. | D8: Baseline start, finish, and duration calculated per WBS. | E8: Task Plan!E5:G17 | F8: Planner | G8: Active | H8: 1.2 12 Step Process
A9: 5 | B9: Margin check & reality check | C9: Check whether dates, budget, and resource assumptions are feasible. | D9: Status tie-out, EVM checks, and RAG indicators added. | E9: EVM!H19:M25 | F9: Project Controls | G9: Active | H9: 1.2 12 Step Process
A10: 6 | B10: Gantt Chart | C10: Show planned timing and status. | D10: Gantt chart with RAG bars and status-date marker exists. | E10: EVM Charts!Gantt Schedule | F10: Project Controls | G10: Active | H10: 8.1.2 Gantt templates
A11: 7 | B11: Resource allocation | C11: Map tasks to people/resources and weekly loading. | D11: Resource Grid added with weekly hours and costs by WBS. | E11: Resource Grid!A4:Z35 | F11: Resource Manager | G11: Active | H11: 8.1.2 Gantt template from garden office
A12: 8 | B12: Predicting & reducing risk | C12: Identify project risks and containment measures. | D12: PID risk-control register added. | E12: PID!A63:E70 | F12: Project Manager | G12: Template ready | H12: 2.1.2 PID template
A13: 9 | B13: Monitoring progress | C13: Track completion against plan. | D13: Progress is linked from Fact_Physical_Progress to Task Plan and dashboard. | E13: Task Plan!K5:K17 | F13: Project Controls | G13: Active | H13: 1.2 12 Step Process
A14: 10 | B14: Monitoring cost | C14: Track actual cost and forecast. | D14: EVM reporting monitors AC, CV, CPI, EAC, ETC, VAC. | E14: EVM!A4:N16 | F14: Project Controls | G14: Active | H14: 1.2 12 Step Process
A15: 11 | B15: Adjusting the plan | C15: Use EVM and RAG exceptions to trigger decisions. | D15: Decision/action log added to Review. | E15: Review!A20:F28 | F15: Project Board | G15: Template ready | H15: 1.2 12 Step Process
A16: 12 | B16: Review & lessons | C16: Capture good, bad, better after delivery. | D16: Review sheet added with GOOD / BAD / BETTER structure. | E16: Review!A4:F17 | F16: Project Team | G16: Template ready | H16: 13.1.2 Review Template

Sheet PM-EVM Compliance
A1: PM-EVM Compliance Checklist
A2: Workbook compliance map against the attached PM-EVM guideline: WBS, Gantt, EVM, dashboard, live formulas, and exception-focused reporting.
A4: Guideline requirement | B4: Workbook implementation | C4: Location | D4: Status | E4: Evidence
A5: Setup controls: project metadata, status date, reporting period, rates/thresholds | B5: Added setup control sheet with live project metadata and thresholds | C5: Setup!A4:D20 | D5: Compliant | E5: PM-EVM.md lines 117-126
A6: Task Plan as integrated WBS/task control view | B6: Added live task table combining WBS, dates, BAC, PV, AC, progress, EV, variances, forecasts and RAG | C6: Task Plan!A4:T17 | D6: Compliant | E6: PM-EVM.md lines 120-125
A7: Gantt display tied to WBS baseline dates | B7: Existing EVM Charts Gantt uses WBS activities, baseline start/finish and duration | C7: EVM Charts!Gantt Schedule | D7: Compliant | E7: PM-EVM.md lines 122-125
A8: EVM by reporting period with PV, EV, AC, SV, CV, SPI, CPI, BAC, EAC, ETC, VAC | B8: Added EVM reporting table with weekly live formulas | C8: EVM!A4:N16 | D8: Compliant | E8: PM-EVM.md lines 123-124
A9: S-curve shows cumulative PV, EV, and AC over time | B9: Existing EVM S-curve chart is sourced from weekly cumulative helper table | C9: EVM Charts!EVM S-Curve | D9: Compliant | E9: PM-EVM.md lines 50-54
A10: Dashboard summarizes management KPIs and top WBS exceptions | B10: Existing dashboard has KPI tiles, WBS table, RAG, variance/status fields | C10: EVM Dashboard!A1:P47 | D10: Compliant | E10: PM-EVM.md lines 781-785
A11: Exception-focused reporting with RAG / traffic-light indicators | B11: RAG rules applied across performance indices, progress, variances, and status cells | C11: EVM Dashboard, Task Plan, EVM | D11: Compliant | E11: PM-EVM.md lines 781-785
A12: Consistent WBS codes, budgets, dates, and actuals across views | B12: Task Plan, EVM, Gantt and dashboard all reference Dim_WBS and fact tables | C12: Dim_WBS / Fact_* | D12: Compliant | E12: PM-EVM.md lines 270-274
A13: Validate formulas and totals | B13: Added formula validation and status-date tie-out to dashboard KPIs | C13: EVM!H19:M25 | D13: Compliant | E13: PM-EVM.md lines 783-785

Sheet Setup
A1: Setup Controls
A2: Single place to review project metadata, status date, reporting period, and RAG thresholds used by the control workbook.
A4: Control | B4: Value
A5: Project ID | B5: =Control_Project_ID -> P101
A6: Project Name | B6: =Control_Project_Name -> Office Fit-Out
A7: Project Start | B7: =Control_Project_Start -> 46146
A8: Project End | B8: =Control_Project_End -> 46229
A9: Status Date | B9: 46203
A10: Reporting Period | B10: Weekly
A11: Budget at Completion (BAC) | B11: =Control_BAC -> 268650
A12: CPI/SPI Red Threshold | B12: 0.95
A13: CPI/SPI Green Threshold | B13: 1
A14: Progress Amber Threshold | B14: 0.5
A15: Progress Green Threshold | B15: 0.8
A17: RAG | B17: Metric | C17: Rule | D17: Interpretation
A18: Green | B18: CPI/SPI | C18: >= 1.00 | D18: On or above plan
A19: Amber | B19: CPI/SPI | C19: 0.95 to < 1.00 | D19: Near threshold / watch
A20: Red | B20: CPI/SPI | C20: < 0.95 | D20: Action required

Sheet Task Plan
A1: Task Plan
A2: Integrated WBS control table: one live task-level view for scope, schedule, budget, progress, actuals, forecasts, and RAG status.
A4: WBS ID | B4: WBS Code | C4: Task / Activity | D4: Type | E4: Baseline Start | F4: Baseline Finish | G4: Duration Days | H4: BAC (NOK) | I4: PV @ Status | J4: AC @ Status | K4: Progress % | L4: EV @ Status | M4: SV | N4: CV | O4: SPI | P4: CPI | Q4: EAC | R4: ETC | S4: VAC | T4: Status
A5: =Dim_WBS!A2 -> WBS-01 | B5: =Dim_WBS!B2 -> 1 | C5: =Dim_WBS!C2 -> Project Management | D5: =Dim_WBS!D2 -> Labor | E5: =_xlfn.MINIFS(Fact_Baseline_PV!$A:$A,Fact_Baseline_PV!$B:$B,A5) -> 46146 | F5: =_xlfn.MAXIFS(Fact_Baseline_PV!$A:$A,Fact_Baseline_PV!$B:$B,A5)+6 -> 46229 | G5: =F5-E5+1 -> 84 | H5: =Dim_WBS!E2 -> 18000 | I5: =SUMIFS(Fact_Baseline_PV!$C:$C,Fact_Baseline_PV!$B:$B,A5,Fact_Baseline_PV!$A:$A,"<="&Setup!$B$9) -> 13500 | J5: =SUMIFS(Fact_Actual_Costs!$D:$D,Fact_Actual_Costs!$B:$B,A5,Fact_Actual_Costs!$A:$A,"<="&Setup!$B$9) -> 9600 | K5: {=IFERROR(LOOKUP(2,1/(Fact_Physical_Progress!$B$2:$B$35=A5)/(Fact_Physical_Progress!$A$2:$A$35<=Setup!$B$9),Fact_Physical_Progress!$C$2:$C$35),0)} -> 0.5 | L5: =H5*K5 -> 9000 | M5: =L5-I5 -> -4500 | N5: =L5-J5 -> -600 | O5: =IFERROR(L5/I5,1) -> 0.66666667 | P5: =IFERROR(L5/J5,1) -> 0.9375 | Q5: =IF(P5>0,H5/P5,H5) -> 19200 | R5: =Q5-J5 -> 9600 | S5: =H5-Q5 -> -1200 | T5: =IF(OR(N5<0,P5<Setup!$B$12,O5<Setup!$B$12),"Red",IF(OR(P5<Setup!$B$13,O5<Setup!$B$13),"Amber","Green")) -> Red
A6: =Dim_WBS!A3 -> WBS-02 | B6: =Dim_WBS!B3 -> 2 | C6: =Dim_WBS!C3 -> Site Survey & Mobilization | D6: =Dim_WBS!D3 -> Labor | E6: =_xlfn.MINIFS(Fact_Baseline_PV!$A:$A,Fact_Baseline_PV!$B:$B,A6) -> 46146 | F6: =_xlfn.MAXIFS(Fact_Baseline_PV!$A:$A,Fact_Baseline_PV!$B:$B,A6)+6 -> 46152 | G6: =F6-E6+1 -> 7 | H6: =Dim_WBS!E3 -> 8500 | I6: =SUMIFS(Fact_Baseline_PV!$C:$C,Fact_Baseline_PV!$B:$B,A6,Fact_Baseline_PV!$A:$A,"<="&Setup!$B$9) -> 8500 | J6: =SUMIFS(Fact_Actual_Costs!$D:$D,Fact_Actual_Costs!$B:$B,A6,Fact_Actual_Costs!$A:$A,"<="&Setup!$B$9) -> 8700 | K6: {=IFERROR(LOOKUP(2,1/(Fact_Physical_Progress!$B$2:$B$35=A6)/(Fact_Physical_Progress!$A$2:$A$35<=Setup!$B$9),Fact_Physical_Progress!$C$2:$C$35),0)} -> 1 | L6: =H6*K6 -> 8500 | M6: =L6-I6 -> 0 | N6: =L6-J6 -> -200 | O6: =IFERROR(L6/I6,1) -> 1 | P6: =IFERROR(L6/J6,1) -> 0.97701149 | Q6: =IF(P6>0,H6/P6,H6) -> 8700 | R6: =Q6-J6 -> 0 | S6: =H6-Q6 -> -200 | T6: =IF(OR(N6<0,P6<Setup!$B$12,O6<Setup!$B$12),"Red",IF(OR(P6<Setup!$B$13,O6<Setup!$B$13),"Amber","Green")) -> Red
A7: =Dim_WBS!A4 -> WBS-03 | B7: =Dim_WBS!B4 -> 3 | C7: =Dim_WBS!C4 -> Design & Engineering | D7: =Dim_WBS!D4 -> Labor | E7: =_xlfn.MINIFS(Fact_Baseline_PV!$A:$A,Fact_Baseline_PV!$B:$B,A7) -> 46146 | F7: =_xlfn.MAXIFS(Fact_Baseline_PV!$A:$A,Fact_Baseline_PV!$B:$B,A7)+6 -> 46166 | G7: =F7-E7+1 -> 21 | H7: =Dim_WBS!E4 -> 19200 | I7: =SUMIFS(Fact_Baseline_PV!$C:$C,Fact_Baseline_PV!$B:$B,A7,Fact_Baseline_PV!$A:$A,"<="&Setup!$B$9) -> 19200 | J7: =SUMIFS(Fact_Actual_Costs!$D:$D,Fact_Actual_Costs!$B:$B,A7,Fact_Actual_Costs!$A:$A,"<="&Setup!$B$9) -> 18195.04 | K7: {=IFERROR(LOOKUP(2,1/(Fact_Physical_Progress!$B$2:$B$35=A7)/(Fact_Physical_Progress!$A$2:$A$35<=Setup!$B$9),Fact_Physical_Progress!$C$2:$C$35),0)} -> 1 | L7: =H7*K7 -> 19200 | M7: =L7-I7 -> 0 | N7: =L7-J7 -> 1004.96 | O7: =IFERROR(L7/I7,1) -> 1 | P7: =IFERROR(L7/J7,1) -> 1.0552326 | Q7: =IF(P7>0,H7/P7,H7) -> 18195.04 | R7: =Q7-J7 -> 0 | S7: =H7-Q7 -> 1004.96 | T7: =IF(OR(N7<0,P7<Setup!$B$12,O7<Setup!$B$12),"Red",IF(OR(P7<Setup!$B$13,O7<Setup!$B$13),"Amber","Green")) -> Green
A8: =Dim_WBS!A5 -> WBS-04 | B8: =Dim_WBS!B5 -> 4 | C8: =Dim_WBS!C5 -> Procurement - Materials | D8: =Dim_WBS!D5 -> Material | E8: =_xlfn.MINIFS(Fact_Baseline_PV!$A:$A,Fact_Baseline_PV!$B:$B,A8) -> 46153 | F8: =_xlfn.MAXIFS(Fact_Baseline_PV!$A:$A,Fact_Baseline_PV!$B:$B,A8)+6 -> 46180 | G8: =F8-E8+1 -> 28 | H8: =Dim_WBS!E5 -> 42000 | I8: =SUMIFS(Fact_Baseline_PV!$C:$C,Fact_Baseline_PV!$B:$B,A8,Fact_Baseline_PV!$A:$A,"<="&Setup!$B$9) -> 42000 | J8: =SUMIFS(Fact_Actual_Costs!$D:$D,Fact_Actual_Costs!$B:$B,A8,Fact_Actual_Costs!$A:$A,"<="&Setup!$B$9) -> 41300 | K8: {=IFERROR(LOOKUP(2,1/(Fact_Physical_Progress!$B$2:$B$35=A8)/(Fact_Physical_Progress!$A$2:$A$35<=Setup!$B$9),Fact_Physical_Progress!$C$2:$C$35),0)} -> 1 | L8: =H8*K8 -> 42000 | M8: =L8-I8 -> 0 | N8: =L8-J8 -> 700 | O8: =IFERROR(L8/I8,1) -> 1 | P8: =IFERROR(L8/J8,1) -> 1.0169492 | Q8: =IF(P8>0,H8/P8,H8) -> 41300 | R8: =Q8-J8 -> 0 | S8: =H8-Q8 -> 700 | T8: =IF(OR(N8<0,P8<Setup!$B$12,O8<Setup!$B$12),"Red",IF(OR(P8<Setup!$B$13,O8<Setup!$B$13),"Amber","Green")) -> Green
A9: =Dim_WBS!A6 -> WBS-05 | B9: =Dim_WBS!B6 -> 5 | C9: =Dim_WBS!C6 -> Demolition & Prep | D9: =Dim_WBS!D6 -> Labor | E9: =_xlfn.MINIFS(Fact_Baseline_PV!$A:$A,Fact_Baseline_PV!$B:$B,A9) -> 46153 | F9: =_xlfn.MAXIFS(Fact_Baseline_PV!$A:$A,Fact_Baseline_PV!$B:$B,A9)+6 -> 46173 | G9: =F9-E9+1 -> 21 | H9: =Dim_WBS!E6 -> 13200 | I9: =SUMIFS(Fact_Baseline_PV!$C:$C,Fact_Baseline_PV!$B:$B,A9,Fact_Baseline_PV!$A:$A,"<="&Setup!$B$9) -> 13200 | J9: =SUMIFS(Fact_Actual_Costs!$D:$D,Fact_Actual_Costs!$B:$B,A9,Fact_Actual_Costs!$A:$A,"<="&Setup!$B$9) -> 13408.16 | K9: {=IFERROR(LOOKUP(2,1/(Fact_Physical_Progress!$B$2:$B$35=A9)/(Fact_Physical_Progress!$A$2:$A$35<=Setup!$B$9),Fact_Physical_Progress!$C$2:$C$35),0)} -> 1 | L9: =H9*K9 -> 13200 | M9: =L9-I9 -> 0 | N9: =L9-J9 -> -208.16 | O9: =IFERROR(L9/I9,1) -> 1 | P9: =IFERROR(L9/J9,1) -> 0.98447513 | Q9: =IF(P9>0,H9/P9,H9) -> 13408.16 | R9: =Q9-J9 -> 0 | S9: =H9-Q9 -> -208.16 | T9: =IF(OR(N9<0,P9<Setup!$B$12,O9<Setup!$B$12),"Red",IF(OR(P9<Setup!$B$13,O9<Setup!$B$13),"Amber","Green")) -> Red
A10: =Dim_WBS!A7 -> WBS-06 | B10: =Dim_WBS!B7 -> 6 | C10: =Dim_WBS!C7 -> Electrical Rough-In | D10: =Dim_WBS!D7 -> Labor | E10: =_xlfn.MINIFS(Fact_Baseline_PV!$A:$A,Fact_Baseline_PV!$B:$B,A10) -> 46167 | F10: =_xlfn.MAXIFS(Fact_Baseline_PV!$A:$A,Fact_Baseline_PV!$B:$B,A10)+6 -> 46187 | G10: =F10-E10+1 -> 21 | H10: =Dim_WBS!E7 -> 26000 | I10: =SUMIFS(Fact_Baseline_PV!$C:$C,Fact_Baseline_PV!$B:$B,A10,Fact_Baseline_PV!$A:$A,"<="&Setup!$B$9) -> 26000 | J10: =SUMIFS(Fact_Actual_Costs!$D:$D,Fact_Actual_Costs!$B:$B,A10,Fact_Actual_Costs!$A:$A,"<="&Setup!$B$9) -> 26206.24 | K10: {=IFERROR(LOOKUP(2,1/(Fact_Physical_Progress!$B$2:$B$35=A10)/(Fact_Physical_Progress!$A$2:$A$35<=Setup!$B$9),Fact_Physical_Progress!$C$2:$C$35),0)} -> 0.7 | L10: =H10*K10 -> 18200 | M10: =L10-I10 -> -7800 | N10: =L10-J10 -> -8006.24 | O10: =IFERROR(L10/I10,1) -> 0.7 | P10: =IFERROR(L10/J10,1) -> 0.69449108 | Q10: =IF(P10>0,H10/P10,H10) -> 37437.486 | R10: =Q10-J10 -> 11231.246 | S10: =H10-Q10 -> -11437.486 | T10: =IF(OR(N10<0,P10<Setup!$B$12,O10<Setup!$B$12),"Red",IF(OR(P10<Setup!$B$13,O10<Setup!$B$13),"Amber","Green")) -> Red
A11: =Dim_WBS!A8 -> WBS-07 | B11: =Dim_WBS!B8 -> 7 | C11: =Dim_WBS!C8 -> HVAC Installation | D11: =Dim_WBS!D8 -> Subcontractor | E11: =_xlfn.MINIFS(Fact_Baseline_PV!$A:$A,Fact_Baseline_PV!$B:$B,A11) -> 46174 | F11: =_xlfn.MAXIFS(Fact_Baseline_PV!$A:$A,Fact_Baseline_PV!$B:$B,A11)+6 -> 46201 | G11: =F11-E11+1 -> 28 | H11: =Dim_WBS!E8 -> 36000 | I11: =SUMIFS(Fact_Baseline_PV!$C:$C,Fact_Baseline_PV!$B:$B,A11,Fact_Baseline_PV!$A:$A,"<="&Setup!$B$9) -> 36000 | J11: =SUMIFS(Fact_Actual_Costs!$D:$D,Fact_Actual_Costs!$B:$B,A11,Fact_Actual_Costs!$A:$A,"<="&Setup!$B$9) -> 17476.8 | K11: {=IFERROR(LOOKUP(2,1/(Fact_Physical_Progress!$B$2:$B$35=A11)/(Fact_Physical_Progress!$A$2:$A$35<=Setup!$B$9),Fact_Physical_Progress!$C$2:$C$35),0)} -> 0.4 | L11: =H11*K11 -> 14400 | M11: =L11-I11 -> -21600 | N11: =L11-J11 -> -3076.8 | O11: =IFERROR(L11/I11,1) -> 0.4 | P11: =IFERROR(L11/J11,1) -> 0.82394946 | Q11: =IF(P11>0,H11/P11,H11) -> 43692 | R11: =Q11-J11 -> 26215.2 | S11: =H11-Q11 -> -7692 | T11: =IF(OR(N11<0,P11<Setup!$B$12,O11<Setup!$B$12),"Red",IF(OR(P11<Setup!$B$13,O11<Setup!$B$13),"Amber","Green")) -> Red
A12: =Dim_WBS!A9 -> WBS-08 | B12: =Dim_WBS!B9 -> 8 | C12: =Dim_WBS!C9 -> Partitions & Drywall | D12: =Dim_WBS!D9 -> Subcontractor | E12: =_xlfn.MINIFS(Fact_Baseline_PV!$A:$A,Fact_Baseline_PV!$B:$B,A12) -> 46181 | F12: =_xlfn.MAXIFS(Fact_Baseline_PV!$A:$A,Fact_Baseline_PV!$B:$B,A12)+6 -> 46208 | G12: =F12-E12+1 -> 28 | H12: =Dim_WBS!E9 -> 28000 | I12: =SUMIFS(Fact_Baseline_PV!$C:$C,Fact_Baseline_PV!$B:$B,A12,Fact_Baseline_PV!$A:$A,"<="&Setup!$B$9) -> 28000 | J12: =SUMIFS(Fact_Actual_Costs!$D:$D,Fact_Actual_Costs!$B:$B,A12,Fact_Actual_Costs!$A:$A,"<="&Setup!$B$9) -> 7099.2 | K12: {=IFERROR(LOOKUP(2,1/(Fact_Physical_Progress!$B$2:$B$35=A12)/(Fact_Physical_Progress!$A$2:$A$35<=Setup!$B$9),Fact_Physical_Progress!$C$2:$C$35),0)} -> 0.248857 | L12: =H12*K12 -> 6967.996 | M12: =L12-I12 -> -21032.004 | N12: =L12-J12 -> -131.204 | O12: =IFERROR(L12/I12,1) -> 0.248857 | P12: =IFERROR(L12/J12,1) -> 0.98151848 | Q12: =IF(P12>0,H12/P12,H12) -> 28527.226 | R12: =Q12-J12 -> 21428.026 | S12: =H12-Q12 -> -527.22648 | T12: =IF(OR(N12<0,P12<Setup!$B$12,O12<Setup!$B$12),"Red",IF(OR(P12<Setup!$B$13,O12<Setup!$B$13),"Amber","Green")) -> Red
A13: =Dim_WBS!A10 -> WBS-09 | B13: =Dim_WBS!B10 -> 9 | C13: =Dim_WBS!C10 -> Flooring | D13: =Dim_WBS!D10 -> Material | E13: =_xlfn.MINIFS(Fact_Baseline_PV!$A:$A,Fact_Baseline_PV!$B:$B,A13) -> 46195 | F13: =_xlfn.MAXIFS(Fact_Baseline_PV!$A:$A,Fact_Baseline_PV!$B:$B,A13)+6 -> 46215 | G13: =F13-E13+1 -> 21 | H13: =Dim_WBS!E10 -> 35750 | I13: =SUMIFS(Fact_Baseline_PV!$C:$C,Fact_Baseline_PV!$B:$B,A13,Fact_Baseline_PV!$A:$A,"<="&Setup!$B$9) -> 23833.34 | J13: =SUMIFS(Fact_Actual_Costs!$D:$D,Fact_Actual_Costs!$B:$B,A13,Fact_Actual_Costs!$A:$A,"<="&Setup!$B$9) -> 0 | K13: {=IFERROR(LOOKUP(2,1/(Fact_Physical_Progress!$B$2:$B$35=A13)/(Fact_Physical_Progress!$A$2:$A$35<=Setup!$B$9),Fact_Physical_Progress!$C$2:$C$35),0)} -> 0 | L13: =H13*K13 -> 0 | M13: =L13-I13 -> -23833.34 | N13: =L13-J13 -> 0 | O13: =IFERROR(L13/I13,1) -> 0 | P13: =IFERROR(L13/J13,1) -> 1 | Q13: =IF(P13>0,H13/P13,H13) -> 35750 | R13: =Q13-J13 -> 35750 | S13: =H13-Q13 -> 0 | T13: =IF(OR(N13<0,P13<Setup!$B$12,O13<Setup!$B$12),"Red",IF(OR(P13<Setup!$B$13,O13<Setup!$B$13),"Amber","Green")) -> Red
A14: =Dim_WBS!A11 -> WBS-10 | B14: =Dim_WBS!B11 -> 10 | C14: =Dim_WBS!C11 -> Fixtures & Furniture | D14: =Dim_WBS!D11 -> Material | E14: =_xlfn.MINIFS(Fact_Baseline_PV!$A:$A,Fact_Baseline_PV!$B:$B,A14) -> 46202 | F14: =_xlfn.MAXIFS(Fact_Baseline_PV!$A:$A,Fact_Baseline_PV!$B:$B,A14)+6 -> 46222 | G14: =F14-E14+1 -> 21 | H14: =Dim_WBS!E11 -> 30000 | I14: =SUMIFS(Fact_Baseline_PV!$C:$C,Fact_Baseline_PV!$B:$B,A14,Fact_Baseline_PV!$A:$A,"<="&Setup!$B$9) -> 10000 | J14: =SUMIFS(Fact_Actual_Costs!$D:$D,Fact_Actual_Costs!$B:$B,A14,Fact_Actual_Costs!$A:$A,"<="&Setup!$B$9) -> 0 | K14: {=IFERROR(LOOKUP(2,1/(Fact_Physical_Progress!$B$2:$B$35=A14)/(Fact_Physical_Progress!$A$2:$A$35<=Setup!$B$9),Fact_Physical_Progress!$C$2:$C$35),0)} -> 0 | L14: =H14*K14 -> 0 | M14: =L14-I14 -> -10000 | N14: =L14-J14 -> 0 | O14: =IFERROR(L14/I14,1) -> 0 | P14: =IFERROR(L14/J14,1) -> 1 | Q14: =IF(P14>0,H14/P14,H14) -> 30000 | R14: =Q14-J14 -> 30000 | S14: =H14-Q14 -> 0 | T14: =IF(OR(N14<0,P14<Setup!$B$12,O14<Setup!$B$12),"Red",IF(OR(P14<Setup!$B$13,O14<Setup!$B$13),"Amber","Green")) -> Red
A15: =Dim_WBS!A12 -> WBS-11 | B15: =Dim_WBS!B12 -> 11 | C15: =Dim_WBS!C12 -> Testing / Commissioning | D15: =Dim_WBS!D12 -> Labor | E15: =_xlfn.MINIFS(Fact_Baseline_PV!$A:$A,Fact_Baseline_PV!$B:$B,A15) -> 46216 | F15: =_xlfn.MAXIFS(Fact_Baseline_PV!$A:$A,Fact_Baseline_PV!$B:$B,A15)+6 -> 46229 | G15: =F15-E15+1 -> 14 | H15: =Dim_WBS!E12 -> 8400 | I15: =SUMIFS(Fact_Baseline_PV!$C:$C,Fact_Baseline_PV!$B:$B,A15,Fact_Baseline_PV!$A:$A,"<="&Setup!$B$9) -> 0 | J15: =SUMIFS(Fact_Actual_Costs!$D:$D,Fact_Actual_Costs!$B:$B,A15,Fact_Actual_Costs!$A:$A,"<="&Setup!$B$9) -> 0 | K15: {=IFERROR(LOOKUP(2,1/(Fact_Physical_Progress!$B$2:$B$35=A15)/(Fact_Physical_Progress!$A$2:$A$35<=Setup!$B$9),Fact_Physical_Progress!$C$2:$C$35),0)} -> 0 | L15: =H15*K15 -> 0 | M15: =L15-I15 -> 0 | N15: =L15-J15 -> 0 | O15: =IFERROR(L15/I15,1) -> 1 | P15: =IFERROR(L15/J15,1) -> 1 | Q15: =IF(P15>0,H15/P15,H15) -> 8400 | R15: =Q15-J15 -> 8400 | S15: =H15-Q15 -> 0 | T15: =IF(OR(N15<0,P15<Setup!$B$12,O15<Setup!$B$12),"Red",IF(OR(P15<Setup!$B$13,O15<Setup!$B$13),"Amber","Green")) -> Green
A16: =Dim_WBS!A13 -> WBS-12 | B16: =Dim_WBS!B13 -> 12 | C16: =Dim_WBS!C13 -> Handover & Closeout | D16: =Dim_WBS!D13 -> Labor | E16: =_xlfn.MINIFS(Fact_Baseline_PV!$A:$A,Fact_Baseline_PV!$B:$B,A16) -> 46223 | F16: =_xlfn.MAXIFS(Fact_Baseline_PV!$A:$A,Fact_Baseline_PV!$B:$B,A16)+6 -> 46229 | G16: =F16-E16+1 -> 7 | H16: =Dim_WBS!E13 -> 3600 | I16: =SUMIFS(Fact_Baseline_PV!$C:$C,Fact_Baseline_PV!$B:$B,A16,Fact_Baseline_PV!$A:$A,"<="&Setup!$B$9) -> 0 | J16: =SUMIFS(Fact_Actual_Costs!$D:$D,Fact_Actual_Costs!$B:$B,A16,Fact_Actual_Costs!$A:$A,"<="&Setup!$B$9) -> 0 | K16: {=IFERROR(LOOKUP(2,1/(Fact_Physical_Progress!$B$2:$B$35=A16)/(Fact_Physical_Progress!$A$2:$A$35<=Setup!$B$9),Fact_Physical_Progress!$C$2:$C$35),0)} -> 0 | L16: =H16*K16 -> 0 | M16: =L16-I16 -> 0 | N16: =L16-J16 -> 0 | O16: =IFERROR(L16/I16,1) -> 1 | P16: =IFERROR(L16/J16,1) -> 1 | Q16: =IF(P16>0,H16/P16,H16) -> 3600 | R16: =Q16-J16 -> 3600 | S16: =H16-Q16 -> 0 | T16: =IF(OR(N16<0,P16<Setup!$B$12,O16<Setup!$B$12),"Red",IF(OR(P16<Setup!$B$13,O16<Setup!$B$13),"Amber","Green")) -> Green
A17: Total / Project Portfolio | G17: =MAX(F5:F16)-MIN(E5:E16)+1 -> 84 | H17: =SUM(H5:H16) -> 268650 | I17: =SUM(I5:I16) -> 220233.34 | J17: =SUM(J5:J16) -> 141985.44 | K17: =SUMPRODUCT(H5:H16,K5:K16)/SUM(H5:H16) -> 0.48936533 | L17: =SUM(L5:L16) -> 131468 | M17: =SUM(M5:M16) -> -88765.344 | N17: =SUM(N5:N16) -> -10517.444 | O17: =IFERROR(L17/I17,1) -> 0.59694865 | P17: =IFERROR(L17/J17,1) -> 0.9259259 | Q17: =IF(P17>0,H17/P17,H17) -> 290142.01 | R17: =Q17-J17 -> 148156.57 | S17: =H17-Q17 -> -21492.009 | T17: =IF(OR(N17<0,P17<Setup!$B$12,O17<Setup!$B$12),"Red",IF(OR(P17<Setup!$B$13,O17<Setup!$B$13),"Amber","Green")) -> Red

Sheet Task Capture
A1: Task Capture / List the Tasks
A2: Method: first list all tasks without worrying about order, cost, or time; then group into phases and convert into the controlled Task Plan.
A4: Phase / Area | B4: Task | C4: WBS ID | D4: Type | E4: Included? | F4: Event / Milestone? | G4: Owner | H4: Notes | I4: Source / next action | J4: Mapped to Task Plan
A5: =Dim_WBS!D2 -> Labor | B5: =Dim_WBS!C2 -> Project Management | C5: =Dim_WBS!A2 -> WBS-01 | D5: =Dim_WBS!D2 -> Labor | E5: Yes | I5: Imported from current WBS | J5: =IFERROR(MATCH(C5,'Task Plan'!A:A,0),"") -> 5
A6: =Dim_WBS!D3 -> Labor | B6: =Dim_WBS!C3 -> Site Survey & Mobilization | C6: =Dim_WBS!A3 -> WBS-02 | D6: =Dim_WBS!D3 -> Labor | E6: Yes | I6: Imported from current WBS | J6: =IFERROR(MATCH(C6,'Task Plan'!A:A,0),"") -> 6
A7: =Dim_WBS!D4 -> Labor | B7: =Dim_WBS!C4 -> Design & Engineering | C7: =Dim_WBS!A4 -> WBS-03 | D7: =Dim_WBS!D4 -> Labor | E7: Yes | I7: Imported from current WBS | J7: =IFERROR(MATCH(C7,'Task Plan'!A:A,0),"") -> 7
A8: =Dim_WBS!D5 -> Material | B8: =Dim_WBS!C5 -> Procurement - Materials | C8: =Dim_WBS!A5 -> WBS-04 | D8: =Dim_WBS!D5 -> Material | E8: Yes | I8: Imported from current WBS | J8: =IFERROR(MATCH(C8,'Task Plan'!A:A,0),"") -> 8
A9: =Dim_WBS!D6 -> Labor | B9: =Dim_WBS!C6 -> Demolition & Prep | C9: =Dim_WBS!A6 -> WBS-05 | D9: =Dim_WBS!D6 -> Labor | E9: Yes | I9: Imported from current WBS | J9: =IFERROR(MATCH(C9,'Task Plan'!A:A,0),"") -> 9
A10: =Dim_WBS!D7 -> Labor | B10: =Dim_WBS!C7 -> Electrical Rough-In | C10: =Dim_WBS!A7 -> WBS-06 | D10: =Dim_WBS!D7 -> Labor | E10: Yes | I10: Imported from current WBS | J10: =IFERROR(MATCH(C10,'Task Plan'!A:A,0),"") -> 10
A11: =Dim_WBS!D8 -> Subcontractor | B11: =Dim_WBS!C8 -> HVAC Installation | C11: =Dim_WBS!A8 -> WBS-07 | D11: =Dim_WBS!D8 -> Subcontractor | E11: Yes | I11: Imported from current WBS | J11: =IFERROR(MATCH(C11,'Task Plan'!A:A,0),"") -> 11
A12: =Dim_WBS!D9 -> Subcontractor | B12: =Dim_WBS!C9 -> Partitions & Drywall | C12: =Dim_WBS!A9 -> WBS-08 | D12: =Dim_WBS!D9 -> Subcontractor | E12: Yes | I12: Imported from current WBS | J12: =IFERROR(MATCH(C12,'Task Plan'!A:A,0),"") -> 12
A13: =Dim_WBS!D10 -> Material | B13: =Dim_WBS!C10 -> Flooring | C13: =Dim_WBS!A10 -> WBS-09 | D13: =Dim_WBS!D10 -> Material | E13: Yes | I13: Imported from current WBS | J13: =IFERROR(MATCH(C13,'Task Plan'!A:A,0),"") -> 13
A14: =Dim_WBS!D11 -> Material | B14: =Dim_WBS!C11 -> Fixtures & Furniture | C14: =Dim_WBS!A11 -> WBS-10 | D14: =Dim_WBS!D11 -> Material | E14: Yes | I14: Imported from current WBS | J14: =IFERROR(MATCH(C14,'Task Plan'!A:A,0),"") -> 14
A15: =Dim_WBS!D12 -> Labor | B15: =Dim_WBS!C12 -> Testing / Commissioning | C15: =Dim_WBS!A12 -> WBS-11 | D15: =Dim_WBS!D12 -> Labor | E15: Yes | I15: Imported from current WBS | J15: =IFERROR(MATCH(C15,'Task Plan'!A:A,0),"") -> 15
A16: =Dim_WBS!D13 -> Labor | B16: =Dim_WBS!C13 -> Handover & Closeout | C16: =Dim_WBS!A13 -> WBS-12 | D16: =Dim_WBS!D13 -> Labor | E16: Yes | I16: Imported from current WBS | J16: =IFERROR(MATCH(C16,'Task Plan'!A:A,0),"") -> 16
A17: Brainstorm / new | I17: Add new tasks here before sequencing
A18: Brainstorm / new | I18: Add new tasks here before sequencing
A21: Example task-list method from attachment | B21: Garden office example grouped tasks: clear the space, foundations, buy the shed, install shed, legal. Use this area to add unstructured tasks before converting them to WBS.

Sheet EVM Dashboard
A1: OFFICE FIT-OUT - PROJECT CONTROLLING DASHBOARD
A2: EVM Performance Status | Tufte-Compliant Design | Data-Ink Maximized
A4: Status Date: | B4: =Control_Status_Date -> 46203 | D4: Status Week: | E4: =MATCH(B4,EVM!B5:B16,1) -> 8 | G4: Sector: | H4: =Control_Sector -> Corporate Real Estate | N4: RAG Legend | O4: Rule | P4: Meaning
N5: Green | O5: Good | P5: On/above plan or low exposure
A6: BUDGET AT COMPLETION (BAC) | D6: PLANNED VALUE (PV) | G6: ACTUAL COST (AC) | J6: EARNED VALUE (EV) | N6: Amber | O6: Watch | P6: Near threshold / medium exposure
A7: =Setup!B11 -> 268650 | D7: ='Task Plan'!I17 -> 220233.34 | G7: ='Task Plan'!J17 -> 141985.44 | J7: ='Task Plan'!L17 -> 131468 | N7: Red | O7: Action | P7: Behind plan, overrun, or high exposure
A9: COST VARIANCE (CV) | D9: SCHEDULE VARIANCE (SV) | G9: CPI (COST INDEX) | J9: SPI (SCHEDULE INDEX)
A10: ='Task Plan'!N17 -> -10517.444 | D10: ='Task Plan'!M17 -> -88765.344 | G10: ='Task Plan'!P17 -> 0.9259259 | J10: ='Task Plan'!O17 -> 0.59694865
A12: ESTIMATE AT COMPLETION (EAC) | D12: ESTIMATE TO COMPLETE (ETC) | G12: VARIANCE AT COMPLETION (VAC) | J12: PROJECT PROGRESS %
A13: ='Task Plan'!Q17 -> 290142.01 | D13: ='Task Plan'!R17 -> 148156.57 | G13: ='Task Plan'!S17 -> -21492.009 | J13: ='Task Plan'!K17 -> 0.48936533
A15: WBS Element Performance Breakdown
A17: WBS ID | B17: Activity Name | C17: Type | D17: Budget (BAC) | E17: Planned Value (PV) | F17: Actual Cost (AC) | G17: Progress % | H17: Earned Value (EV) | I17: CV | J17: SV | K17: CPI | L17: SPI | M17: EAC | N17: ETC | O17: VAC | P17: Status
A18: ='Task Plan'!A5 -> WBS-01 | B18: ='Task Plan'!C5 -> Project Management | C18: ='Task Plan'!D5 -> Labor | D18: ='Task Plan'!H5 -> 18000 | E18: ='Task Plan'!I5 -> 13500 | F18: ='Task Plan'!J5 -> 9600 | G18: ='Task Plan'!K5 -> 0.5 | H18: ='Task Plan'!L5 -> 9000 | I18: ='Task Plan'!N5 -> -600 | J18: ='Task Plan'!M5 -> -4500 | K18: ='Task Plan'!P5 -> 0.9375 | L18: ='Task Plan'!O5 -> 0.66666667 | M18: ='Task Plan'!Q5 -> 19200 | N18: ='Task Plan'!R5 -> 9600 | O18: ='Task Plan'!S5 -> -1200 | P18: =IF('Task Plan'!T5="Red","🔴 Overrun",IF('Task Plan'!T5="Amber","🟡 Warning","On Track")) -> 🔴 Overrun
A19: ='Task Plan'!A6 -> WBS-02 | B19: ='Task Plan'!C6 -> Site Survey & Mobilization | C19: ='Task Plan'!D6 -> Labor | D19: ='Task Plan'!H6 -> 8500 | E19: ='Task Plan'!I6 -> 8500 | F19: ='Task Plan'!J6 -> 8700 | G19: ='Task Plan'!K6 -> 1 | H19: ='Task Plan'!L6 -> 8500 | I19: ='Task Plan'!N6 -> -200 | J19: ='Task Plan'!M6 -> 0 | K19: ='Task Plan'!P6 -> 0.97701149 | L19: ='Task Plan'!O6 -> 1 | M19: ='Task Plan'!Q6 -> 8700 | N19: ='Task Plan'!R6 -> 0 | O19: ='Task Plan'!S6 -> -200 | P19: =IF('Task Plan'!T6="Red","🔴 Overrun",IF('Task Plan'!T6="Amber","🟡 Warning","On Track")) -> 🔴 Overrun
A20: ='Task Plan'!A7 -> WBS-03 | B20: ='Task Plan'!C7 -> Design & Engineering | C20: ='Task Plan'!D7 -> Labor | D20: ='Task Plan'!H7 -> 19200 | E20: ='Task Plan'!I7 -> 19200 | F20: ='Task Plan'!J7 -> 18195.04 | G20: ='Task Plan'!K7 -> 1 | H20: ='Task Plan'!L7 -> 19200 | I20: ='Task Plan'!N7 -> 1004.96 | J20: ='Task Plan'!M7 -> 0 | K20: ='Task Plan'!P7 -> 1.0552326 | L20: ='Task Plan'!O7 -> 1 | M20: ='Task Plan'!Q7 -> 18195.04 | N20: ='Task Plan'!R7 -> 0 | O20: ='Task Plan'!S7 -> 1004.96 | P20: =IF('Task Plan'!T7="Red","🔴 Overrun",IF('Task Plan'!T7="Amber","🟡 Warning","On Track")) -> On Track
A21: ='Task Plan'!A8 -> WBS-04 | B21: ='Task Plan'!C8 -> Procurement - Materials | C21: ='Task Plan'!D8 -> Material | D21: ='Task Plan'!H8 -> 42000 | E21: ='Task Plan'!I8 -> 42000 | F21: ='Task Plan'!J8 -> 41300 | G21: ='Task Plan'!K8 -> 1 | H21: ='Task Plan'!L8 -> 42000 | I21: ='Task Plan'!N8 -> 700 | J21: ='Task Plan'!M8 -> 0 | K21: ='Task Plan'!P8 -> 1.0169492 | L21: ='Task Plan'!O8 -> 1 | M21: ='Task Plan'!Q8 -> 41300 | N21: ='Task Plan'!R8 -> 0 | O21: ='Task Plan'!S8 -> 700 | P21: =IF('Task Plan'!T8="Red","🔴 Overrun",IF('Task Plan'!T8="Amber","🟡 Warning","On Track")) -> On Track
A22: ='Task Plan'!A9 -> WBS-05 | B22: ='Task Plan'!C9 -> Demolition & Prep | C22: ='Task Plan'!D9 -> Labor | D22: ='Task Plan'!H9 -> 13200 | E22: ='Task Plan'!I9 -> 13200 | F22: ='Task Plan'!J9 -> 13408.16 | G22: ='Task Plan'!K9 -> 1 | H22: ='Task Plan'!L9 -> 13200 | I22: ='Task Plan'!N9 -> -208.16 | J22: ='Task Plan'!M9 -> 0 | K22: ='Task Plan'!P9 -> 0.98447513 | L22: ='Task Plan'!O9 -> 1 | M22: ='Task Plan'!Q9 -> 13408.16 | N22: ='Task Plan'!R9 -> 0 | O22: ='Task Plan'!S9 -> -208.16 | P22: =IF('Task Plan'!T9="Red","🔴 Overrun",IF('Task Plan'!T9="Amber","🟡 Warning","On Track")) -> 🔴 Overrun
A23: ='Task Plan'!A10 -> WBS-06 | B23: ='Task Plan'!C10 -> Electrical Rough-In | C23: ='Task Plan'!D10 -> Labor | D23: ='Task Plan'!H10 -> 26000 | E23: ='Task Plan'!I10 -> 26000 | F23: ='Task Plan'!J10 -> 26206.24 | G23: ='Task Plan'!K10 -> 0.7 | H23: ='Task Plan'!L10 -> 18200 | I23: ='Task Plan'!N10 -> -8006.24 | J23: ='Task Plan'!M10 -> -7800 | K23: ='Task Plan'!P10 -> 0.69449108 | L23: ='Task Plan'!O10 -> 0.7 | M23: ='Task Plan'!Q10 -> 37437.486 | N23: ='Task Plan'!R10 -> 11231.246 | O23: ='Task Plan'!S10 -> -11437.486 | P23: =IF('Task Plan'!T10="Red","🔴 Overrun",IF('Task Plan'!T10="Amber","🟡 Warning","On Track")) -> 🔴 Overrun
A24: ='Task Plan'!A11 -> WBS-07 | B24: ='Task Plan'!C11 -> HVAC Installation | C24: ='Task Plan'!D11 -> Subcontractor | D24: ='Task Plan'!H11 -> 36000 | E24: ='Task Plan'!I11 -> 36000 | F24: ='Task Plan'!J11 -> 17476.8 | G24: ='Task Plan'!K11 -> 0.4 | H24: ='Task Plan'!L11 -> 14400 | I24: ='Task Plan'!N11 -> -3076.8 | J24: ='Task Plan'!M11 -> -21600 | K24: ='Task Plan'!P11 -> 0.82394946 | L24: ='Task Plan'!O11 -> 0.4 | M24: ='Task Plan'!Q11 -> 43692 | N24: ='Task Plan'!R11 -> 26215.2 | O24: ='Task Plan'!S11 -> -7692 | P24: =IF('Task Plan'!T11="Red","🔴 Overrun",IF('Task Plan'!T11="Amber","🟡 Warning","On Track")) -> 🔴 Overrun
A25: ='Task Plan'!A12 -> WBS-08 | B25: ='Task Plan'!C12 -> Partitions & Drywall | C25: ='Task Plan'!D12 -> Subcontractor | D25: ='Task Plan'!H12 -> 28000 | E25: ='Task Plan'!I12 -> 28000 | F25: ='Task Plan'!J12 -> 7099.2 | G25: ='Task Plan'!K12 -> 0.248857 | H25: ='Task Plan'!L12 -> 6967.996 | I25: ='Task Plan'!N12 -> -131.204 | J25: ='Task Plan'!M12 -> -21032.004 | K25: ='Task Plan'!P12 -> 0.98151848 | L25: ='Task Plan'!O12 -> 0.248857 | M25: ='Task Plan'!Q12 -> 28527.226 | N25: ='Task Plan'!R12 -> 21428.026 | O25: ='Task Plan'!S12 -> -527.22648 | P25: =IF('Task Plan'!T12="Red","🔴 Overrun",IF('Task Plan'!T12="Amber","🟡 Warning","On Track")) -> 🔴 Overrun
A26: ='Task Plan'!A13 -> WBS-09 | B26: ='Task Plan'!C13 -> Flooring | C26: ='Task Plan'!D13 -> Material | D26: ='Task Plan'!H13 -> 35750 | E26: ='Task Plan'!I13 -> 23833.34 | F26: ='Task Plan'!J13 -> 0 | G26: ='Task Plan'!K13 -> 0 | H26: ='Task Plan'!L13 -> 0 | I26: ='Task Plan'!N13 -> 0 | J26: ='Task Plan'!M13 -> -23833.34 | K26: ='Task Plan'!P13 -> 1 | L26: ='Task Plan'!O13 -> 0 | M26: ='Task Plan'!Q13 -> 35750 | N26: ='Task Plan'!R13 -> 35750 | O26: ='Task Plan'!S13 -> 0 | P26: =IF('Task Plan'!T13="Red","🔴 Overrun",IF('Task Plan'!T13="Amber","🟡 Warning","On Track")) -> 🔴 Overrun
A27: ='Task Plan'!A14 -> WBS-10 | B27: ='Task Plan'!C14 -> Fixtures & Furniture | C27: ='Task Plan'!D14 -> Material | D27: ='Task Plan'!H14 -> 30000 | E27: ='Task Plan'!I14 -> 10000 | F27: ='Task Plan'!J14 -> 0 | G27: ='Task Plan'!K14 -> 0 | H27: ='Task Plan'!L14 -> 0 | I27: ='Task Plan'!N14 -> 0 | J27: ='Task Plan'!M14 -> -10000 | K27: ='Task Plan'!P14 -> 1 | L27: ='Task Plan'!O14 -> 0 | M27: ='Task Plan'!Q14 -> 30000 | N27: ='Task Plan'!R14 -> 30000 | O27: ='Task Plan'!S14 -> 0 | P27: =IF('Task Plan'!T14="Red","🔴 Overrun",IF('Task Plan'!T14="Amber","🟡 Warning","On Track")) -> 🔴 Overrun
A28: ='Task Plan'!A15 -> WBS-11 | B28: ='Task Plan'!C15 -> Testing / Commissioning | C28: ='Task Plan'!D15 -> Labor | D28: ='Task Plan'!H15 -> 8400 | E28: ='Task Plan'!I15 -> 0 | F28: ='Task Plan'!J15 -> 0 | G28: ='Task Plan'!K15 -> 0 | H28: ='Task Plan'!L15 -> 0 | I28: ='Task Plan'!N15 -> 0 | J28: ='Task Plan'!M15 -> 0 | K28: ='Task Plan'!P15 -> 1 | L28: ='Task Plan'!O15 -> 1 | M28: ='Task Plan'!Q15 -> 8400 | N28: ='Task Plan'!R15 -> 8400 | O28: ='Task Plan'!S15 -> 0 | P28: =IF('Task Plan'!T15="Red","🔴 Overrun",IF('Task Plan'!T15="Amber","🟡 Warning","On Track")) -> On Track
A29: ='Task Plan'!A16 -> WBS-12 | B29: ='Task Plan'!C16 -> Handover & Closeout | C29: ='Task Plan'!D16 -> Labor | D29: ='Task Plan'!H16 -> 3600 | E29: ='Task Plan'!I16 -> 0 | F29: ='Task Plan'!J16 -> 0 | G29: ='Task Plan'!K16 -> 0 | H29: ='Task Plan'!L16 -> 0 | I29: ='Task Plan'!N16 -> 0 | J29: ='Task Plan'!M16 -> 0 | K29: ='Task Plan'!P16 -> 1 | L29: ='Task Plan'!O16 -> 1 | M29: ='Task Plan'!Q16 -> 3600 | N29: ='Task Plan'!R16 -> 3600 | O29: ='Task Plan'!S16 -> 0 | P29: =IF('Task Plan'!T16="Red","🔴 Overrun",IF('Task Plan'!T16="Amber","🟡 Warning","On Track")) -> On Track
A30: Total / Project Portfolio | D30: ='Task Plan'!H17 -> 268650 | E30: ='Task Plan'!I17 -> 220233.34 | F30: ='Task Plan'!J17 -> 141985.44 | G30: ='Task Plan'!K17 -> 0.48936533 | H30: ='Task Plan'!L17 -> 131468 | I30: ='Task Plan'!N17 -> -10517.444 | J30: ='Task Plan'!M17 -> -88765.344 | K30: ='Task Plan'!P17 -> 0.9259259 | L30: ='Task Plan'!O17 -> 0.59694865 | M30: ='Task Plan'!Q17 -> 290142.01 | N30: ='Task Plan'!R17 -> 148156.57 | O30: ='Task Plan'!S17 -> -21492.009 | P30: =IF('Task Plan'!T17="Red","🔴 Overrun",IF('Task Plan'!T17="Amber","🟡 Warning","On Track")) -> 🔴 Overrun
A33: Weekly Cumulative Performance Trends
A35: Week | B35: Week Date | C35: Weekly PV | D35: Cum PV | E35: Weekly AC | F35: Cum AC | G35: Cum EV | H35: CV | I35: SV | J35: CPI | K35: SPI
A36: 1 | B36: 46146 | C36: =SUMIFS(Fact_Baseline_PV!C:C, Fact_Baseline_PV!A:A, B36) -> 16400 | D36: =SUM(C$36:C36) -> 16400 | E36: =SUMIFS(Fact_Actual_Costs!D:D, Fact_Actual_Costs!A:A, ">="&B36, Fact_Actual_Costs!A:A, "<="&B36+6) -> 16295.04 | F36: =SUM(E$36:E36) -> 16295.04 | G36: =SUMPRODUCT(Dim_WBS!$E$2:$E$13, SUMIFS(Fact_Physical_Progress!$C$2:$C$100, Fact_Physical_Progress!$B$2:$B$100, Dim_WBS!$A$2:$A$13, Fact_Physical_Progress!$A$2:$A$100, "<="&B36+4)) -> 15087.994 | H36: =G36-F36 -> -1207.046 | I36: =G36-D36 -> -1312.006 | J36: =IF(F36>0, G36/F36, 1) -> 0.92592556 | K36: =IF(D36>0, G36/D36, 1) -> 0.91999963
A37: 2 | B37: 46153 | C37: =SUMIFS(Fact_Baseline_PV!C:C, Fact_Baseline_PV!A:A, B37) -> 22800 | D37: =SUM(C$36:C37) -> 39200 | E37: =SUMIFS(Fact_Actual_Costs!D:D, Fact_Actual_Costs!A:A, ">="&B37, Fact_Actual_Costs!A:A, "<="&B37+6) -> 22654.08 | F37: =SUM(E$36:E37) -> 38949.12 | G37: =SUMPRODUCT(Dim_WBS!$E$2:$E$13, SUMIFS(Fact_Physical_Progress!$C$2:$C$100, Fact_Physical_Progress!$B$2:$B$100, Dim_WBS!$A$2:$A$13, Fact_Physical_Progress!$A$2:$A$100, "<="&B37+4)) -> 51151.998 | H37: =G37-F37 -> 12202.878 | I37: =G37-D37 -> 11951.998 | J37: =IF(F37>0, G37/F37, 1) -> 1.313303 | K37: =IF(D37>0, G37/D37, 1) -> 1.3048979
A38: 3 | B38: 46160 | C38: =SUMIFS(Fact_Baseline_PV!C:C, Fact_Baseline_PV!A:A, B38) -> 22800 | D38: =SUM(C$36:C38) -> 62000 | E38: =SUMIFS(Fact_Actual_Costs!D:D, Fact_Actual_Costs!A:A, ">="&B38, Fact_Actual_Costs!A:A, "<="&B38+6) -> 22654.08 | F38: =SUM(E$36:E38) -> 61603.2 | G38: =SUMPRODUCT(Dim_WBS!$E$2:$E$13, SUMIFS(Fact_Physical_Progress!$C$2:$C$100, Fact_Physical_Progress!$B$2:$B$100, Dim_WBS!$A$2:$A$13, Fact_Physical_Progress!$A$2:$A$100, "<="&B38+4)) -> 108192 | H38: =G38-F38 -> 46588.798 | I38: =G38-D38 -> 46191.998 | J38: =IF(F38>0, G38/F38, 1) -> 1.7562724 | K38: =IF(D38>0, G38/D38, 1) -> 1.7450322
A39: 4 | B39: 46167 | C39: =SUMIFS(Fact_Baseline_PV!C:C, Fact_Baseline_PV!A:A, B39) -> 25066.67 | D39: =SUM(C$36:C39) -> 87066.67 | E39: =SUMIFS(Fact_Actual_Costs!D:D, Fact_Actual_Costs!A:A, ">="&B39, Fact_Actual_Costs!A:A, "<="&B39+6) -> 24906.24 | F39: =SUM(E$36:E39) -> 86509.44 | G39: =SUMPRODUCT(Dim_WBS!$E$2:$E$13, SUMIFS(Fact_Physical_Progress!$C$2:$C$100, Fact_Physical_Progress!$B$2:$B$100, Dim_WBS!$A$2:$A$13, Fact_Physical_Progress!$A$2:$A$100, "<="&B39+4)) -> 188293.33 | H39: =G39-F39 -> 101783.89 | I39: =G39-D39 -> 101226.66 | J39: =IF(F39>0, G39/F39, 1) -> 2.1765639 | K39: =IF(D39>0, G39/D39, 1) -> 2.1626338
A40: 5 | B40: 46174 | C40: =SUMIFS(Fact_Baseline_PV!C:C, Fact_Baseline_PV!A:A, B40) -> 29666.67 | D40: =SUM(C$36:C40) -> 116733.34 | E40: =SUMIFS(Fact_Actual_Costs!D:D, Fact_Actual_Costs!A:A, ">="&B40, Fact_Actual_Costs!A:A, "<="&B40+6) -> 29476.8 | F40: =SUM(E$36:E40) -> 115986.24 | G40: =SUMPRODUCT(Dim_WBS!$E$2:$E$13, SUMIFS(Fact_Physical_Progress!$C$2:$C$100, Fact_Physical_Progress!$B$2:$B$100, Dim_WBS!$A$2:$A$13, Fact_Physical_Progress!$A$2:$A$100, "<="&B40+4)) -> 295688 | H40: =G40-F40 -> 179701.76 | I40: =G40-D40 -> 178954.66 | J40: =IF(F40>0, G40/F40, 1) -> 2.5493369 | K40: =IF(D40>0, G40/D40, 1) -> 2.533021
A41: 6 | B41: 46181 | C41: =SUMIFS(Fact_Baseline_PV!C:C, Fact_Baseline_PV!A:A, B41) -> 26166.66 | D41: =SUM(C$36:C41) -> 142900 | E41: =SUMIFS(Fact_Actual_Costs!D:D, Fact_Actual_Costs!A:A, ">="&B41, Fact_Actual_Costs!A:A, "<="&B41+6) -> 25999.2 | F41: =SUM(E$36:E41) -> 141985.44 | G41: =SUMPRODUCT(Dim_WBS!$E$2:$E$13, SUMIFS(Fact_Physical_Progress!$C$2:$C$100, Fact_Physical_Progress!$B$2:$B$100, Dim_WBS!$A$2:$A$13, Fact_Physical_Progress!$A$2:$A$100, "<="&B41+4)) -> 427156 | H41: =G41-F41 -> 285170.56 | I41: =G41-D41 -> 284256 | J41: =IF(F41>0, G41/F41, 1) -> 3.0084493 | K41: =IF(D41>0, G41/D41, 1) -> 2.9891952
A42: 7 | B42: 46188 | C42: =SUMIFS(Fact_Baseline_PV!C:C, Fact_Baseline_PV!A:A, B42) -> 17500 | D42: =SUM(C$36:C42) -> 160400 | E42: =SUMIFS(Fact_Actual_Costs!D:D, Fact_Actual_Costs!A:A, ">="&B42, Fact_Actual_Costs!A:A, "<="&B42+6) -> 0 | F42: =SUM(E$36:E42) -> 141985.44 | G42: =SUMPRODUCT(Dim_WBS!$E$2:$E$13, SUMIFS(Fact_Physical_Progress!$C$2:$C$100, Fact_Physical_Progress!$B$2:$B$100, Dim_WBS!$A$2:$A$13, Fact_Physical_Progress!$A$2:$A$100, "<="&B42+4)) -> 427156 | H42: =G42-F42 -> 285170.56 | I42: =G42-D42 -> 266756 | J42: =IF(F42>0, G42/F42, 1) -> 3.0084493 | K42: =IF(D42>0, G42/D42, 1) -> 2.6630673
A43: 8 | B43: 46195 | C43: =SUMIFS(Fact_Baseline_PV!C:C, Fact_Baseline_PV!A:A, B43) -> 29416.67 | D43: =SUM(C$36:C43) -> 189816.67 | E43: =SUMIFS(Fact_Actual_Costs!D:D, Fact_Actual_Costs!A:A, ">="&B43, Fact_Actual_Costs!A:A, "<="&B43+6) -> 0 | F43: =SUM(E$36:E43) -> 141985.44 | G43: =SUMPRODUCT(Dim_WBS!$E$2:$E$13, SUMIFS(Fact_Physical_Progress!$C$2:$C$100, Fact_Physical_Progress!$B$2:$B$100, Dim_WBS!$A$2:$A$13, Fact_Physical_Progress!$A$2:$A$100, "<="&B43+4)) -> 427156 | H43: =G43-F43 -> 285170.56 | I43: =G43-D43 -> 237339.33 | J43: =IF(F43>0, G43/F43, 1) -> 3.0084493 | K43: =IF(D43>0, G43/D43, 1) -> 2.2503608
A44: 9 | B44: 46202 | C44: =SUMIFS(Fact_Baseline_PV!C:C, Fact_Baseline_PV!A:A, B44) -> 30416.67 | D44: =SUM(C$36:C44) -> 220233.34 | E44: =SUMIFS(Fact_Actual_Costs!D:D, Fact_Actual_Costs!A:A, ">="&B44, Fact_Actual_Costs!A:A, "<="&B44+6) -> 0 | F44: =SUM(E$36:E44) -> 141985.44 | G44: =SUMPRODUCT(Dim_WBS!$E$2:$E$13, SUMIFS(Fact_Physical_Progress!$C$2:$C$100, Fact_Physical_Progress!$B$2:$B$100, Dim_WBS!$A$2:$A$13, Fact_Physical_Progress!$A$2:$A$100, "<="&B44+4)) -> 427156 | H44: =G44-F44 -> 285170.56 | I44: =G44-D44 -> 206922.66 | J44: =IF(F44>0, G44/F44, 1) -> 3.0084493 | K44: =IF(D44>0, G44/D44, 1) -> 1.939561
A45: 10 | B45: 46209 | C45: =SUMIFS(Fact_Baseline_PV!C:C, Fact_Baseline_PV!A:A, B45) -> 23416.66 | D45: =SUM(C$36:C45) -> 243650 | E45: =SUMIFS(Fact_Actual_Costs!D:D, Fact_Actual_Costs!A:A, ">="&B45, Fact_Actual_Costs!A:A, "<="&B45+6) -> 0 | F45: =SUM(E$36:E45) -> 141985.44 | G45: =SUMPRODUCT(Dim_WBS!$E$2:$E$13, SUMIFS(Fact_Physical_Progress!$C$2:$C$100, Fact_Physical_Progress!$B$2:$B$100, Dim_WBS!$A$2:$A$13, Fact_Physical_Progress!$A$2:$A$100, "<="&B45+4)) -> 427156 | H45: =G45-F45 -> 285170.56 | I45: =G45-D45 -> 183506 | J45: =IF(F45>0, G45/F45, 1) -> 3.0084493 | K45: =IF(D45>0, G45/D45, 1) -> 1.7531541
A46: 11 | B46: 46216 | C46: =SUMIFS(Fact_Baseline_PV!C:C, Fact_Baseline_PV!A:A, B46) -> 15700 | D46: =SUM(C$36:C46) -> 259350 | E46: =SUMIFS(Fact_Actual_Costs!D:D, Fact_Actual_Costs!A:A, ">="&B46, Fact_Actual_Costs!A:A, "<="&B46+6) -> 0 | F46: =SUM(E$36:E46) -> 141985.44 | G46: =SUMPRODUCT(Dim_WBS!$E$2:$E$13, SUMIFS(Fact_Physical_Progress!$C$2:$C$100, Fact_Physical_Progress!$B$2:$B$100, Dim_WBS!$A$2:$A$13, Fact_Physical_Progress!$A$2:$A$100, "<="&B46+4)) -> 427156 | H46: =G46-F46 -> 285170.56 | I46: =G46-D46 -> 167806 | J46: =IF(F46>0, G46/F46, 1) -> 3.0084493 | K46: =IF(D46>0, G46/D46, 1) -> 1.6470252
A47: 12 | B47: 46223 | C47: =SUMIFS(Fact_Baseline_PV!C:C, Fact_Baseline_PV!A:A, B47) -> 9300 | D47: =SUM(C$36:C47) -> 268650 | E47: =SUMIFS(Fact_Actual_Costs!D:D, Fact_Actual_Costs!A:A, ">="&B47, Fact_Actual_Costs!A:A, "<="&B47+6) -> 0 | F47: =SUM(E$36:E47) -> 141985.44 | G47: =SUMPRODUCT(Dim_WBS!$E$2:$E$13, SUMIFS(Fact_Physical_Progress!$C$2:$C$100, Fact_Physical_Progress!$B$2:$B$100, Dim_WBS!$A$2:$A$13, Fact_Physical_Progress!$A$2:$A$100, "<="&B47+4)) -> 427156 | H47: =G47-F47 -> 285170.56 | I47: =G47-D47 -> 158506 | J47: =IF(F47>0, G47/F47, 1) -> 3.0084493 | K47: =IF(D47>0, G47/D47, 1) -> 1.5900093

Sheet Red Actions
A1: Red RAG Action Recommendations
A2: Focused recovery actions for WBS items and control risks currently flagged Red. Evidence is pulled live from tbl_Task_Plan.
A4: STORY IN BRIEF
A5: The red status is mainly schedule-driven: Flooring, Fixtures & Furniture, Partitions & Drywall, HVAC, and Electrical Rough-In are the recovery priorities because their SPI and schedule variances are pulling the project off plan. Cost exposure is concentrated in Electrical Rough-In and HVAC, while completed red tasks need closeout variance review rather than delivery acceleration. The recommended response is a short recovery sprint: remove blockers, confirm subcontractor/material readiness, reset near-term dates, and escalate decision items already logged in the Review sheet.
A9: Red WBS items | C9: Worst red SPI | E9: Largest red SV | G9: Red forecast overrun
A10: =COUNTIF(tbl_Task_Plan[Status],"Red") -> 8 | C10: =_xlfn.MINIFS(tbl_Task_Plan[SPI],tbl_Task_Plan[Status],"Red") -> 0 | E10: =_xlfn.MINIFS(tbl_Task_Plan[SV],tbl_Task_Plan[Status],"Red") -> -23833.34 | G10: =-SUMIFS(tbl_Task_Plan[VAC],tbl_Task_Plan[Status],"Red") -> 21264.872
A13: Priority | B13: WBS ID | C13: Activity | D13: Red driver | E13: Live evidence | F13: Recommended action | G13: Owner | H13: Due date
A14: 1 | B14: WBS-09 | C14: =_xlfn.XLOOKUP(B14,tbl_Task_Plan[WBS ID],tbl_Task_Plan[Task / Activity],"") -> Flooring | D14: Schedule / not started | E14: =TEXT(_xlfn.XLOOKUP(B14,tbl_Task_Plan[WBS ID],tbl_Task_Plan[Progress %]),"0%")&" complete; SPI "&TEXT(_xlfn.XLOOKUP(B14,tbl_Task_Plan[WBS ID],tbl_Task_Plan[SPI]),"0.00")&"; CPI "&TEXT(_xlfn.XLOOKUP(B14,tbl_Task_Plan[WBS ID],tbl_Task_Plan[CPI]),"0.00")&"; SV "&TEXT(_xlfn.XLOOKUP(B14,tbl_Task_Plan[WBS ID],tbl_Task_Plan[SV]),"#,##0")&" NOK" -> 0% complete; SPI 0.00; CPI 1.00; SV -23,833 NOK | F14: Start recovery immediately: confirm all prerequisites from HVAC/drywall, lock crew/material availability, and publish a catch-up start/finish date within the next planning cycle. | G14: Planner | H14: =Control_Status_Date+2 -> 46205
